ERROR 2025-02-08 15:14:29,386 log Internal Server Error: /
Traceback (most recent call last):
  File "/home/syful/projects/python/djvenv/lib/python3.10/site-packages/django/core/handlers/exception.py", line 55, in inner
    response = get_response(request)
  File "/home/syful/projects/python/evchargingapi/app/core/logger.py", line 35, in __call__
    if self.log_sql_queries and duration > self.slow_query_threshold:
AttributeError: 'AdvancedLoggingMiddleware' object has no attribute 'log_sql_queries'
ERROR 2025-02-08 15:14:29,386 basehttp "GET / HTTP/1.1" 500 65614
ERROR 2025-02-08 15:14:29,571 log Internal Server Error: /favicon.ico
Traceback (most recent call last):
  File "/home/syful/projects/python/djvenv/lib/python3.10/site-packages/django/core/handlers/exception.py", line 55, in inner
    response = get_response(request)
  File "/home/syful/projects/python/evchargingapi/app/core/logger.py", line 35, in __call__
    if self.log_sql_queries and duration > self.slow_query_threshold:
AttributeError: 'AdvancedLoggingMiddleware' object has no attribute 'log_sql_queries'
ERROR 2025-02-08 15:14:29,572 basehttp "GET /favicon.ico HTTP/1.1" 500 65517
ERROR 2025-02-08 15:15:36,854 log Internal Server Error: /
Traceback (most recent call last):
  File "/home/syful/projects/python/djvenv/lib/python3.10/site-packages/django/core/handlers/exception.py", line 55, in inner
    response = get_response(request)
  File "/home/syful/projects/python/evchargingapi/app/core/logger.py", line 35, in __call__
    if self.log_sql_queries and duration > self.slow_query_threshold:
AttributeError: 'AdvancedLoggingMiddleware' object has no attribute 'log_sql_queries'
ERROR 2025-02-08 15:15:36,855 basehttp "GET / HTTP/1.1" 500 65750
ERROR 2025-02-08 15:15:37,025 log Internal Server Error: /favicon.ico
Traceback (most recent call last):
  File "/home/syful/projects/python/djvenv/lib/python3.10/site-packages/django/core/handlers/exception.py", line 55, in inner
    response = get_response(request)
  File "/home/syful/projects/python/evchargingapi/app/core/logger.py", line 35, in __call__
    if self.log_sql_queries and duration > self.slow_query_threshold:
AttributeError: 'AdvancedLoggingMiddleware' object has no attribute 'log_sql_queries'
ERROR 2025-02-08 15:15:37,026 basehttp "GET /favicon.ico HTTP/1.1" 500 65517
ERROR 2025-02-08 15:15:38,130 log Internal Server Error: /
Traceback (most recent call last):
  File "/home/syful/projects/python/djvenv/lib/python3.10/site-packages/django/core/handlers/exception.py", line 55, in inner
    response = get_response(request)
  File "/home/syful/projects/python/evchargingapi/app/core/logger.py", line 35, in __call__
    if self.log_sql_queries and duration > self.slow_query_threshold:
AttributeError: 'AdvancedLoggingMiddleware' object has no attribute 'log_sql_queries'
ERROR 2025-02-08 15:15:38,130 basehttp "GET / HTTP/1.1" 500 65750
ERROR 2025-02-08 15:15:38,237 log Internal Server Error: /favicon.ico
Traceback (most recent call last):
  File "/home/syful/projects/python/djvenv/lib/python3.10/site-packages/django/core/handlers/exception.py", line 55, in inner
    response = get_response(request)
  File "/home/syful/projects/python/evchargingapi/app/core/logger.py", line 35, in __call__
    if self.log_sql_queries and duration > self.slow_query_threshold:
AttributeError: 'AdvancedLoggingMiddleware' object has no attribute 'log_sql_queries'
ERROR 2025-02-08 15:15:38,238 basehttp "GET /favicon.ico HTTP/1.1" 500 65518
ERROR 2025-02-08 15:15:38,402 log Internal Server Error: /
Traceback (most recent call last):
  File "/home/syful/projects/python/djvenv/lib/python3.10/site-packages/django/core/handlers/exception.py", line 55, in inner
    response = get_response(request)
  File "/home/syful/projects/python/evchargingapi/app/core/logger.py", line 35, in __call__
    if self.log_sql_queries and duration > self.slow_query_threshold:
AttributeError: 'AdvancedLoggingMiddleware' object has no attribute 'log_sql_queries'
ERROR 2025-02-08 15:15:38,402 basehttp "GET / HTTP/1.1" 500 65751
ERROR 2025-02-08 15:15:38,506 log Internal Server Error: /favicon.ico
Traceback (most recent call last):
  File "/home/syful/projects/python/djvenv/lib/python3.10/site-packages/django/core/handlers/exception.py", line 55, in inner
    response = get_response(request)
  File "/home/syful/projects/python/evchargingapi/app/core/logger.py", line 35, in __call__
    if self.log_sql_queries and duration > self.slow_query_threshold:
AttributeError: 'AdvancedLoggingMiddleware' object has no attribute 'log_sql_queries'
ERROR 2025-02-08 15:15:38,506 basehttp "GET /favicon.ico HTTP/1.1" 500 65518
ERROR 2025-02-13 04:49:58,825 log Internal Server Error: /api/software/
Traceback (most recent call last):
  File "/home/syful/projects/python/djvenv/lib/python3.10/site-packages/django/db/backends/utils.py", line 105, in _execute
    return self.cursor.execute(sql, params)
psycopg2.errors.UndefinedTable: relation "app_softwaredetail" does not exist
LINE 1: ...ategory"."id", "app_softwarecategory"."name" FROM "app_softw...
                                                             ^


The above exception was the direct cause of the following exception:

Traceback (most recent call last):
  File "/home/syful/projects/python/djvenv/lib/python3.10/site-packages/django/core/handlers/exception.py", line 55, in inner
    response = get_response(request)
  File "/home/syful/projects/python/djvenv/lib/python3.10/site-packages/django/core/handlers/base.py", line 197, in _get_response
    response = wrapped_callback(request, *callback_args, **callback_kwargs)
  File "/home/syful/projects/python/djvenv/lib/python3.10/site-packages/django/views/decorators/csrf.py", line 65, in _view_wrapper
    return view_func(request, *args, **kwargs)
  File "/home/syful/projects/python/djvenv/lib/python3.10/site-packages/rest_framework/viewsets.py", line 124, in view
    return self.dispatch(request, *args, **kwargs)
  File "/home/syful/projects/python/djvenv/lib/python3.10/site-packages/rest_framework/views.py", line 509, in dispatch
    response = self.handle_exception(exc)
  File "/home/syful/projects/python/djvenv/lib/python3.10/site-packages/rest_framework/views.py", line 469, in handle_exception
    self.raise_uncaught_exception(exc)
  File "/home/syful/projects/python/djvenv/lib/python3.10/site-packages/rest_framework/views.py", line 480, in raise_uncaught_exception
    raise exc
  File "/home/syful/projects/python/djvenv/lib/python3.10/site-packages/rest_framework/views.py", line 506, in dispatch
    response = handler(request, *args, **kwargs)
  File "/home/syful/projects/python/djvenv/lib/python3.10/site-packages/rest_framework/mixins.py", line 46, in list
    return Response(serializer.data)
  File "/home/syful/projects/python/djvenv/lib/python3.10/site-packages/rest_framework/serializers.py", line 795, in data
    ret = super().data
  File "/home/syful/projects/python/djvenv/lib/python3.10/site-packages/rest_framework/serializers.py", line 249, in data
    self._data = self.to_representation(self.instance)
  File "/home/syful/projects/python/djvenv/lib/python3.10/site-packages/rest_framework/serializers.py", line 713, in to_representation
    return [
  File "/home/syful/projects/python/djvenv/lib/python3.10/site-packages/django/db/models/query.py", line 400, in __iter__
    self._fetch_all()
  File "/home/syful/projects/python/djvenv/lib/python3.10/site-packages/django/db/models/query.py", line 1928, in _fetch_all
    self._result_cache = list(self._iterable_class(self))
  File "/home/syful/projects/python/djvenv/lib/python3.10/site-packages/django/db/models/query.py", line 91, in __iter__
    results = compiler.execute_sql(
  File "/home/syful/projects/python/djvenv/lib/python3.10/site-packages/django/db/models/sql/compiler.py", line 1574, in execute_sql
    cursor.execute(sql, params)
  File "/home/syful/projects/python/djvenv/lib/python3.10/site-packages/django/db/backends/utils.py", line 122, in execute
    return super().execute(sql, params)
  File "/home/syful/projects/python/djvenv/lib/python3.10/site-packages/django/db/backends/utils.py", line 79, in execute
    return self._execute_with_wrappers(
  File "/home/syful/projects/python/djvenv/lib/python3.10/site-packages/django/db/backends/utils.py", line 92, in _execute_with_wrappers
    return executor(sql, params, many, context)
  File "/home/syful/projects/python/djvenv/lib/python3.10/site-packages/django/db/backends/utils.py", line 100, in _execute
    with self.db.wrap_database_errors:
  File "/home/syful/projects/python/djvenv/lib/python3.10/site-packages/django/db/utils.py", line 91, in __exit__
    raise dj_exc_value.with_traceback(traceback) from exc_value
  File "/home/syful/projects/python/djvenv/lib/python3.10/site-packages/django/db/backends/utils.py", line 105, in _execute
    return self.cursor.execute(sql, params)
django.db.utils.ProgrammingError: relation "app_softwaredetail" does not exist
LINE 1: ...ategory"."id", "app_softwarecategory"."name" FROM "app_softw...
                                                             ^

ERROR 2025-02-13 04:49:58,828 basehttp "GET /api/software/ HTTP/1.1" 500 23033
ERROR 2025-03-03 07:45:05,235 log Internal Server Error: /api/employees/
Traceback (most recent call last):
  File "/media/zahid/Ads Power/Enterprise Infosec Consultants/ComplyWiseApi/venv/lib/python3.11/site-packages/django/db/backends/utils.py", line 105, in _execute
    return self.cursor.execute(sql, params)
           ^^^^^^^^^^^^^^^^^^^^^^^^^^^^^^^^
psycopg2.errors.UndefinedTable: relation "app_employee" does not exist
LINE 1: ...e"."created_at", "app_employee"."updated_at" FROM "app_emplo...
                                                             ^


The above exception was the direct cause of the following exception:

Traceback (most recent call last):
  File "/media/zahid/Ads Power/Enterprise Infosec Consultants/ComplyWiseApi/venv/lib/python3.11/site-packages/django/core/handlers/exception.py", line 55, in inner
    response = get_response(request)
               ^^^^^^^^^^^^^^^^^^^^^
  File "/media/zahid/Ads Power/Enterprise Infosec Consultants/ComplyWiseApi/venv/lib/python3.11/site-packages/django/core/handlers/base.py", line 197, in _get_response
    response = wrapped_callback(request, *callback_args, **callback_kwargs)
               ^^^^^^^^^^^^^^^^^^^^^^^^^^^^^^^^^^^^^^^^^^^^^^^^^^^^^^^^^^^^
  File "/media/zahid/Ads Power/Enterprise Infosec Consultants/ComplyWiseApi/venv/lib/python3.11/site-packages/django/views/decorators/csrf.py", line 65, in _view_wrapper
    return view_func(request, *args, **kwargs)
           ^^^^^^^^^^^^^^^^^^^^^^^^^^^^^^^^^^^
  File "/media/zahid/Ads Power/Enterprise Infosec Consultants/ComplyWiseApi/venv/lib/python3.11/site-packages/rest_framework/viewsets.py", line 124, in view
    return self.dispatch(request, *args, **kwargs)
           ^^^^^^^^^^^^^^^^^^^^^^^^^^^^^^^^^^^^^^^
  File "/media/zahid/Ads Power/Enterprise Infosec Consultants/ComplyWiseApi/venv/lib/python3.11/site-packages/rest_framework/views.py", line 509, in dispatch
    response = self.handle_exception(exc)
               ^^^^^^^^^^^^^^^^^^^^^^^^^^
  File "/media/zahid/Ads Power/Enterprise Infosec Consultants/ComplyWiseApi/venv/lib/python3.11/site-packages/rest_framework/views.py", line 469, in handle_exception
    self.raise_uncaught_exception(exc)
  File "/media/zahid/Ads Power/Enterprise Infosec Consultants/ComplyWiseApi/venv/lib/python3.11/site-packages/rest_framework/views.py", line 480, in raise_uncaught_exception
    raise exc
  File "/media/zahid/Ads Power/Enterprise Infosec Consultants/ComplyWiseApi/venv/lib/python3.11/site-packages/rest_framework/views.py", line 506, in dispatch
    response = handler(request, *args, **kwargs)
               ^^^^^^^^^^^^^^^^^^^^^^^^^^^^^^^^^
  File "/media/zahid/Ads Power/Enterprise Infosec Consultants/ComplyWiseApi/venv/lib/python3.11/site-packages/rest_framework/mixins.py", line 46, in list
    return Response(serializer.data)
                    ^^^^^^^^^^^^^^^
  File "/media/zahid/Ads Power/Enterprise Infosec Consultants/ComplyWiseApi/venv/lib/python3.11/site-packages/rest_framework/serializers.py", line 795, in data
    ret = super().data
          ^^^^^^^^^^^^
  File "/media/zahid/Ads Power/Enterprise Infosec Consultants/ComplyWiseApi/venv/lib/python3.11/site-packages/rest_framework/serializers.py", line 249, in data
    self._data = self.to_representation(self.instance)
                 ^^^^^^^^^^^^^^^^^^^^^^^^^^^^^^^^^^^^^
  File "/media/zahid/Ads Power/Enterprise Infosec Consultants/ComplyWiseApi/venv/lib/python3.11/site-packages/rest_framework/serializers.py", line 713, in to_representation
    return [
           ^
  File "/media/zahid/Ads Power/Enterprise Infosec Consultants/ComplyWiseApi/venv/lib/python3.11/site-packages/django/db/models/query.py", line 400, in __iter__
    self._fetch_all()
  File "/media/zahid/Ads Power/Enterprise Infosec Consultants/ComplyWiseApi/venv/lib/python3.11/site-packages/django/db/models/query.py", line 1928, in _fetch_all
    self._result_cache = list(self._iterable_class(self))
                         ^^^^^^^^^^^^^^^^^^^^^^^^^^^^^^^^
  File "/media/zahid/Ads Power/Enterprise Infosec Consultants/ComplyWiseApi/venv/lib/python3.11/site-packages/django/db/models/query.py", line 91, in __iter__
    results = compiler.execute_sql(
              ^^^^^^^^^^^^^^^^^^^^^
  File "/media/zahid/Ads Power/Enterprise Infosec Consultants/ComplyWiseApi/venv/lib/python3.11/site-packages/django/db/models/sql/compiler.py", line 1574, in execute_sql
    cursor.execute(sql, params)
  File "/media/zahid/Ads Power/Enterprise Infosec Consultants/ComplyWiseApi/venv/lib/python3.11/site-packages/django/db/backends/utils.py", line 122, in execute
    return super().execute(sql, params)
           ^^^^^^^^^^^^^^^^^^^^^^^^^^^^
  File "/media/zahid/Ads Power/Enterprise Infosec Consultants/ComplyWiseApi/venv/lib/python3.11/site-packages/django/db/backends/utils.py", line 79, in execute
    return self._execute_with_wrappers(
           ^^^^^^^^^^^^^^^^^^^^^^^^^^^^
  File "/media/zahid/Ads Power/Enterprise Infosec Consultants/ComplyWiseApi/venv/lib/python3.11/site-packages/django/db/backends/utils.py", line 92, in _execute_with_wrappers
    return executor(sql, params, many, context)
           ^^^^^^^^^^^^^^^^^^^^^^^^^^^^^^^^^^^^
  File "/media/zahid/Ads Power/Enterprise Infosec Consultants/ComplyWiseApi/venv/lib/python3.11/site-packages/django/db/backends/utils.py", line 100, in _execute
    with self.db.wrap_database_errors:
  File "/media/zahid/Ads Power/Enterprise Infosec Consultants/ComplyWiseApi/venv/lib/python3.11/site-packages/django/db/utils.py", line 91, in __exit__
    raise dj_exc_value.with_traceback(traceback) from exc_value
  File "/media/zahid/Ads Power/Enterprise Infosec Consultants/ComplyWiseApi/venv/lib/python3.11/site-packages/django/db/backends/utils.py", line 105, in _execute
    return self.cursor.execute(sql, params)
           ^^^^^^^^^^^^^^^^^^^^^^^^^^^^^^^^
django.db.utils.ProgrammingError: relation "app_employee" does not exist
LINE 1: ...e"."created_at", "app_employee"."updated_at" FROM "app_emplo...
                                                             ^

ERROR 2025-03-03 07:45:05,253 basehttp "GET /api/employees/ HTTP/1.1" 500 25894
ERROR 2025-03-03 07:48:13,260 log Internal Server Error: /api/employees/
Traceback (most recent call last):
  File "/media/zahid/Ads Power/Enterprise Infosec Consultants/ComplyWiseApi/venv/lib/python3.11/site-packages/django/core/handlers/exception.py", line 55, in inner
    response = get_response(request)
               ^^^^^^^^^^^^^^^^^^^^^
  File "/media/zahid/Ads Power/Enterprise Infosec Consultants/ComplyWiseApi/venv/lib/python3.11/site-packages/django/core/handlers/base.py", line 197, in _get_response
    response = wrapped_callback(request, *callback_args, **callback_kwargs)
               ^^^^^^^^^^^^^^^^^^^^^^^^^^^^^^^^^^^^^^^^^^^^^^^^^^^^^^^^^^^^
  File "/media/zahid/Ads Power/Enterprise Infosec Consultants/ComplyWiseApi/venv/lib/python3.11/site-packages/django/views/decorators/csrf.py", line 65, in _view_wrapper
    return view_func(request, *args, **kwargs)
           ^^^^^^^^^^^^^^^^^^^^^^^^^^^^^^^^^^^
  File "/media/zahid/Ads Power/Enterprise Infosec Consultants/ComplyWiseApi/venv/lib/python3.11/site-packages/rest_framework/viewsets.py", line 124, in view
    return self.dispatch(request, *args, **kwargs)
           ^^^^^^^^^^^^^^^^^^^^^^^^^^^^^^^^^^^^^^^
  File "/media/zahid/Ads Power/Enterprise Infosec Consultants/ComplyWiseApi/venv/lib/python3.11/site-packages/rest_framework/views.py", line 509, in dispatch
    response = self.handle_exception(exc)
               ^^^^^^^^^^^^^^^^^^^^^^^^^^
  File "/media/zahid/Ads Power/Enterprise Infosec Consultants/ComplyWiseApi/venv/lib/python3.11/site-packages/rest_framework/views.py", line 469, in handle_exception
    self.raise_uncaught_exception(exc)
  File "/media/zahid/Ads Power/Enterprise Infosec Consultants/ComplyWiseApi/venv/lib/python3.11/site-packages/rest_framework/views.py", line 480, in raise_uncaught_exception
    raise exc
  File "/media/zahid/Ads Power/Enterprise Infosec Consultants/ComplyWiseApi/venv/lib/python3.11/site-packages/rest_framework/views.py", line 506, in dispatch
    response = handler(request, *args, **kwargs)
               ^^^^^^^^^^^^^^^^^^^^^^^^^^^^^^^^^
  File "/media/zahid/Ads Power/Enterprise Infosec Consultants/ComplyWiseApi/venv/lib/python3.11/site-packages/rest_framework/mixins.py", line 19, in create
    self.perform_create(serializer)
  File "/media/zahid/Ads Power/Enterprise Infosec Consultants/ComplyWiseApi/venv/lib/python3.11/site-packages/rest_framework/mixins.py", line 24, in perform_create
    serializer.save()
  File "/media/zahid/Ads Power/Enterprise Infosec Consultants/ComplyWiseApi/venv/lib/python3.11/site-packages/rest_framework/serializers.py", line 208, in save
    self.instance = self.create(validated_data)
                    ^^^^^^^^^^^^^^^^^^^^^^^^^^^
  File "/media/zahid/Ads Power/Enterprise Infosec Consultants/ComplyWiseApi/app/modules/access_control/serializers/employee.py", line 31, in create
    employee = Employee.objects.create(user=user, **validated_data)
               ^^^^^^^^^^^^^^^^^^^^^^^^^^^^^^^^^^^^^^^^^^^^^^^^^^^^
  File "/media/zahid/Ads Power/Enterprise Infosec Consultants/ComplyWiseApi/venv/lib/python3.11/site-packages/django/db/models/manager.py", line 87, in manager_method
    return getattr(self.get_queryset(), name)(*args, **kwargs)
           ^^^^^^^^^^^^^^^^^^^^^^^^^^^^^^^^^^^^^^^^^^^^^^^^^^^
  File "/media/zahid/Ads Power/Enterprise Infosec Consultants/ComplyWiseApi/venv/lib/python3.11/site-packages/django/db/models/query.py", line 677, in create
    obj = self.model(**kwargs)
          ^^^^^^^^^^^^^^^^^^^^
  File "/media/zahid/Ads Power/Enterprise Infosec Consultants/ComplyWiseApi/venv/lib/python3.11/site-packages/django/db/models/base.py", line 567, in __init__
    raise TypeError(
TypeError: Employee() got unexpected keyword arguments: 'user'
ERROR 2025-03-03 07:48:13,274 basehttp "POST /api/employees/ HTTP/1.1" 500 23516
