ERROR 2025-02-08 15:14:29,386 log Internal Server Error: /
Traceback (most recent call last):
  File "/home/syful/projects/python/djvenv/lib/python3.10/site-packages/django/core/handlers/exception.py", line 55, in inner
    response = get_response(request)
  File "/home/syful/projects/python/evchargingapi/app/core/logger.py", line 35, in __call__
    if self.log_sql_queries and duration > self.slow_query_threshold:
AttributeError: 'AdvancedLoggingMiddleware' object has no attribute 'log_sql_queries'
ERROR 2025-02-08 15:14:29,386 basehttp "GET / HTTP/1.1" 500 65614
ERROR 2025-02-08 15:14:29,571 log Internal Server Error: /favicon.ico
Traceback (most recent call last):
  File "/home/syful/projects/python/djvenv/lib/python3.10/site-packages/django/core/handlers/exception.py", line 55, in inner
    response = get_response(request)
  File "/home/syful/projects/python/evchargingapi/app/core/logger.py", line 35, in __call__
    if self.log_sql_queries and duration > self.slow_query_threshold:
AttributeError: 'AdvancedLoggingMiddleware' object has no attribute 'log_sql_queries'
ERROR 2025-02-08 15:14:29,572 basehttp "GET /favicon.ico HTTP/1.1" 500 65517
ERROR 2025-02-08 15:15:36,854 log Internal Server Error: /
Traceback (most recent call last):
  File "/home/syful/projects/python/djvenv/lib/python3.10/site-packages/django/core/handlers/exception.py", line 55, in inner
    response = get_response(request)
  File "/home/syful/projects/python/evchargingapi/app/core/logger.py", line 35, in __call__
    if self.log_sql_queries and duration > self.slow_query_threshold:
AttributeError: 'AdvancedLoggingMiddleware' object has no attribute 'log_sql_queries'
ERROR 2025-02-08 15:15:36,855 basehttp "GET / HTTP/1.1" 500 65750
ERROR 2025-02-08 15:15:37,025 log Internal Server Error: /favicon.ico
Traceback (most recent call last):
  File "/home/syful/projects/python/djvenv/lib/python3.10/site-packages/django/core/handlers/exception.py", line 55, in inner
    response = get_response(request)
  File "/home/syful/projects/python/evchargingapi/app/core/logger.py", line 35, in __call__
    if self.log_sql_queries and duration > self.slow_query_threshold:
AttributeError: 'AdvancedLoggingMiddleware' object has no attribute 'log_sql_queries'
ERROR 2025-02-08 15:15:37,026 basehttp "GET /favicon.ico HTTP/1.1" 500 65517
ERROR 2025-02-08 15:15:38,130 log Internal Server Error: /
Traceback (most recent call last):
  File "/home/syful/projects/python/djvenv/lib/python3.10/site-packages/django/core/handlers/exception.py", line 55, in inner
    response = get_response(request)
  File "/home/syful/projects/python/evchargingapi/app/core/logger.py", line 35, in __call__
    if self.log_sql_queries and duration > self.slow_query_threshold:
AttributeError: 'AdvancedLoggingMiddleware' object has no attribute 'log_sql_queries'
ERROR 2025-02-08 15:15:38,130 basehttp "GET / HTTP/1.1" 500 65750
ERROR 2025-02-08 15:15:38,237 log Internal Server Error: /favicon.ico
Traceback (most recent call last):
  File "/home/syful/projects/python/djvenv/lib/python3.10/site-packages/django/core/handlers/exception.py", line 55, in inner
    response = get_response(request)
  File "/home/syful/projects/python/evchargingapi/app/core/logger.py", line 35, in __call__
    if self.log_sql_queries and duration > self.slow_query_threshold:
AttributeError: 'AdvancedLoggingMiddleware' object has no attribute 'log_sql_queries'
ERROR 2025-02-08 15:15:38,238 basehttp "GET /favicon.ico HTTP/1.1" 500 65518
ERROR 2025-02-08 15:15:38,402 log Internal Server Error: /
Traceback (most recent call last):
  File "/home/syful/projects/python/djvenv/lib/python3.10/site-packages/django/core/handlers/exception.py", line 55, in inner
    response = get_response(request)
  File "/home/syful/projects/python/evchargingapi/app/core/logger.py", line 35, in __call__
    if self.log_sql_queries and duration > self.slow_query_threshold:
AttributeError: 'AdvancedLoggingMiddleware' object has no attribute 'log_sql_queries'
ERROR 2025-02-08 15:15:38,402 basehttp "GET / HTTP/1.1" 500 65751
ERROR 2025-02-08 15:15:38,506 log Internal Server Error: /favicon.ico
Traceback (most recent call last):
  File "/home/syful/projects/python/djvenv/lib/python3.10/site-packages/django/core/handlers/exception.py", line 55, in inner
    response = get_response(request)
  File "/home/syful/projects/python/evchargingapi/app/core/logger.py", line 35, in __call__
    if self.log_sql_queries and duration > self.slow_query_threshold:
AttributeError: 'AdvancedLoggingMiddleware' object has no attribute 'log_sql_queries'
ERROR 2025-02-08 15:15:38,506 basehttp "GET /favicon.ico HTTP/1.1" 500 65518
ERROR 2025-02-13 04:49:58,825 log Internal Server Error: /api/software/
Traceback (most recent call last):
  File "/home/syful/projects/python/djvenv/lib/python3.10/site-packages/django/db/backends/utils.py", line 105, in _execute
    return self.cursor.execute(sql, params)
psycopg2.errors.UndefinedTable: relation "app_softwaredetail" does not exist
LINE 1: ...ategory"."id", "app_softwarecategory"."name" FROM "app_softw...
                                                             ^


The above exception was the direct cause of the following exception:

Traceback (most recent call last):
  File "/home/syful/projects/python/djvenv/lib/python3.10/site-packages/django/core/handlers/exception.py", line 55, in inner
    response = get_response(request)
  File "/home/syful/projects/python/djvenv/lib/python3.10/site-packages/django/core/handlers/base.py", line 197, in _get_response
    response = wrapped_callback(request, *callback_args, **callback_kwargs)
  File "/home/syful/projects/python/djvenv/lib/python3.10/site-packages/django/views/decorators/csrf.py", line 65, in _view_wrapper
    return view_func(request, *args, **kwargs)
  File "/home/syful/projects/python/djvenv/lib/python3.10/site-packages/rest_framework/viewsets.py", line 124, in view
    return self.dispatch(request, *args, **kwargs)
  File "/home/syful/projects/python/djvenv/lib/python3.10/site-packages/rest_framework/views.py", line 509, in dispatch
    response = self.handle_exception(exc)
  File "/home/syful/projects/python/djvenv/lib/python3.10/site-packages/rest_framework/views.py", line 469, in handle_exception
    self.raise_uncaught_exception(exc)
  File "/home/syful/projects/python/djvenv/lib/python3.10/site-packages/rest_framework/views.py", line 480, in raise_uncaught_exception
    raise exc
  File "/home/syful/projects/python/djvenv/lib/python3.10/site-packages/rest_framework/views.py", line 506, in dispatch
    response = handler(request, *args, **kwargs)
  File "/home/syful/projects/python/djvenv/lib/python3.10/site-packages/rest_framework/mixins.py", line 46, in list
    return Response(serializer.data)
  File "/home/syful/projects/python/djvenv/lib/python3.10/site-packages/rest_framework/serializers.py", line 795, in data
    ret = super().data
  File "/home/syful/projects/python/djvenv/lib/python3.10/site-packages/rest_framework/serializers.py", line 249, in data
    self._data = self.to_representation(self.instance)
  File "/home/syful/projects/python/djvenv/lib/python3.10/site-packages/rest_framework/serializers.py", line 713, in to_representation
    return [
  File "/home/syful/projects/python/djvenv/lib/python3.10/site-packages/django/db/models/query.py", line 400, in __iter__
    self._fetch_all()
  File "/home/syful/projects/python/djvenv/lib/python3.10/site-packages/django/db/models/query.py", line 1928, in _fetch_all
    self._result_cache = list(self._iterable_class(self))
  File "/home/syful/projects/python/djvenv/lib/python3.10/site-packages/django/db/models/query.py", line 91, in __iter__
    results = compiler.execute_sql(
  File "/home/syful/projects/python/djvenv/lib/python3.10/site-packages/django/db/models/sql/compiler.py", line 1574, in execute_sql
    cursor.execute(sql, params)
  File "/home/syful/projects/python/djvenv/lib/python3.10/site-packages/django/db/backends/utils.py", line 122, in execute
    return super().execute(sql, params)
  File "/home/syful/projects/python/djvenv/lib/python3.10/site-packages/django/db/backends/utils.py", line 79, in execute
    return self._execute_with_wrappers(
  File "/home/syful/projects/python/djvenv/lib/python3.10/site-packages/django/db/backends/utils.py", line 92, in _execute_with_wrappers
    return executor(sql, params, many, context)
  File "/home/syful/projects/python/djvenv/lib/python3.10/site-packages/django/db/backends/utils.py", line 100, in _execute
    with self.db.wrap_database_errors:
  File "/home/syful/projects/python/djvenv/lib/python3.10/site-packages/django/db/utils.py", line 91, in __exit__
    raise dj_exc_value.with_traceback(traceback) from exc_value
  File "/home/syful/projects/python/djvenv/lib/python3.10/site-packages/django/db/backends/utils.py", line 105, in _execute
    return self.cursor.execute(sql, params)
django.db.utils.ProgrammingError: relation "app_softwaredetail" does not exist
LINE 1: ...ategory"."id", "app_softwarecategory"."name" FROM "app_softw...
                                                             ^

ERROR 2025-02-13 04:49:58,828 basehttp "GET /api/software/ HTTP/1.1" 500 23033
ERROR 2025-03-03 07:45:05,235 log Internal Server Error: /api/employees/
Traceback (most recent call last):
  File "/media/zahid/Ads Power/Enterprise Infosec Consultants/ComplyWiseApi/venv/lib/python3.11/site-packages/django/db/backends/utils.py", line 105, in _execute
    return self.cursor.execute(sql, params)
           ^^^^^^^^^^^^^^^^^^^^^^^^^^^^^^^^
psycopg2.errors.UndefinedTable: relation "app_employee" does not exist
LINE 1: ...e"."created_at", "app_employee"."updated_at" FROM "app_emplo...
                                                             ^


The above exception was the direct cause of the following exception:

Traceback (most recent call last):
  File "/media/zahid/Ads Power/Enterprise Infosec Consultants/ComplyWiseApi/venv/lib/python3.11/site-packages/django/core/handlers/exception.py", line 55, in inner
    response = get_response(request)
               ^^^^^^^^^^^^^^^^^^^^^
  File "/media/zahid/Ads Power/Enterprise Infosec Consultants/ComplyWiseApi/venv/lib/python3.11/site-packages/django/core/handlers/base.py", line 197, in _get_response
    response = wrapped_callback(request, *callback_args, **callback_kwargs)
               ^^^^^^^^^^^^^^^^^^^^^^^^^^^^^^^^^^^^^^^^^^^^^^^^^^^^^^^^^^^^
  File "/media/zahid/Ads Power/Enterprise Infosec Consultants/ComplyWiseApi/venv/lib/python3.11/site-packages/django/views/decorators/csrf.py", line 65, in _view_wrapper
    return view_func(request, *args, **kwargs)
           ^^^^^^^^^^^^^^^^^^^^^^^^^^^^^^^^^^^
  File "/media/zahid/Ads Power/Enterprise Infosec Consultants/ComplyWiseApi/venv/lib/python3.11/site-packages/rest_framework/viewsets.py", line 124, in view
    return self.dispatch(request, *args, **kwargs)
           ^^^^^^^^^^^^^^^^^^^^^^^^^^^^^^^^^^^^^^^
  File "/media/zahid/Ads Power/Enterprise Infosec Consultants/ComplyWiseApi/venv/lib/python3.11/site-packages/rest_framework/views.py", line 509, in dispatch
    response = self.handle_exception(exc)
               ^^^^^^^^^^^^^^^^^^^^^^^^^^
  File "/media/zahid/Ads Power/Enterprise Infosec Consultants/ComplyWiseApi/venv/lib/python3.11/site-packages/rest_framework/views.py", line 469, in handle_exception
    self.raise_uncaught_exception(exc)
  File "/media/zahid/Ads Power/Enterprise Infosec Consultants/ComplyWiseApi/venv/lib/python3.11/site-packages/rest_framework/views.py", line 480, in raise_uncaught_exception
    raise exc
  File "/media/zahid/Ads Power/Enterprise Infosec Consultants/ComplyWiseApi/venv/lib/python3.11/site-packages/rest_framework/views.py", line 506, in dispatch
    response = handler(request, *args, **kwargs)
               ^^^^^^^^^^^^^^^^^^^^^^^^^^^^^^^^^
  File "/media/zahid/Ads Power/Enterprise Infosec Consultants/ComplyWiseApi/venv/lib/python3.11/site-packages/rest_framework/mixins.py", line 46, in list
    return Response(serializer.data)
                    ^^^^^^^^^^^^^^^
  File "/media/zahid/Ads Power/Enterprise Infosec Consultants/ComplyWiseApi/venv/lib/python3.11/site-packages/rest_framework/serializers.py", line 795, in data
    ret = super().data
          ^^^^^^^^^^^^
  File "/media/zahid/Ads Power/Enterprise Infosec Consultants/ComplyWiseApi/venv/lib/python3.11/site-packages/rest_framework/serializers.py", line 249, in data
    self._data = self.to_representation(self.instance)
                 ^^^^^^^^^^^^^^^^^^^^^^^^^^^^^^^^^^^^^
  File "/media/zahid/Ads Power/Enterprise Infosec Consultants/ComplyWiseApi/venv/lib/python3.11/site-packages/rest_framework/serializers.py", line 713, in to_representation
    return [
           ^
  File "/media/zahid/Ads Power/Enterprise Infosec Consultants/ComplyWiseApi/venv/lib/python3.11/site-packages/django/db/models/query.py", line 400, in __iter__
    self._fetch_all()
  File "/media/zahid/Ads Power/Enterprise Infosec Consultants/ComplyWiseApi/venv/lib/python3.11/site-packages/django/db/models/query.py", line 1928, in _fetch_all
    self._result_cache = list(self._iterable_class(self))
                         ^^^^^^^^^^^^^^^^^^^^^^^^^^^^^^^^
  File "/media/zahid/Ads Power/Enterprise Infosec Consultants/ComplyWiseApi/venv/lib/python3.11/site-packages/django/db/models/query.py", line 91, in __iter__
    results = compiler.execute_sql(
              ^^^^^^^^^^^^^^^^^^^^^
  File "/media/zahid/Ads Power/Enterprise Infosec Consultants/ComplyWiseApi/venv/lib/python3.11/site-packages/django/db/models/sql/compiler.py", line 1574, in execute_sql
    cursor.execute(sql, params)
  File "/media/zahid/Ads Power/Enterprise Infosec Consultants/ComplyWiseApi/venv/lib/python3.11/site-packages/django/db/backends/utils.py", line 122, in execute
    return super().execute(sql, params)
           ^^^^^^^^^^^^^^^^^^^^^^^^^^^^
  File "/media/zahid/Ads Power/Enterprise Infosec Consultants/ComplyWiseApi/venv/lib/python3.11/site-packages/django/db/backends/utils.py", line 79, in execute
    return self._execute_with_wrappers(
           ^^^^^^^^^^^^^^^^^^^^^^^^^^^^
  File "/media/zahid/Ads Power/Enterprise Infosec Consultants/ComplyWiseApi/venv/lib/python3.11/site-packages/django/db/backends/utils.py", line 92, in _execute_with_wrappers
    return executor(sql, params, many, context)
           ^^^^^^^^^^^^^^^^^^^^^^^^^^^^^^^^^^^^
  File "/media/zahid/Ads Power/Enterprise Infosec Consultants/ComplyWiseApi/venv/lib/python3.11/site-packages/django/db/backends/utils.py", line 100, in _execute
    with self.db.wrap_database_errors:
  File "/media/zahid/Ads Power/Enterprise Infosec Consultants/ComplyWiseApi/venv/lib/python3.11/site-packages/django/db/utils.py", line 91, in __exit__
    raise dj_exc_value.with_traceback(traceback) from exc_value
  File "/media/zahid/Ads Power/Enterprise Infosec Consultants/ComplyWiseApi/venv/lib/python3.11/site-packages/django/db/backends/utils.py", line 105, in _execute
    return self.cursor.execute(sql, params)
           ^^^^^^^^^^^^^^^^^^^^^^^^^^^^^^^^
django.db.utils.ProgrammingError: relation "app_employee" does not exist
LINE 1: ...e"."created_at", "app_employee"."updated_at" FROM "app_emplo...
                                                             ^

ERROR 2025-03-03 07:45:05,253 basehttp "GET /api/employees/ HTTP/1.1" 500 25894
ERROR 2025-03-03 07:48:13,260 log Internal Server Error: /api/employees/
Traceback (most recent call last):
  File "/media/zahid/Ads Power/Enterprise Infosec Consultants/ComplyWiseApi/venv/lib/python3.11/site-packages/django/core/handlers/exception.py", line 55, in inner
    response = get_response(request)
               ^^^^^^^^^^^^^^^^^^^^^
  File "/media/zahid/Ads Power/Enterprise Infosec Consultants/ComplyWiseApi/venv/lib/python3.11/site-packages/django/core/handlers/base.py", line 197, in _get_response
    response = wrapped_callback(request, *callback_args, **callback_kwargs)
               ^^^^^^^^^^^^^^^^^^^^^^^^^^^^^^^^^^^^^^^^^^^^^^^^^^^^^^^^^^^^
  File "/media/zahid/Ads Power/Enterprise Infosec Consultants/ComplyWiseApi/venv/lib/python3.11/site-packages/django/views/decorators/csrf.py", line 65, in _view_wrapper
    return view_func(request, *args, **kwargs)
           ^^^^^^^^^^^^^^^^^^^^^^^^^^^^^^^^^^^
  File "/media/zahid/Ads Power/Enterprise Infosec Consultants/ComplyWiseApi/venv/lib/python3.11/site-packages/rest_framework/viewsets.py", line 124, in view
    return self.dispatch(request, *args, **kwargs)
           ^^^^^^^^^^^^^^^^^^^^^^^^^^^^^^^^^^^^^^^
  File "/media/zahid/Ads Power/Enterprise Infosec Consultants/ComplyWiseApi/venv/lib/python3.11/site-packages/rest_framework/views.py", line 509, in dispatch
    response = self.handle_exception(exc)
               ^^^^^^^^^^^^^^^^^^^^^^^^^^
  File "/media/zahid/Ads Power/Enterprise Infosec Consultants/ComplyWiseApi/venv/lib/python3.11/site-packages/rest_framework/views.py", line 469, in handle_exception
    self.raise_uncaught_exception(exc)
  File "/media/zahid/Ads Power/Enterprise Infosec Consultants/ComplyWiseApi/venv/lib/python3.11/site-packages/rest_framework/views.py", line 480, in raise_uncaught_exception
    raise exc
  File "/media/zahid/Ads Power/Enterprise Infosec Consultants/ComplyWiseApi/venv/lib/python3.11/site-packages/rest_framework/views.py", line 506, in dispatch
    response = handler(request, *args, **kwargs)
               ^^^^^^^^^^^^^^^^^^^^^^^^^^^^^^^^^
  File "/media/zahid/Ads Power/Enterprise Infosec Consultants/ComplyWiseApi/venv/lib/python3.11/site-packages/rest_framework/mixins.py", line 19, in create
    self.perform_create(serializer)
  File "/media/zahid/Ads Power/Enterprise Infosec Consultants/ComplyWiseApi/venv/lib/python3.11/site-packages/rest_framework/mixins.py", line 24, in perform_create
    serializer.save()
  File "/media/zahid/Ads Power/Enterprise Infosec Consultants/ComplyWiseApi/venv/lib/python3.11/site-packages/rest_framework/serializers.py", line 208, in save
    self.instance = self.create(validated_data)
                    ^^^^^^^^^^^^^^^^^^^^^^^^^^^
  File "/media/zahid/Ads Power/Enterprise Infosec Consultants/ComplyWiseApi/app/modules/access_control/serializers/employee.py", line 31, in create
    employee = Employee.objects.create(user=user, **validated_data)
               ^^^^^^^^^^^^^^^^^^^^^^^^^^^^^^^^^^^^^^^^^^^^^^^^^^^^
  File "/media/zahid/Ads Power/Enterprise Infosec Consultants/ComplyWiseApi/venv/lib/python3.11/site-packages/django/db/models/manager.py", line 87, in manager_method
    return getattr(self.get_queryset(), name)(*args, **kwargs)
           ^^^^^^^^^^^^^^^^^^^^^^^^^^^^^^^^^^^^^^^^^^^^^^^^^^^
  File "/media/zahid/Ads Power/Enterprise Infosec Consultants/ComplyWiseApi/venv/lib/python3.11/site-packages/django/db/models/query.py", line 677, in create
    obj = self.model(**kwargs)
          ^^^^^^^^^^^^^^^^^^^^
  File "/media/zahid/Ads Power/Enterprise Infosec Consultants/ComplyWiseApi/venv/lib/python3.11/site-packages/django/db/models/base.py", line 567, in __init__
    raise TypeError(
TypeError: Employee() got unexpected keyword arguments: 'user'
ERROR 2025-03-03 07:48:13,274 basehttp "POST /api/employees/ HTTP/1.1" 500 23516
ERROR 2025-03-04 04:47:22,816 log Internal Server Error: /api/employees/
Traceback (most recent call last):
  File "/media/zahid/Ads Power/Enterprise Infosec Consultants/ComplyWiseApi/venv/lib/python3.11/site-packages/django/core/handlers/exception.py", line 55, in inner
    response = get_response(request)
               ^^^^^^^^^^^^^^^^^^^^^
  File "/media/zahid/Ads Power/Enterprise Infosec Consultants/ComplyWiseApi/venv/lib/python3.11/site-packages/django/core/handlers/base.py", line 197, in _get_response
    response = wrapped_callback(request, *callback_args, **callback_kwargs)
               ^^^^^^^^^^^^^^^^^^^^^^^^^^^^^^^^^^^^^^^^^^^^^^^^^^^^^^^^^^^^
  File "/media/zahid/Ads Power/Enterprise Infosec Consultants/ComplyWiseApi/venv/lib/python3.11/site-packages/django/views/decorators/csrf.py", line 65, in _view_wrapper
    return view_func(request, *args, **kwargs)
           ^^^^^^^^^^^^^^^^^^^^^^^^^^^^^^^^^^^
  File "/media/zahid/Ads Power/Enterprise Infosec Consultants/ComplyWiseApi/venv/lib/python3.11/site-packages/rest_framework/viewsets.py", line 124, in view
    return self.dispatch(request, *args, **kwargs)
           ^^^^^^^^^^^^^^^^^^^^^^^^^^^^^^^^^^^^^^^
  File "/media/zahid/Ads Power/Enterprise Infosec Consultants/ComplyWiseApi/venv/lib/python3.11/site-packages/rest_framework/views.py", line 509, in dispatch
    response = self.handle_exception(exc)
               ^^^^^^^^^^^^^^^^^^^^^^^^^^
  File "/media/zahid/Ads Power/Enterprise Infosec Consultants/ComplyWiseApi/venv/lib/python3.11/site-packages/rest_framework/views.py", line 469, in handle_exception
    self.raise_uncaught_exception(exc)
  File "/media/zahid/Ads Power/Enterprise Infosec Consultants/ComplyWiseApi/venv/lib/python3.11/site-packages/rest_framework/views.py", line 480, in raise_uncaught_exception
    raise exc
  File "/media/zahid/Ads Power/Enterprise Infosec Consultants/ComplyWiseApi/venv/lib/python3.11/site-packages/rest_framework/views.py", line 506, in dispatch
    response = handler(request, *args, **kwargs)
               ^^^^^^^^^^^^^^^^^^^^^^^^^^^^^^^^^
  File "/media/zahid/Ads Power/Enterprise Infosec Consultants/ComplyWiseApi/venv/lib/python3.11/site-packages/rest_framework/mixins.py", line 46, in list
    return Response(serializer.data)
                    ^^^^^^^^^^^^^^^
  File "/media/zahid/Ads Power/Enterprise Infosec Consultants/ComplyWiseApi/venv/lib/python3.11/site-packages/rest_framework/serializers.py", line 795, in data
    ret = super().data
          ^^^^^^^^^^^^
  File "/media/zahid/Ads Power/Enterprise Infosec Consultants/ComplyWiseApi/venv/lib/python3.11/site-packages/rest_framework/serializers.py", line 249, in data
    self._data = self.to_representation(self.instance)
                 ^^^^^^^^^^^^^^^^^^^^^^^^^^^^^^^^^^^^^
  File "/media/zahid/Ads Power/Enterprise Infosec Consultants/ComplyWiseApi/venv/lib/python3.11/site-packages/rest_framework/serializers.py", line 713, in to_representation
    return [
           ^
  File "/media/zahid/Ads Power/Enterprise Infosec Consultants/ComplyWiseApi/venv/lib/python3.11/site-packages/rest_framework/serializers.py", line 714, in <listcomp>
    self.child.to_representation(item) for item in iterable
    ^^^^^^^^^^^^^^^^^^^^^^^^^^^^^^^^^^
  File "/media/zahid/Ads Power/Enterprise Infosec Consultants/ComplyWiseApi/venv/lib/python3.11/site-packages/rest_framework/serializers.py", line 538, in to_representation
    ret[field.field_name] = field.to_representation(attribute)
                            ^^^^^^^^^^^^^^^^^^^^^^^^^^^^^^^^^^
  File "/media/zahid/Ads Power/Enterprise Infosec Consultants/ComplyWiseApi/venv/lib/python3.11/site-packages/rest_framework/fields.py", line 1654, in to_representation
    return [self.child.to_representation(item) if item is not None else None for item in data]
           ^^^^^^^^^^^^^^^^^^^^^^^^^^^^^^^^^^^^^^^^^^^^^^^^^^^^^^^^^^^^^^^^^^^^^^^^^^^^^^^^^^^
  File "/media/zahid/Ads Power/Enterprise Infosec Consultants/ComplyWiseApi/venv/lib/python3.11/site-packages/rest_framework/fields.py", line 1654, in <listcomp>
    return [self.child.to_representation(item) if item is not None else None for item in data]
           ^^^^^^^^^^^^^^^^^^^^^^^^^^^^^^^^^^^^^^^^^^^^^^^^^^^^^^^^^^^^^^^^^^^^^^^^^^^^^^^^^^^
  File "/media/zahid/Ads Power/Enterprise Infosec Consultants/ComplyWiseApi/venv/lib/python3.11/site-packages/django/core/files/base.py", line 78, in __iter__
    for chunk in self.chunks():
  File "/media/zahid/Ads Power/Enterprise Infosec Consultants/ComplyWiseApi/venv/lib/python3.11/site-packages/django/core/files/base.py", line 55, in chunks
    self.seek(0)
    ^^^^^^^^^
  File "/media/zahid/Ads Power/Enterprise Infosec Consultants/ComplyWiseApi/venv/lib/python3.11/site-packages/django/core/files/utils.py", line 45, in <lambda>
    seek = property(lambda self: self.file.seek)
                                 ^^^^^^^^^
  File "/media/zahid/Ads Power/Enterprise Infosec Consultants/ComplyWiseApi/venv/lib/python3.11/site-packages/django/db/models/fields/files.py", line 49, in _get_file
    self._require_file()
  File "/media/zahid/Ads Power/Enterprise Infosec Consultants/ComplyWiseApi/venv/lib/python3.11/site-packages/django/db/models/fields/files.py", line 44, in _require_file
    raise ValueError(
ValueError: The 'files' attribute has no file associated with it.
ERROR 2025-03-04 04:47:22,825 basehttp "GET /api/employees/ HTTP/1.1" 500 160820
ERROR 2025-03-04 04:47:56,619 log Internal Server Error: /api/employees/
Traceback (most recent call last):
  File "/media/zahid/Ads Power/Enterprise Infosec Consultants/ComplyWiseApi/venv/lib/python3.11/site-packages/django/core/handlers/exception.py", line 55, in inner
    response = get_response(request)
               ^^^^^^^^^^^^^^^^^^^^^
  File "/media/zahid/Ads Power/Enterprise Infosec Consultants/ComplyWiseApi/venv/lib/python3.11/site-packages/django/core/handlers/base.py", line 197, in _get_response
    response = wrapped_callback(request, *callback_args, **callback_kwargs)
               ^^^^^^^^^^^^^^^^^^^^^^^^^^^^^^^^^^^^^^^^^^^^^^^^^^^^^^^^^^^^
  File "/media/zahid/Ads Power/Enterprise Infosec Consultants/ComplyWiseApi/venv/lib/python3.11/site-packages/django/views/decorators/csrf.py", line 65, in _view_wrapper
    return view_func(request, *args, **kwargs)
           ^^^^^^^^^^^^^^^^^^^^^^^^^^^^^^^^^^^
  File "/media/zahid/Ads Power/Enterprise Infosec Consultants/ComplyWiseApi/venv/lib/python3.11/site-packages/rest_framework/viewsets.py", line 124, in view
    return self.dispatch(request, *args, **kwargs)
           ^^^^^^^^^^^^^^^^^^^^^^^^^^^^^^^^^^^^^^^
  File "/media/zahid/Ads Power/Enterprise Infosec Consultants/ComplyWiseApi/venv/lib/python3.11/site-packages/rest_framework/views.py", line 509, in dispatch
    response = self.handle_exception(exc)
               ^^^^^^^^^^^^^^^^^^^^^^^^^^
  File "/media/zahid/Ads Power/Enterprise Infosec Consultants/ComplyWiseApi/venv/lib/python3.11/site-packages/rest_framework/views.py", line 469, in handle_exception
    self.raise_uncaught_exception(exc)
  File "/media/zahid/Ads Power/Enterprise Infosec Consultants/ComplyWiseApi/venv/lib/python3.11/site-packages/rest_framework/views.py", line 480, in raise_uncaught_exception
    raise exc
  File "/media/zahid/Ads Power/Enterprise Infosec Consultants/ComplyWiseApi/venv/lib/python3.11/site-packages/rest_framework/views.py", line 506, in dispatch
    response = handler(request, *args, **kwargs)
               ^^^^^^^^^^^^^^^^^^^^^^^^^^^^^^^^^
  File "/media/zahid/Ads Power/Enterprise Infosec Consultants/ComplyWiseApi/venv/lib/python3.11/site-packages/rest_framework/mixins.py", line 46, in list
    return Response(serializer.data)
                    ^^^^^^^^^^^^^^^
  File "/media/zahid/Ads Power/Enterprise Infosec Consultants/ComplyWiseApi/venv/lib/python3.11/site-packages/rest_framework/serializers.py", line 795, in data
    ret = super().data
          ^^^^^^^^^^^^
  File "/media/zahid/Ads Power/Enterprise Infosec Consultants/ComplyWiseApi/venv/lib/python3.11/site-packages/rest_framework/serializers.py", line 249, in data
    self._data = self.to_representation(self.instance)
                 ^^^^^^^^^^^^^^^^^^^^^^^^^^^^^^^^^^^^^
  File "/media/zahid/Ads Power/Enterprise Infosec Consultants/ComplyWiseApi/venv/lib/python3.11/site-packages/rest_framework/serializers.py", line 713, in to_representation
    return [
           ^
  File "/media/zahid/Ads Power/Enterprise Infosec Consultants/ComplyWiseApi/venv/lib/python3.11/site-packages/rest_framework/serializers.py", line 714, in <listcomp>
    self.child.to_representation(item) for item in iterable
    ^^^^^^^^^^^^^^^^^^^^^^^^^^^^^^^^^^
  File "/media/zahid/Ads Power/Enterprise Infosec Consultants/ComplyWiseApi/venv/lib/python3.11/site-packages/rest_framework/serializers.py", line 538, in to_representation
    ret[field.field_name] = field.to_representation(attribute)
                            ^^^^^^^^^^^^^^^^^^^^^^^^^^^^^^^^^^
  File "/media/zahid/Ads Power/Enterprise Infosec Consultants/ComplyWiseApi/venv/lib/python3.11/site-packages/rest_framework/fields.py", line 1654, in to_representation
    return [self.child.to_representation(item) if item is not None else None for item in data]
           ^^^^^^^^^^^^^^^^^^^^^^^^^^^^^^^^^^^^^^^^^^^^^^^^^^^^^^^^^^^^^^^^^^^^^^^^^^^^^^^^^^^
  File "/media/zahid/Ads Power/Enterprise Infosec Consultants/ComplyWiseApi/venv/lib/python3.11/site-packages/rest_framework/fields.py", line 1654, in <listcomp>
    return [self.child.to_representation(item) if item is not None else None for item in data]
           ^^^^^^^^^^^^^^^^^^^^^^^^^^^^^^^^^^^^^^^^^^^^^^^^^^^^^^^^^^^^^^^^^^^^^^^^^^^^^^^^^^^
  File "/media/zahid/Ads Power/Enterprise Infosec Consultants/ComplyWiseApi/venv/lib/python3.11/site-packages/django/core/files/base.py", line 78, in __iter__
    for chunk in self.chunks():
  File "/media/zahid/Ads Power/Enterprise Infosec Consultants/ComplyWiseApi/venv/lib/python3.11/site-packages/django/core/files/base.py", line 55, in chunks
    self.seek(0)
    ^^^^^^^^^
  File "/media/zahid/Ads Power/Enterprise Infosec Consultants/ComplyWiseApi/venv/lib/python3.11/site-packages/django/core/files/utils.py", line 45, in <lambda>
    seek = property(lambda self: self.file.seek)
                                 ^^^^^^^^^
  File "/media/zahid/Ads Power/Enterprise Infosec Consultants/ComplyWiseApi/venv/lib/python3.11/site-packages/django/db/models/fields/files.py", line 49, in _get_file
    self._require_file()
  File "/media/zahid/Ads Power/Enterprise Infosec Consultants/ComplyWiseApi/venv/lib/python3.11/site-packages/django/db/models/fields/files.py", line 44, in _require_file
    raise ValueError(
ValueError: The 'files' attribute has no file associated with it.
ERROR 2025-03-04 04:47:56,626 basehttp "GET /api/employees/ HTTP/1.1" 500 160665
ERROR 2025-03-04 06:19:19,271 log Internal Server Error: /api/employees/
Traceback (most recent call last):
  File "/media/zahid/Ads Power/Enterprise Infosec Consultants/ComplyWiseApi/venv/lib/python3.11/site-packages/django/core/handlers/exception.py", line 55, in inner
    response = get_response(request)
               ^^^^^^^^^^^^^^^^^^^^^
  File "/media/zahid/Ads Power/Enterprise Infosec Consultants/ComplyWiseApi/venv/lib/python3.11/site-packages/django/core/handlers/base.py", line 197, in _get_response
    response = wrapped_callback(request, *callback_args, **callback_kwargs)
               ^^^^^^^^^^^^^^^^^^^^^^^^^^^^^^^^^^^^^^^^^^^^^^^^^^^^^^^^^^^^
  File "/media/zahid/Ads Power/Enterprise Infosec Consultants/ComplyWiseApi/venv/lib/python3.11/site-packages/django/views/decorators/csrf.py", line 65, in _view_wrapper
    return view_func(request, *args, **kwargs)
           ^^^^^^^^^^^^^^^^^^^^^^^^^^^^^^^^^^^
  File "/media/zahid/Ads Power/Enterprise Infosec Consultants/ComplyWiseApi/venv/lib/python3.11/site-packages/rest_framework/viewsets.py", line 124, in view
    return self.dispatch(request, *args, **kwargs)
           ^^^^^^^^^^^^^^^^^^^^^^^^^^^^^^^^^^^^^^^
  File "/media/zahid/Ads Power/Enterprise Infosec Consultants/ComplyWiseApi/venv/lib/python3.11/site-packages/rest_framework/views.py", line 509, in dispatch
    response = self.handle_exception(exc)
               ^^^^^^^^^^^^^^^^^^^^^^^^^^
  File "/media/zahid/Ads Power/Enterprise Infosec Consultants/ComplyWiseApi/venv/lib/python3.11/site-packages/rest_framework/views.py", line 469, in handle_exception
    self.raise_uncaught_exception(exc)
  File "/media/zahid/Ads Power/Enterprise Infosec Consultants/ComplyWiseApi/venv/lib/python3.11/site-packages/rest_framework/views.py", line 480, in raise_uncaught_exception
    raise exc
  File "/media/zahid/Ads Power/Enterprise Infosec Consultants/ComplyWiseApi/venv/lib/python3.11/site-packages/rest_framework/views.py", line 506, in dispatch
    response = handler(request, *args, **kwargs)
               ^^^^^^^^^^^^^^^^^^^^^^^^^^^^^^^^^
  File "/media/zahid/Ads Power/Enterprise Infosec Consultants/ComplyWiseApi/venv/lib/python3.11/site-packages/rest_framework/mixins.py", line 46, in list
    return Response(serializer.data)
                    ^^^^^^^^^^^^^^^
  File "/media/zahid/Ads Power/Enterprise Infosec Consultants/ComplyWiseApi/venv/lib/python3.11/site-packages/rest_framework/serializers.py", line 795, in data
    ret = super().data
          ^^^^^^^^^^^^
  File "/media/zahid/Ads Power/Enterprise Infosec Consultants/ComplyWiseApi/venv/lib/python3.11/site-packages/rest_framework/serializers.py", line 249, in data
    self._data = self.to_representation(self.instance)
                 ^^^^^^^^^^^^^^^^^^^^^^^^^^^^^^^^^^^^^
  File "/media/zahid/Ads Power/Enterprise Infosec Consultants/ComplyWiseApi/venv/lib/python3.11/site-packages/rest_framework/serializers.py", line 713, in to_representation
    return [
           ^
  File "/media/zahid/Ads Power/Enterprise Infosec Consultants/ComplyWiseApi/venv/lib/python3.11/site-packages/django/db/models/query.py", line 400, in __iter__
    self._fetch_all()
  File "/media/zahid/Ads Power/Enterprise Infosec Consultants/ComplyWiseApi/venv/lib/python3.11/site-packages/django/db/models/query.py", line 1928, in _fetch_all
    self._result_cache = list(self._iterable_class(self))
                         ^^^^^^^^^^^^^^^^^^^^^^^^^^^^^^^^
  File "/media/zahid/Ads Power/Enterprise Infosec Consultants/ComplyWiseApi/venv/lib/python3.11/site-packages/django/db/models/query.py", line 124, in __iter__
    obj = model_cls.from_db(
          ^^^^^^^^^^^^^^^^^^
  File "/media/zahid/Ads Power/Enterprise Infosec Consultants/ComplyWiseApi/venv/lib/python3.11/site-packages/django/db/models/base.py", line 582, in from_db
    new = cls(*values)
          ^^^^^^^^^^^^
  File "/media/zahid/Ads Power/Enterprise Infosec Consultants/ComplyWiseApi/venv/lib/python3.11/site-packages/django/db/models/base.py", line 491, in __init__
    _setattr(self, field.attname, val)
  File "/media/zahid/Ads Power/Enterprise Infosec Consultants/ComplyWiseApi/venv/lib/python3.11/site-packages/django/db/models/fields/related_descriptors.py", line 665, in __set__
    raise TypeError(
TypeError: Direct assignment to the reverse side of a related set is prohibited. Use files.set() instead.
ERROR 2025-03-04 06:19:19,280 basehttp "GET /api/employees/ HTTP/1.1" 500 152288
ERROR 2025-03-04 06:24:16,161 log Internal Server Error: /api/employees/
Traceback (most recent call last):
  File "/media/zahid/Ads Power/Enterprise Infosec Consultants/ComplyWiseApi/venv/lib/python3.11/site-packages/django/core/handlers/exception.py", line 55, in inner
    response = get_response(request)
               ^^^^^^^^^^^^^^^^^^^^^
  File "/media/zahid/Ads Power/Enterprise Infosec Consultants/ComplyWiseApi/venv/lib/python3.11/site-packages/django/core/handlers/base.py", line 197, in _get_response
    response = wrapped_callback(request, *callback_args, **callback_kwargs)
               ^^^^^^^^^^^^^^^^^^^^^^^^^^^^^^^^^^^^^^^^^^^^^^^^^^^^^^^^^^^^
  File "/media/zahid/Ads Power/Enterprise Infosec Consultants/ComplyWiseApi/venv/lib/python3.11/site-packages/django/views/decorators/csrf.py", line 65, in _view_wrapper
    return view_func(request, *args, **kwargs)
           ^^^^^^^^^^^^^^^^^^^^^^^^^^^^^^^^^^^
  File "/media/zahid/Ads Power/Enterprise Infosec Consultants/ComplyWiseApi/venv/lib/python3.11/site-packages/rest_framework/viewsets.py", line 124, in view
    return self.dispatch(request, *args, **kwargs)
           ^^^^^^^^^^^^^^^^^^^^^^^^^^^^^^^^^^^^^^^
  File "/media/zahid/Ads Power/Enterprise Infosec Consultants/ComplyWiseApi/venv/lib/python3.11/site-packages/rest_framework/views.py", line 509, in dispatch
    response = self.handle_exception(exc)
               ^^^^^^^^^^^^^^^^^^^^^^^^^^
  File "/media/zahid/Ads Power/Enterprise Infosec Consultants/ComplyWiseApi/venv/lib/python3.11/site-packages/rest_framework/views.py", line 469, in handle_exception
    self.raise_uncaught_exception(exc)
  File "/media/zahid/Ads Power/Enterprise Infosec Consultants/ComplyWiseApi/venv/lib/python3.11/site-packages/rest_framework/views.py", line 480, in raise_uncaught_exception
    raise exc
  File "/media/zahid/Ads Power/Enterprise Infosec Consultants/ComplyWiseApi/venv/lib/python3.11/site-packages/rest_framework/views.py", line 506, in dispatch
    response = handler(request, *args, **kwargs)
               ^^^^^^^^^^^^^^^^^^^^^^^^^^^^^^^^^
  File "/media/zahid/Ads Power/Enterprise Infosec Consultants/ComplyWiseApi/venv/lib/python3.11/site-packages/rest_framework/mixins.py", line 46, in list
    return Response(serializer.data)
                    ^^^^^^^^^^^^^^^
  File "/media/zahid/Ads Power/Enterprise Infosec Consultants/ComplyWiseApi/venv/lib/python3.11/site-packages/rest_framework/serializers.py", line 795, in data
    ret = super().data
          ^^^^^^^^^^^^
  File "/media/zahid/Ads Power/Enterprise Infosec Consultants/ComplyWiseApi/venv/lib/python3.11/site-packages/rest_framework/serializers.py", line 249, in data
    self._data = self.to_representation(self.instance)
                 ^^^^^^^^^^^^^^^^^^^^^^^^^^^^^^^^^^^^^
  File "/media/zahid/Ads Power/Enterprise Infosec Consultants/ComplyWiseApi/venv/lib/python3.11/site-packages/rest_framework/serializers.py", line 713, in to_representation
    return [
           ^
  File "/media/zahid/Ads Power/Enterprise Infosec Consultants/ComplyWiseApi/venv/lib/python3.11/site-packages/django/db/models/query.py", line 400, in __iter__
    self._fetch_all()
  File "/media/zahid/Ads Power/Enterprise Infosec Consultants/ComplyWiseApi/venv/lib/python3.11/site-packages/django/db/models/query.py", line 1928, in _fetch_all
    self._result_cache = list(self._iterable_class(self))
                         ^^^^^^^^^^^^^^^^^^^^^^^^^^^^^^^^
  File "/media/zahid/Ads Power/Enterprise Infosec Consultants/ComplyWiseApi/venv/lib/python3.11/site-packages/django/db/models/query.py", line 124, in __iter__
    obj = model_cls.from_db(
          ^^^^^^^^^^^^^^^^^^
  File "/media/zahid/Ads Power/Enterprise Infosec Consultants/ComplyWiseApi/venv/lib/python3.11/site-packages/django/db/models/base.py", line 582, in from_db
    new = cls(*values)
          ^^^^^^^^^^^^
  File "/media/zahid/Ads Power/Enterprise Infosec Consultants/ComplyWiseApi/venv/lib/python3.11/site-packages/django/db/models/base.py", line 491, in __init__
    _setattr(self, field.attname, val)
  File "/media/zahid/Ads Power/Enterprise Infosec Consultants/ComplyWiseApi/venv/lib/python3.11/site-packages/django/db/models/fields/related_descriptors.py", line 665, in __set__
    raise TypeError(
TypeError: Direct assignment to the reverse side of a related set is prohibited. Use files.set() instead.
ERROR 2025-03-04 06:24:16,166 basehttp "GET /api/employees/ HTTP/1.1" 500 152288
ERROR 2025-03-04 06:27:15,736 log Internal Server Error: /api/employees/
Traceback (most recent call last):
  File "/media/zahid/Ads Power/Enterprise Infosec Consultants/ComplyWiseApi/venv/lib/python3.11/site-packages/django/core/handlers/exception.py", line 55, in inner
    response = get_response(request)
               ^^^^^^^^^^^^^^^^^^^^^
  File "/media/zahid/Ads Power/Enterprise Infosec Consultants/ComplyWiseApi/venv/lib/python3.11/site-packages/django/core/handlers/base.py", line 197, in _get_response
    response = wrapped_callback(request, *callback_args, **callback_kwargs)
               ^^^^^^^^^^^^^^^^^^^^^^^^^^^^^^^^^^^^^^^^^^^^^^^^^^^^^^^^^^^^
  File "/media/zahid/Ads Power/Enterprise Infosec Consultants/ComplyWiseApi/venv/lib/python3.11/site-packages/django/views/decorators/csrf.py", line 65, in _view_wrapper
    return view_func(request, *args, **kwargs)
           ^^^^^^^^^^^^^^^^^^^^^^^^^^^^^^^^^^^
  File "/media/zahid/Ads Power/Enterprise Infosec Consultants/ComplyWiseApi/venv/lib/python3.11/site-packages/rest_framework/viewsets.py", line 124, in view
    return self.dispatch(request, *args, **kwargs)
           ^^^^^^^^^^^^^^^^^^^^^^^^^^^^^^^^^^^^^^^
  File "/media/zahid/Ads Power/Enterprise Infosec Consultants/ComplyWiseApi/venv/lib/python3.11/site-packages/rest_framework/views.py", line 509, in dispatch
    response = self.handle_exception(exc)
               ^^^^^^^^^^^^^^^^^^^^^^^^^^
  File "/media/zahid/Ads Power/Enterprise Infosec Consultants/ComplyWiseApi/venv/lib/python3.11/site-packages/rest_framework/views.py", line 469, in handle_exception
    self.raise_uncaught_exception(exc)
  File "/media/zahid/Ads Power/Enterprise Infosec Consultants/ComplyWiseApi/venv/lib/python3.11/site-packages/rest_framework/views.py", line 480, in raise_uncaught_exception
    raise exc
  File "/media/zahid/Ads Power/Enterprise Infosec Consultants/ComplyWiseApi/venv/lib/python3.11/site-packages/rest_framework/views.py", line 506, in dispatch
    response = handler(request, *args, **kwargs)
               ^^^^^^^^^^^^^^^^^^^^^^^^^^^^^^^^^
  File "/media/zahid/Ads Power/Enterprise Infosec Consultants/ComplyWiseApi/venv/lib/python3.11/site-packages/rest_framework/mixins.py", line 46, in list
    return Response(serializer.data)
                    ^^^^^^^^^^^^^^^
  File "/media/zahid/Ads Power/Enterprise Infosec Consultants/ComplyWiseApi/venv/lib/python3.11/site-packages/rest_framework/serializers.py", line 795, in data
    ret = super().data
          ^^^^^^^^^^^^
  File "/media/zahid/Ads Power/Enterprise Infosec Consultants/ComplyWiseApi/venv/lib/python3.11/site-packages/rest_framework/serializers.py", line 249, in data
    self._data = self.to_representation(self.instance)
                 ^^^^^^^^^^^^^^^^^^^^^^^^^^^^^^^^^^^^^
  File "/media/zahid/Ads Power/Enterprise Infosec Consultants/ComplyWiseApi/venv/lib/python3.11/site-packages/rest_framework/serializers.py", line 713, in to_representation
    return [
           ^
  File "/media/zahid/Ads Power/Enterprise Infosec Consultants/ComplyWiseApi/venv/lib/python3.11/site-packages/django/db/models/query.py", line 400, in __iter__
    self._fetch_all()
  File "/media/zahid/Ads Power/Enterprise Infosec Consultants/ComplyWiseApi/venv/lib/python3.11/site-packages/django/db/models/query.py", line 1928, in _fetch_all
    self._result_cache = list(self._iterable_class(self))
                         ^^^^^^^^^^^^^^^^^^^^^^^^^^^^^^^^
  File "/media/zahid/Ads Power/Enterprise Infosec Consultants/ComplyWiseApi/venv/lib/python3.11/site-packages/django/db/models/query.py", line 124, in __iter__
    obj = model_cls.from_db(
          ^^^^^^^^^^^^^^^^^^
  File "/media/zahid/Ads Power/Enterprise Infosec Consultants/ComplyWiseApi/venv/lib/python3.11/site-packages/django/db/models/base.py", line 582, in from_db
    new = cls(*values)
          ^^^^^^^^^^^^
  File "/media/zahid/Ads Power/Enterprise Infosec Consultants/ComplyWiseApi/venv/lib/python3.11/site-packages/django/db/models/base.py", line 491, in __init__
    _setattr(self, field.attname, val)
  File "/media/zahid/Ads Power/Enterprise Infosec Consultants/ComplyWiseApi/venv/lib/python3.11/site-packages/django/db/models/fields/related_descriptors.py", line 665, in __set__
    raise TypeError(
TypeError: Direct assignment to the reverse side of a related set is prohibited. Use files.set() instead.
ERROR 2025-03-04 06:27:15,744 basehttp "GET /api/employees/ HTTP/1.1" 500 152288
ERROR 2025-03-04 06:28:11,627 log Internal Server Error: /api/employees/
Traceback (most recent call last):
  File "/media/zahid/Ads Power/Enterprise Infosec Consultants/ComplyWiseApi/venv/lib/python3.11/site-packages/django/core/handlers/exception.py", line 55, in inner
    response = get_response(request)
               ^^^^^^^^^^^^^^^^^^^^^
  File "/media/zahid/Ads Power/Enterprise Infosec Consultants/ComplyWiseApi/venv/lib/python3.11/site-packages/django/core/handlers/base.py", line 197, in _get_response
    response = wrapped_callback(request, *callback_args, **callback_kwargs)
               ^^^^^^^^^^^^^^^^^^^^^^^^^^^^^^^^^^^^^^^^^^^^^^^^^^^^^^^^^^^^
  File "/media/zahid/Ads Power/Enterprise Infosec Consultants/ComplyWiseApi/venv/lib/python3.11/site-packages/django/views/decorators/csrf.py", line 65, in _view_wrapper
    return view_func(request, *args, **kwargs)
           ^^^^^^^^^^^^^^^^^^^^^^^^^^^^^^^^^^^
  File "/media/zahid/Ads Power/Enterprise Infosec Consultants/ComplyWiseApi/venv/lib/python3.11/site-packages/rest_framework/viewsets.py", line 124, in view
    return self.dispatch(request, *args, **kwargs)
           ^^^^^^^^^^^^^^^^^^^^^^^^^^^^^^^^^^^^^^^
  File "/media/zahid/Ads Power/Enterprise Infosec Consultants/ComplyWiseApi/venv/lib/python3.11/site-packages/rest_framework/views.py", line 509, in dispatch
    response = self.handle_exception(exc)
               ^^^^^^^^^^^^^^^^^^^^^^^^^^
  File "/media/zahid/Ads Power/Enterprise Infosec Consultants/ComplyWiseApi/venv/lib/python3.11/site-packages/rest_framework/views.py", line 469, in handle_exception
    self.raise_uncaught_exception(exc)
  File "/media/zahid/Ads Power/Enterprise Infosec Consultants/ComplyWiseApi/venv/lib/python3.11/site-packages/rest_framework/views.py", line 480, in raise_uncaught_exception
    raise exc
  File "/media/zahid/Ads Power/Enterprise Infosec Consultants/ComplyWiseApi/venv/lib/python3.11/site-packages/rest_framework/views.py", line 506, in dispatch
    response = handler(request, *args, **kwargs)
               ^^^^^^^^^^^^^^^^^^^^^^^^^^^^^^^^^
  File "/media/zahid/Ads Power/Enterprise Infosec Consultants/ComplyWiseApi/venv/lib/python3.11/site-packages/rest_framework/mixins.py", line 46, in list
    return Response(serializer.data)
                    ^^^^^^^^^^^^^^^
  File "/media/zahid/Ads Power/Enterprise Infosec Consultants/ComplyWiseApi/venv/lib/python3.11/site-packages/rest_framework/serializers.py", line 795, in data
    ret = super().data
          ^^^^^^^^^^^^
  File "/media/zahid/Ads Power/Enterprise Infosec Consultants/ComplyWiseApi/venv/lib/python3.11/site-packages/rest_framework/serializers.py", line 249, in data
    self._data = self.to_representation(self.instance)
                 ^^^^^^^^^^^^^^^^^^^^^^^^^^^^^^^^^^^^^
  File "/media/zahid/Ads Power/Enterprise Infosec Consultants/ComplyWiseApi/venv/lib/python3.11/site-packages/rest_framework/serializers.py", line 713, in to_representation
    return [
           ^
  File "/media/zahid/Ads Power/Enterprise Infosec Consultants/ComplyWiseApi/venv/lib/python3.11/site-packages/django/db/models/query.py", line 400, in __iter__
    self._fetch_all()
  File "/media/zahid/Ads Power/Enterprise Infosec Consultants/ComplyWiseApi/venv/lib/python3.11/site-packages/django/db/models/query.py", line 1928, in _fetch_all
    self._result_cache = list(self._iterable_class(self))
                         ^^^^^^^^^^^^^^^^^^^^^^^^^^^^^^^^
  File "/media/zahid/Ads Power/Enterprise Infosec Consultants/ComplyWiseApi/venv/lib/python3.11/site-packages/django/db/models/query.py", line 124, in __iter__
    obj = model_cls.from_db(
          ^^^^^^^^^^^^^^^^^^
  File "/media/zahid/Ads Power/Enterprise Infosec Consultants/ComplyWiseApi/venv/lib/python3.11/site-packages/django/db/models/base.py", line 582, in from_db
    new = cls(*values)
          ^^^^^^^^^^^^
  File "/media/zahid/Ads Power/Enterprise Infosec Consultants/ComplyWiseApi/venv/lib/python3.11/site-packages/django/db/models/base.py", line 491, in __init__
    _setattr(self, field.attname, val)
  File "/media/zahid/Ads Power/Enterprise Infosec Consultants/ComplyWiseApi/venv/lib/python3.11/site-packages/django/db/models/fields/related_descriptors.py", line 665, in __set__
    raise TypeError(
TypeError: Direct assignment to the reverse side of a related set is prohibited. Use files.set() instead.
ERROR 2025-03-04 06:28:11,632 basehttp "GET /api/employees/ HTTP/1.1" 500 152288
ERROR 2025-03-04 06:30:16,022 log Internal Server Error: /api/employees/
Traceback (most recent call last):
  File "/media/zahid/Ads Power/Enterprise Infosec Consultants/ComplyWiseApi/venv/lib/python3.11/site-packages/django/core/handlers/exception.py", line 55, in inner
    response = get_response(request)
               ^^^^^^^^^^^^^^^^^^^^^
  File "/media/zahid/Ads Power/Enterprise Infosec Consultants/ComplyWiseApi/venv/lib/python3.11/site-packages/django/core/handlers/base.py", line 197, in _get_response
    response = wrapped_callback(request, *callback_args, **callback_kwargs)
               ^^^^^^^^^^^^^^^^^^^^^^^^^^^^^^^^^^^^^^^^^^^^^^^^^^^^^^^^^^^^
  File "/media/zahid/Ads Power/Enterprise Infosec Consultants/ComplyWiseApi/venv/lib/python3.11/site-packages/django/views/decorators/csrf.py", line 65, in _view_wrapper
    return view_func(request, *args, **kwargs)
           ^^^^^^^^^^^^^^^^^^^^^^^^^^^^^^^^^^^
  File "/media/zahid/Ads Power/Enterprise Infosec Consultants/ComplyWiseApi/venv/lib/python3.11/site-packages/rest_framework/viewsets.py", line 124, in view
    return self.dispatch(request, *args, **kwargs)
           ^^^^^^^^^^^^^^^^^^^^^^^^^^^^^^^^^^^^^^^
  File "/media/zahid/Ads Power/Enterprise Infosec Consultants/ComplyWiseApi/venv/lib/python3.11/site-packages/rest_framework/views.py", line 509, in dispatch
    response = self.handle_exception(exc)
               ^^^^^^^^^^^^^^^^^^^^^^^^^^
  File "/media/zahid/Ads Power/Enterprise Infosec Consultants/ComplyWiseApi/venv/lib/python3.11/site-packages/rest_framework/views.py", line 469, in handle_exception
    self.raise_uncaught_exception(exc)
  File "/media/zahid/Ads Power/Enterprise Infosec Consultants/ComplyWiseApi/venv/lib/python3.11/site-packages/rest_framework/views.py", line 480, in raise_uncaught_exception
    raise exc
  File "/media/zahid/Ads Power/Enterprise Infosec Consultants/ComplyWiseApi/venv/lib/python3.11/site-packages/rest_framework/views.py", line 506, in dispatch
    response = handler(request, *args, **kwargs)
               ^^^^^^^^^^^^^^^^^^^^^^^^^^^^^^^^^
  File "/media/zahid/Ads Power/Enterprise Infosec Consultants/ComplyWiseApi/venv/lib/python3.11/site-packages/rest_framework/mixins.py", line 46, in list
    return Response(serializer.data)
                    ^^^^^^^^^^^^^^^
  File "/media/zahid/Ads Power/Enterprise Infosec Consultants/ComplyWiseApi/venv/lib/python3.11/site-packages/rest_framework/serializers.py", line 795, in data
    ret = super().data
          ^^^^^^^^^^^^
  File "/media/zahid/Ads Power/Enterprise Infosec Consultants/ComplyWiseApi/venv/lib/python3.11/site-packages/rest_framework/serializers.py", line 249, in data
    self._data = self.to_representation(self.instance)
                 ^^^^^^^^^^^^^^^^^^^^^^^^^^^^^^^^^^^^^
  File "/media/zahid/Ads Power/Enterprise Infosec Consultants/ComplyWiseApi/venv/lib/python3.11/site-packages/rest_framework/serializers.py", line 713, in to_representation
    return [
           ^
  File "/media/zahid/Ads Power/Enterprise Infosec Consultants/ComplyWiseApi/venv/lib/python3.11/site-packages/django/db/models/query.py", line 400, in __iter__
    self._fetch_all()
  File "/media/zahid/Ads Power/Enterprise Infosec Consultants/ComplyWiseApi/venv/lib/python3.11/site-packages/django/db/models/query.py", line 1928, in _fetch_all
    self._result_cache = list(self._iterable_class(self))
                         ^^^^^^^^^^^^^^^^^^^^^^^^^^^^^^^^
  File "/media/zahid/Ads Power/Enterprise Infosec Consultants/ComplyWiseApi/venv/lib/python3.11/site-packages/django/db/models/query.py", line 124, in __iter__
    obj = model_cls.from_db(
          ^^^^^^^^^^^^^^^^^^
  File "/media/zahid/Ads Power/Enterprise Infosec Consultants/ComplyWiseApi/venv/lib/python3.11/site-packages/django/db/models/base.py", line 582, in from_db
    new = cls(*values)
          ^^^^^^^^^^^^
  File "/media/zahid/Ads Power/Enterprise Infosec Consultants/ComplyWiseApi/venv/lib/python3.11/site-packages/django/db/models/base.py", line 491, in __init__
    _setattr(self, field.attname, val)
  File "/media/zahid/Ads Power/Enterprise Infosec Consultants/ComplyWiseApi/venv/lib/python3.11/site-packages/django/db/models/fields/related_descriptors.py", line 665, in __set__
    raise TypeError(
TypeError: Direct assignment to the reverse side of a related set is prohibited. Use files.set() instead.
ERROR 2025-03-04 06:30:16,025 basehttp "GET /api/employees/ HTTP/1.1" 500 152288
ERROR 2025-03-04 11:06:20,363 log Internal Server Error: /api/employees/
Traceback (most recent call last):
  File "/media/zahid/Ads Power/Enterprise Infosec Consultants/ComplyWiseApi/venv/lib/python3.11/site-packages/django/core/handlers/exception.py", line 55, in inner
    response = get_response(request)
               ^^^^^^^^^^^^^^^^^^^^^
  File "/media/zahid/Ads Power/Enterprise Infosec Consultants/ComplyWiseApi/venv/lib/python3.11/site-packages/django/core/handlers/base.py", line 197, in _get_response
    response = wrapped_callback(request, *callback_args, **callback_kwargs)
               ^^^^^^^^^^^^^^^^^^^^^^^^^^^^^^^^^^^^^^^^^^^^^^^^^^^^^^^^^^^^
  File "/media/zahid/Ads Power/Enterprise Infosec Consultants/ComplyWiseApi/venv/lib/python3.11/site-packages/django/views/decorators/csrf.py", line 65, in _view_wrapper
    return view_func(request, *args, **kwargs)
           ^^^^^^^^^^^^^^^^^^^^^^^^^^^^^^^^^^^
  File "/media/zahid/Ads Power/Enterprise Infosec Consultants/ComplyWiseApi/venv/lib/python3.11/site-packages/rest_framework/viewsets.py", line 124, in view
    return self.dispatch(request, *args, **kwargs)
           ^^^^^^^^^^^^^^^^^^^^^^^^^^^^^^^^^^^^^^^
  File "/media/zahid/Ads Power/Enterprise Infosec Consultants/ComplyWiseApi/venv/lib/python3.11/site-packages/rest_framework/views.py", line 509, in dispatch
    response = self.handle_exception(exc)
               ^^^^^^^^^^^^^^^^^^^^^^^^^^
  File "/media/zahid/Ads Power/Enterprise Infosec Consultants/ComplyWiseApi/venv/lib/python3.11/site-packages/rest_framework/views.py", line 469, in handle_exception
    self.raise_uncaught_exception(exc)
  File "/media/zahid/Ads Power/Enterprise Infosec Consultants/ComplyWiseApi/venv/lib/python3.11/site-packages/rest_framework/views.py", line 480, in raise_uncaught_exception
    raise exc
  File "/media/zahid/Ads Power/Enterprise Infosec Consultants/ComplyWiseApi/venv/lib/python3.11/site-packages/rest_framework/views.py", line 506, in dispatch
    response = handler(request, *args, **kwargs)
               ^^^^^^^^^^^^^^^^^^^^^^^^^^^^^^^^^
  File "/media/zahid/Ads Power/Enterprise Infosec Consultants/ComplyWiseApi/venv/lib/python3.11/site-packages/rest_framework/mixins.py", line 46, in list
    return Response(serializer.data)
                    ^^^^^^^^^^^^^^^
  File "/media/zahid/Ads Power/Enterprise Infosec Consultants/ComplyWiseApi/venv/lib/python3.11/site-packages/rest_framework/serializers.py", line 795, in data
    ret = super().data
          ^^^^^^^^^^^^
  File "/media/zahid/Ads Power/Enterprise Infosec Consultants/ComplyWiseApi/venv/lib/python3.11/site-packages/rest_framework/serializers.py", line 249, in data
    self._data = self.to_representation(self.instance)
                 ^^^^^^^^^^^^^^^^^^^^^^^^^^^^^^^^^^^^^
  File "/media/zahid/Ads Power/Enterprise Infosec Consultants/ComplyWiseApi/venv/lib/python3.11/site-packages/rest_framework/serializers.py", line 713, in to_representation
    return [
           ^
  File "/media/zahid/Ads Power/Enterprise Infosec Consultants/ComplyWiseApi/venv/lib/python3.11/site-packages/rest_framework/serializers.py", line 714, in <listcomp>
    self.child.to_representation(item) for item in iterable
    ^^^^^^^^^^^^^^^^^^^^^^^^^^^^^^^^^^
  File "/media/zahid/Ads Power/Enterprise Infosec Consultants/ComplyWiseApi/venv/lib/python3.11/site-packages/rest_framework/serializers.py", line 523, in to_representation
    for field in fields:
  File "/media/zahid/Ads Power/Enterprise Infosec Consultants/ComplyWiseApi/venv/lib/python3.11/site-packages/rest_framework/serializers.py", line 384, in _readable_fields
    for field in self.fields.values():
                 ^^^^^^^^^^^
  File "/media/zahid/Ads Power/Enterprise Infosec Consultants/ComplyWiseApi/venv/lib/python3.11/site-packages/django/utils/functional.py", line 47, in __get__
    res = instance.__dict__[self.name] = self.func(instance)
                                         ^^^^^^^^^^^^^^^^^^^
  File "/media/zahid/Ads Power/Enterprise Infosec Consultants/ComplyWiseApi/venv/lib/python3.11/site-packages/rest_framework/serializers.py", line 372, in fields
    for key, value in self.get_fields().items():
                      ^^^^^^^^^^^^^^^^^
  File "/media/zahid/Ads Power/Enterprise Infosec Consultants/ComplyWiseApi/venv/lib/python3.11/site-packages/rest_framework/serializers.py", line 1079, in get_fields
    field_names = self.get_field_names(declared_fields, info)
                  ^^^^^^^^^^^^^^^^^^^^^^^^^^^^^^^^^^^^^^^^^^^
  File "/media/zahid/Ads Power/Enterprise Infosec Consultants/ComplyWiseApi/venv/lib/python3.11/site-packages/rest_framework/serializers.py", line 1175, in get_field_names
    assert field_name in fields, (
           ^^^^^^^^^^^^^^^^^^^^
AssertionError: The field 'documents' was declared on serializer EmployeeSerializer, but has not been included in the 'fields' option.
ERROR 2025-03-04 11:06:20,367 basehttp "GET /api/employees/ HTTP/1.1" 500 156347
ERROR 2025-03-04 17:14:22,877 log Internal Server Error: /api/employees/
Traceback (most recent call last):
  File "/media/zahid/Ads Power/Enterprise Infosec Consultants/ComplyWiseApi/venv/lib/python3.11/site-packages/django/core/handlers/exception.py", line 55, in inner
    response = get_response(request)
               ^^^^^^^^^^^^^^^^^^^^^
  File "/media/zahid/Ads Power/Enterprise Infosec Consultants/ComplyWiseApi/venv/lib/python3.11/site-packages/django/core/handlers/base.py", line 197, in _get_response
    response = wrapped_callback(request, *callback_args, **callback_kwargs)
               ^^^^^^^^^^^^^^^^^^^^^^^^^^^^^^^^^^^^^^^^^^^^^^^^^^^^^^^^^^^^
  File "/media/zahid/Ads Power/Enterprise Infosec Consultants/ComplyWiseApi/venv/lib/python3.11/site-packages/django/views/decorators/csrf.py", line 65, in _view_wrapper
    return view_func(request, *args, **kwargs)
           ^^^^^^^^^^^^^^^^^^^^^^^^^^^^^^^^^^^
  File "/media/zahid/Ads Power/Enterprise Infosec Consultants/ComplyWiseApi/venv/lib/python3.11/site-packages/rest_framework/viewsets.py", line 124, in view
    return self.dispatch(request, *args, **kwargs)
           ^^^^^^^^^^^^^^^^^^^^^^^^^^^^^^^^^^^^^^^
  File "/media/zahid/Ads Power/Enterprise Infosec Consultants/ComplyWiseApi/venv/lib/python3.11/site-packages/rest_framework/views.py", line 509, in dispatch
    response = self.handle_exception(exc)
               ^^^^^^^^^^^^^^^^^^^^^^^^^^
  File "/media/zahid/Ads Power/Enterprise Infosec Consultants/ComplyWiseApi/venv/lib/python3.11/site-packages/rest_framework/views.py", line 469, in handle_exception
    self.raise_uncaught_exception(exc)
  File "/media/zahid/Ads Power/Enterprise Infosec Consultants/ComplyWiseApi/venv/lib/python3.11/site-packages/rest_framework/views.py", line 480, in raise_uncaught_exception
    raise exc
  File "/media/zahid/Ads Power/Enterprise Infosec Consultants/ComplyWiseApi/venv/lib/python3.11/site-packages/rest_framework/views.py", line 506, in dispatch
    response = handler(request, *args, **kwargs)
               ^^^^^^^^^^^^^^^^^^^^^^^^^^^^^^^^^
  File "/media/zahid/Ads Power/Enterprise Infosec Consultants/ComplyWiseApi/app/modules/access_control/views/employee.py", line 22, in create
    File.objects.create(employee=employee, file=file)
    ^^^^
NameError: name 'File' is not defined
ERROR 2025-03-04 17:14:22,892 basehttp "POST /api/employees/ HTTP/1.1" 500 108657
ERROR 2025-03-04 17:15:35,034 log Internal Server Error: /api/employees/
Traceback (most recent call last):
  File "/media/zahid/Ads Power/Enterprise Infosec Consultants/ComplyWiseApi/venv/lib/python3.11/site-packages/django/core/handlers/exception.py", line 55, in inner
    response = get_response(request)
               ^^^^^^^^^^^^^^^^^^^^^
  File "/media/zahid/Ads Power/Enterprise Infosec Consultants/ComplyWiseApi/venv/lib/python3.11/site-packages/django/core/handlers/base.py", line 197, in _get_response
    response = wrapped_callback(request, *callback_args, **callback_kwargs)
               ^^^^^^^^^^^^^^^^^^^^^^^^^^^^^^^^^^^^^^^^^^^^^^^^^^^^^^^^^^^^
  File "/media/zahid/Ads Power/Enterprise Infosec Consultants/ComplyWiseApi/venv/lib/python3.11/site-packages/django/views/decorators/csrf.py", line 65, in _view_wrapper
    return view_func(request, *args, **kwargs)
           ^^^^^^^^^^^^^^^^^^^^^^^^^^^^^^^^^^^
  File "/media/zahid/Ads Power/Enterprise Infosec Consultants/ComplyWiseApi/venv/lib/python3.11/site-packages/rest_framework/viewsets.py", line 124, in view
    return self.dispatch(request, *args, **kwargs)
           ^^^^^^^^^^^^^^^^^^^^^^^^^^^^^^^^^^^^^^^
  File "/media/zahid/Ads Power/Enterprise Infosec Consultants/ComplyWiseApi/venv/lib/python3.11/site-packages/rest_framework/views.py", line 509, in dispatch
    response = self.handle_exception(exc)
               ^^^^^^^^^^^^^^^^^^^^^^^^^^
  File "/media/zahid/Ads Power/Enterprise Infosec Consultants/ComplyWiseApi/venv/lib/python3.11/site-packages/rest_framework/views.py", line 469, in handle_exception
    self.raise_uncaught_exception(exc)
  File "/media/zahid/Ads Power/Enterprise Infosec Consultants/ComplyWiseApi/venv/lib/python3.11/site-packages/rest_framework/views.py", line 480, in raise_uncaught_exception
    raise exc
  File "/media/zahid/Ads Power/Enterprise Infosec Consultants/ComplyWiseApi/venv/lib/python3.11/site-packages/rest_framework/views.py", line 506, in dispatch
    response = handler(request, *args, **kwargs)
               ^^^^^^^^^^^^^^^^^^^^^^^^^^^^^^^^^
  File "/media/zahid/Ads Power/Enterprise Infosec Consultants/ComplyWiseApi/app/modules/access_control/views/employee.py", line 22, in create
    File.objects.create(employee=employee, file=file)
    ^^^^
NameError: name 'File' is not defined
ERROR 2025-03-04 17:15:35,042 basehttp "POST /api/employees/ HTTP/1.1" 500 108663
ERROR 2025-03-04 17:28:41,315 log Internal Server Error: /api/employees/
Traceback (most recent call last):
  File "/media/zahid/Ads Power/Enterprise Infosec Consultants/ComplyWiseApi/venv/lib/python3.11/site-packages/django/core/handlers/exception.py", line 55, in inner
    response = get_response(request)
               ^^^^^^^^^^^^^^^^^^^^^
  File "/media/zahid/Ads Power/Enterprise Infosec Consultants/ComplyWiseApi/venv/lib/python3.11/site-packages/django/core/handlers/base.py", line 197, in _get_response
    response = wrapped_callback(request, *callback_args, **callback_kwargs)
               ^^^^^^^^^^^^^^^^^^^^^^^^^^^^^^^^^^^^^^^^^^^^^^^^^^^^^^^^^^^^
  File "/media/zahid/Ads Power/Enterprise Infosec Consultants/ComplyWiseApi/venv/lib/python3.11/site-packages/django/views/decorators/csrf.py", line 65, in _view_wrapper
    return view_func(request, *args, **kwargs)
           ^^^^^^^^^^^^^^^^^^^^^^^^^^^^^^^^^^^
  File "/media/zahid/Ads Power/Enterprise Infosec Consultants/ComplyWiseApi/venv/lib/python3.11/site-packages/rest_framework/viewsets.py", line 124, in view
    return self.dispatch(request, *args, **kwargs)
           ^^^^^^^^^^^^^^^^^^^^^^^^^^^^^^^^^^^^^^^
  File "/media/zahid/Ads Power/Enterprise Infosec Consultants/ComplyWiseApi/venv/lib/python3.11/site-packages/rest_framework/views.py", line 509, in dispatch
    response = self.handle_exception(exc)
               ^^^^^^^^^^^^^^^^^^^^^^^^^^
  File "/media/zahid/Ads Power/Enterprise Infosec Consultants/ComplyWiseApi/venv/lib/python3.11/site-packages/rest_framework/views.py", line 469, in handle_exception
    self.raise_uncaught_exception(exc)
  File "/media/zahid/Ads Power/Enterprise Infosec Consultants/ComplyWiseApi/venv/lib/python3.11/site-packages/rest_framework/views.py", line 480, in raise_uncaught_exception
    raise exc
  File "/media/zahid/Ads Power/Enterprise Infosec Consultants/ComplyWiseApi/venv/lib/python3.11/site-packages/rest_framework/views.py", line 506, in dispatch
    response = handler(request, *args, **kwargs)
               ^^^^^^^^^^^^^^^^^^^^^^^^^^^^^^^^^
  File "/media/zahid/Ads Power/Enterprise Infosec Consultants/ComplyWiseApi/app/modules/access_control/views/employee.py", line 22, in create
    File.objects.create(employee=employee, document=document)
    ^^^^
NameError: name 'File' is not defined
ERROR 2025-03-04 17:28:41,327 basehttp "POST /api/employees/ HTTP/1.1" 500 108719
ERROR 2025-03-04 17:30:09,432 log Internal Server Error: /api/employees/
Traceback (most recent call last):
  File "/media/zahid/Ads Power/Enterprise Infosec Consultants/ComplyWiseApi/venv/lib/python3.11/site-packages/django/core/handlers/exception.py", line 55, in inner
    response = get_response(request)
               ^^^^^^^^^^^^^^^^^^^^^
  File "/media/zahid/Ads Power/Enterprise Infosec Consultants/ComplyWiseApi/venv/lib/python3.11/site-packages/django/core/handlers/base.py", line 197, in _get_response
    response = wrapped_callback(request, *callback_args, **callback_kwargs)
               ^^^^^^^^^^^^^^^^^^^^^^^^^^^^^^^^^^^^^^^^^^^^^^^^^^^^^^^^^^^^
  File "/media/zahid/Ads Power/Enterprise Infosec Consultants/ComplyWiseApi/venv/lib/python3.11/site-packages/django/views/decorators/csrf.py", line 65, in _view_wrapper
    return view_func(request, *args, **kwargs)
           ^^^^^^^^^^^^^^^^^^^^^^^^^^^^^^^^^^^
  File "/media/zahid/Ads Power/Enterprise Infosec Consultants/ComplyWiseApi/venv/lib/python3.11/site-packages/rest_framework/viewsets.py", line 124, in view
    return self.dispatch(request, *args, **kwargs)
           ^^^^^^^^^^^^^^^^^^^^^^^^^^^^^^^^^^^^^^^
  File "/media/zahid/Ads Power/Enterprise Infosec Consultants/ComplyWiseApi/venv/lib/python3.11/site-packages/rest_framework/views.py", line 509, in dispatch
    response = self.handle_exception(exc)
               ^^^^^^^^^^^^^^^^^^^^^^^^^^
  File "/media/zahid/Ads Power/Enterprise Infosec Consultants/ComplyWiseApi/venv/lib/python3.11/site-packages/rest_framework/views.py", line 469, in handle_exception
    self.raise_uncaught_exception(exc)
  File "/media/zahid/Ads Power/Enterprise Infosec Consultants/ComplyWiseApi/venv/lib/python3.11/site-packages/rest_framework/views.py", line 480, in raise_uncaught_exception
    raise exc
  File "/media/zahid/Ads Power/Enterprise Infosec Consultants/ComplyWiseApi/venv/lib/python3.11/site-packages/rest_framework/views.py", line 506, in dispatch
    response = handler(request, *args, **kwargs)
               ^^^^^^^^^^^^^^^^^^^^^^^^^^^^^^^^^
  File "/media/zahid/Ads Power/Enterprise Infosec Consultants/ComplyWiseApi/app/modules/access_control/views/employee.py", line 22, in create
    Documents.objects.create(employee=employee, document=document)
  File "/media/zahid/Ads Power/Enterprise Infosec Consultants/ComplyWiseApi/venv/lib/python3.11/site-packages/django/db/models/manager.py", line 87, in manager_method
    return getattr(self.get_queryset(), name)(*args, **kwargs)
           ^^^^^^^^^^^^^^^^^^^^^^^^^^^^^^^^^^^^^^^^^^^^^^^^^^^
  File "/media/zahid/Ads Power/Enterprise Infosec Consultants/ComplyWiseApi/venv/lib/python3.11/site-packages/django/db/models/query.py", line 677, in create
    obj = self.model(**kwargs)
          ^^^^^^^^^^^^^^^^^^^^
  File "/media/zahid/Ads Power/Enterprise Infosec Consultants/ComplyWiseApi/venv/lib/python3.11/site-packages/django/db/models/base.py", line 567, in __init__
    raise TypeError(
TypeError: Documents() got unexpected keyword arguments: 'document'
ERROR 2025-03-04 17:30:09,446 basehttp "POST /api/employees/ HTTP/1.1" 500 125444
ERROR 2025-03-04 17:30:29,190 log Internal Server Error: /api/employees/
Traceback (most recent call last):
  File "/media/zahid/Ads Power/Enterprise Infosec Consultants/ComplyWiseApi/venv/lib/python3.11/site-packages/django/core/handlers/exception.py", line 55, in inner
    response = get_response(request)
               ^^^^^^^^^^^^^^^^^^^^^
  File "/media/zahid/Ads Power/Enterprise Infosec Consultants/ComplyWiseApi/venv/lib/python3.11/site-packages/django/core/handlers/base.py", line 197, in _get_response
    response = wrapped_callback(request, *callback_args, **callback_kwargs)
               ^^^^^^^^^^^^^^^^^^^^^^^^^^^^^^^^^^^^^^^^^^^^^^^^^^^^^^^^^^^^
  File "/media/zahid/Ads Power/Enterprise Infosec Consultants/ComplyWiseApi/venv/lib/python3.11/site-packages/django/views/decorators/csrf.py", line 65, in _view_wrapper
    return view_func(request, *args, **kwargs)
           ^^^^^^^^^^^^^^^^^^^^^^^^^^^^^^^^^^^
  File "/media/zahid/Ads Power/Enterprise Infosec Consultants/ComplyWiseApi/venv/lib/python3.11/site-packages/rest_framework/viewsets.py", line 124, in view
    return self.dispatch(request, *args, **kwargs)
           ^^^^^^^^^^^^^^^^^^^^^^^^^^^^^^^^^^^^^^^
  File "/media/zahid/Ads Power/Enterprise Infosec Consultants/ComplyWiseApi/venv/lib/python3.11/site-packages/rest_framework/views.py", line 509, in dispatch
    response = self.handle_exception(exc)
               ^^^^^^^^^^^^^^^^^^^^^^^^^^
  File "/media/zahid/Ads Power/Enterprise Infosec Consultants/ComplyWiseApi/venv/lib/python3.11/site-packages/rest_framework/views.py", line 469, in handle_exception
    self.raise_uncaught_exception(exc)
  File "/media/zahid/Ads Power/Enterprise Infosec Consultants/ComplyWiseApi/venv/lib/python3.11/site-packages/rest_framework/views.py", line 480, in raise_uncaught_exception
    raise exc
  File "/media/zahid/Ads Power/Enterprise Infosec Consultants/ComplyWiseApi/venv/lib/python3.11/site-packages/rest_framework/views.py", line 506, in dispatch
    response = handler(request, *args, **kwargs)
               ^^^^^^^^^^^^^^^^^^^^^^^^^^^^^^^^^
  File "/media/zahid/Ads Power/Enterprise Infosec Consultants/ComplyWiseApi/app/modules/access_control/views/employee.py", line 22, in create
    Document.objects.create(employee=employee, document=document)
    ^^^^^^^^
NameError: name 'Document' is not defined
ERROR 2025-03-04 17:30:29,199 basehttp "POST /api/employees/ HTTP/1.1" 500 108763
ERROR 2025-03-05 04:41:16,125 log Internal Server Error: /api/employees/
Traceback (most recent call last):
  File "/media/zahid/Ads Power/Enterprise Infosec Consultants/ComplyWiseApi/venv/lib/python3.11/site-packages/django/core/handlers/exception.py", line 55, in inner
    response = get_response(request)
               ^^^^^^^^^^^^^^^^^^^^^
  File "/media/zahid/Ads Power/Enterprise Infosec Consultants/ComplyWiseApi/venv/lib/python3.11/site-packages/django/core/handlers/base.py", line 197, in _get_response
    response = wrapped_callback(request, *callback_args, **callback_kwargs)
               ^^^^^^^^^^^^^^^^^^^^^^^^^^^^^^^^^^^^^^^^^^^^^^^^^^^^^^^^^^^^
  File "/media/zahid/Ads Power/Enterprise Infosec Consultants/ComplyWiseApi/venv/lib/python3.11/site-packages/django/views/decorators/csrf.py", line 65, in _view_wrapper
    return view_func(request, *args, **kwargs)
           ^^^^^^^^^^^^^^^^^^^^^^^^^^^^^^^^^^^
  File "/media/zahid/Ads Power/Enterprise Infosec Consultants/ComplyWiseApi/venv/lib/python3.11/site-packages/rest_framework/viewsets.py", line 124, in view
    return self.dispatch(request, *args, **kwargs)
           ^^^^^^^^^^^^^^^^^^^^^^^^^^^^^^^^^^^^^^^
  File "/media/zahid/Ads Power/Enterprise Infosec Consultants/ComplyWiseApi/venv/lib/python3.11/site-packages/rest_framework/views.py", line 509, in dispatch
    response = self.handle_exception(exc)
               ^^^^^^^^^^^^^^^^^^^^^^^^^^
  File "/media/zahid/Ads Power/Enterprise Infosec Consultants/ComplyWiseApi/venv/lib/python3.11/site-packages/rest_framework/views.py", line 469, in handle_exception
    self.raise_uncaught_exception(exc)
  File "/media/zahid/Ads Power/Enterprise Infosec Consultants/ComplyWiseApi/venv/lib/python3.11/site-packages/rest_framework/views.py", line 480, in raise_uncaught_exception
    raise exc
  File "/media/zahid/Ads Power/Enterprise Infosec Consultants/ComplyWiseApi/venv/lib/python3.11/site-packages/rest_framework/views.py", line 506, in dispatch
    response = handler(request, *args, **kwargs)
               ^^^^^^^^^^^^^^^^^^^^^^^^^^^^^^^^^
  File "/media/zahid/Ads Power/Enterprise Infosec Consultants/ComplyWiseApi/venv/lib/python3.11/site-packages/rest_framework/mixins.py", line 46, in list
    return Response(serializer.data)
                    ^^^^^^^^^^^^^^^
  File "/media/zahid/Ads Power/Enterprise Infosec Consultants/ComplyWiseApi/venv/lib/python3.11/site-packages/rest_framework/serializers.py", line 795, in data
    ret = super().data
          ^^^^^^^^^^^^
  File "/media/zahid/Ads Power/Enterprise Infosec Consultants/ComplyWiseApi/venv/lib/python3.11/site-packages/rest_framework/serializers.py", line 249, in data
    self._data = self.to_representation(self.instance)
                 ^^^^^^^^^^^^^^^^^^^^^^^^^^^^^^^^^^^^^
  File "/media/zahid/Ads Power/Enterprise Infosec Consultants/ComplyWiseApi/venv/lib/python3.11/site-packages/rest_framework/serializers.py", line 713, in to_representation
    return [
           ^
  File "/media/zahid/Ads Power/Enterprise Infosec Consultants/ComplyWiseApi/venv/lib/python3.11/site-packages/rest_framework/serializers.py", line 714, in <listcomp>
    self.child.to_representation(item) for item in iterable
    ^^^^^^^^^^^^^^^^^^^^^^^^^^^^^^^^^^
  File "/media/zahid/Ads Power/Enterprise Infosec Consultants/ComplyWiseApi/venv/lib/python3.11/site-packages/rest_framework/serializers.py", line 523, in to_representation
    for field in fields:
  File "/media/zahid/Ads Power/Enterprise Infosec Consultants/ComplyWiseApi/venv/lib/python3.11/site-packages/rest_framework/serializers.py", line 384, in _readable_fields
    for field in self.fields.values():
                 ^^^^^^^^^^^
  File "/media/zahid/Ads Power/Enterprise Infosec Consultants/ComplyWiseApi/venv/lib/python3.11/site-packages/django/utils/functional.py", line 47, in __get__
    res = instance.__dict__[self.name] = self.func(instance)
                                         ^^^^^^^^^^^^^^^^^^^
  File "/media/zahid/Ads Power/Enterprise Infosec Consultants/ComplyWiseApi/venv/lib/python3.11/site-packages/rest_framework/serializers.py", line 372, in fields
    for key, value in self.get_fields().items():
                      ^^^^^^^^^^^^^^^^^
  File "/media/zahid/Ads Power/Enterprise Infosec Consultants/ComplyWiseApi/venv/lib/python3.11/site-packages/rest_framework/serializers.py", line 1079, in get_fields
    field_names = self.get_field_names(declared_fields, info)
                  ^^^^^^^^^^^^^^^^^^^^^^^^^^^^^^^^^^^^^^^^^^^
  File "/media/zahid/Ads Power/Enterprise Infosec Consultants/ComplyWiseApi/venv/lib/python3.11/site-packages/rest_framework/serializers.py", line 1151, in get_field_names
    assert not (fields is None and exclude is None), (
                                   ^^^^^^^^^^^^^^^
AssertionError: ("Creating a ModelSerializer without either the 'fields' attribute or the 'exclude' attribute has been deprecated since 3.3.0, and is now disallowed. Add an explicit fields = '__all__' to the EmployeeSerializer serializer.",)
ERROR 2025-03-05 04:41:16,133 basehttp "GET /api/employees/ HTTP/1.1" 500 158891
ERROR 2025-03-05 06:02:29,756 log Internal Server Error: /api/employees/
Traceback (most recent call last):
  File "/media/zahid/Ads Power/Enterprise Infosec Consultants/ComplyWiseApi/venv/lib/python3.11/site-packages/django/db/backends/utils.py", line 105, in _execute
    return self.cursor.execute(sql, params)
           ^^^^^^^^^^^^^^^^^^^^^^^^^^^^^^^^
psycopg2.errors.UndefinedColumn: column app_documents.created_at does not exist
LINE 1: SELECT "app_documents"."id", "app_documents"."created_at", "...
                                     ^
HINT:  Perhaps you meant to reference the column "app_documents.updated_at".


The above exception was the direct cause of the following exception:

Traceback (most recent call last):
  File "/media/zahid/Ads Power/Enterprise Infosec Consultants/ComplyWiseApi/venv/lib/python3.11/site-packages/django/core/handlers/exception.py", line 55, in inner
    response = get_response(request)
               ^^^^^^^^^^^^^^^^^^^^^
  File "/media/zahid/Ads Power/Enterprise Infosec Consultants/ComplyWiseApi/venv/lib/python3.11/site-packages/django/core/handlers/base.py", line 197, in _get_response
    response = wrapped_callback(request, *callback_args, **callback_kwargs)
               ^^^^^^^^^^^^^^^^^^^^^^^^^^^^^^^^^^^^^^^^^^^^^^^^^^^^^^^^^^^^
  File "/media/zahid/Ads Power/Enterprise Infosec Consultants/ComplyWiseApi/venv/lib/python3.11/site-packages/django/views/decorators/csrf.py", line 65, in _view_wrapper
    return view_func(request, *args, **kwargs)
           ^^^^^^^^^^^^^^^^^^^^^^^^^^^^^^^^^^^
  File "/media/zahid/Ads Power/Enterprise Infosec Consultants/ComplyWiseApi/venv/lib/python3.11/site-packages/rest_framework/viewsets.py", line 124, in view
    return self.dispatch(request, *args, **kwargs)
           ^^^^^^^^^^^^^^^^^^^^^^^^^^^^^^^^^^^^^^^
  File "/media/zahid/Ads Power/Enterprise Infosec Consultants/ComplyWiseApi/venv/lib/python3.11/site-packages/rest_framework/views.py", line 509, in dispatch
    response = self.handle_exception(exc)
               ^^^^^^^^^^^^^^^^^^^^^^^^^^
  File "/media/zahid/Ads Power/Enterprise Infosec Consultants/ComplyWiseApi/venv/lib/python3.11/site-packages/rest_framework/views.py", line 469, in handle_exception
    self.raise_uncaught_exception(exc)
  File "/media/zahid/Ads Power/Enterprise Infosec Consultants/ComplyWiseApi/venv/lib/python3.11/site-packages/rest_framework/views.py", line 480, in raise_uncaught_exception
    raise exc
  File "/media/zahid/Ads Power/Enterprise Infosec Consultants/ComplyWiseApi/venv/lib/python3.11/site-packages/rest_framework/views.py", line 506, in dispatch
    response = handler(request, *args, **kwargs)
               ^^^^^^^^^^^^^^^^^^^^^^^^^^^^^^^^^
  File "/media/zahid/Ads Power/Enterprise Infosec Consultants/ComplyWiseApi/venv/lib/python3.11/site-packages/rest_framework/mixins.py", line 46, in list
    return Response(serializer.data)
                    ^^^^^^^^^^^^^^^
  File "/media/zahid/Ads Power/Enterprise Infosec Consultants/ComplyWiseApi/venv/lib/python3.11/site-packages/rest_framework/serializers.py", line 795, in data
    ret = super().data
          ^^^^^^^^^^^^
  File "/media/zahid/Ads Power/Enterprise Infosec Consultants/ComplyWiseApi/venv/lib/python3.11/site-packages/rest_framework/serializers.py", line 249, in data
    self._data = self.to_representation(self.instance)
                 ^^^^^^^^^^^^^^^^^^^^^^^^^^^^^^^^^^^^^
  File "/media/zahid/Ads Power/Enterprise Infosec Consultants/ComplyWiseApi/venv/lib/python3.11/site-packages/rest_framework/serializers.py", line 713, in to_representation
    return [
           ^
  File "/media/zahid/Ads Power/Enterprise Infosec Consultants/ComplyWiseApi/venv/lib/python3.11/site-packages/rest_framework/serializers.py", line 714, in <listcomp>
    self.child.to_representation(item) for item in iterable
    ^^^^^^^^^^^^^^^^^^^^^^^^^^^^^^^^^^
  File "/media/zahid/Ads Power/Enterprise Infosec Consultants/ComplyWiseApi/venv/lib/python3.11/site-packages/rest_framework/serializers.py", line 538, in to_representation
    ret[field.field_name] = field.to_representation(attribute)
                            ^^^^^^^^^^^^^^^^^^^^^^^^^^^^^^^^^^
  File "/media/zahid/Ads Power/Enterprise Infosec Consultants/ComplyWiseApi/venv/lib/python3.11/site-packages/rest_framework/serializers.py", line 713, in to_representation
    return [
           ^
  File "/media/zahid/Ads Power/Enterprise Infosec Consultants/ComplyWiseApi/venv/lib/python3.11/site-packages/django/db/models/query.py", line 400, in __iter__
    self._fetch_all()
  File "/media/zahid/Ads Power/Enterprise Infosec Consultants/ComplyWiseApi/venv/lib/python3.11/site-packages/django/db/models/query.py", line 1928, in _fetch_all
    self._result_cache = list(self._iterable_class(self))
                         ^^^^^^^^^^^^^^^^^^^^^^^^^^^^^^^^
  File "/media/zahid/Ads Power/Enterprise Infosec Consultants/ComplyWiseApi/venv/lib/python3.11/site-packages/django/db/models/query.py", line 91, in __iter__
    results = compiler.execute_sql(
              ^^^^^^^^^^^^^^^^^^^^^
  File "/media/zahid/Ads Power/Enterprise Infosec Consultants/ComplyWiseApi/venv/lib/python3.11/site-packages/django/db/models/sql/compiler.py", line 1574, in execute_sql
    cursor.execute(sql, params)
  File "/media/zahid/Ads Power/Enterprise Infosec Consultants/ComplyWiseApi/venv/lib/python3.11/site-packages/django/db/backends/utils.py", line 122, in execute
    return super().execute(sql, params)
           ^^^^^^^^^^^^^^^^^^^^^^^^^^^^
  File "/media/zahid/Ads Power/Enterprise Infosec Consultants/ComplyWiseApi/venv/lib/python3.11/site-packages/django/db/backends/utils.py", line 79, in execute
    return self._execute_with_wrappers(
           ^^^^^^^^^^^^^^^^^^^^^^^^^^^^
  File "/media/zahid/Ads Power/Enterprise Infosec Consultants/ComplyWiseApi/venv/lib/python3.11/site-packages/django/db/backends/utils.py", line 92, in _execute_with_wrappers
    return executor(sql, params, many, context)
           ^^^^^^^^^^^^^^^^^^^^^^^^^^^^^^^^^^^^
  File "/media/zahid/Ads Power/Enterprise Infosec Consultants/ComplyWiseApi/venv/lib/python3.11/site-packages/django/db/backends/utils.py", line 100, in _execute
    with self.db.wrap_database_errors:
  File "/media/zahid/Ads Power/Enterprise Infosec Consultants/ComplyWiseApi/venv/lib/python3.11/site-packages/django/db/utils.py", line 91, in __exit__
    raise dj_exc_value.with_traceback(traceback) from exc_value
  File "/media/zahid/Ads Power/Enterprise Infosec Consultants/ComplyWiseApi/venv/lib/python3.11/site-packages/django/db/backends/utils.py", line 105, in _execute
    return self.cursor.execute(sql, params)
           ^^^^^^^^^^^^^^^^^^^^^^^^^^^^^^^^
django.db.utils.ProgrammingError: column app_documents.created_at does not exist
LINE 1: SELECT "app_documents"."id", "app_documents"."created_at", "...
                                     ^
HINT:  Perhaps you meant to reference the column "app_documents.updated_at".

ERROR 2025-03-05 06:02:29,762 basehttp "GET /api/employees/ HTTP/1.1" 500 203913
ERROR 2025-03-05 06:17:50,566 log Internal Server Error: /api/employees/
Traceback (most recent call last):
  File "/media/zahid/Ads Power/Enterprise Infosec Consultants/ComplyWiseApi/venv/lib/python3.11/site-packages/django/core/handlers/exception.py", line 55, in inner
    response = get_response(request)
               ^^^^^^^^^^^^^^^^^^^^^
  File "/media/zahid/Ads Power/Enterprise Infosec Consultants/ComplyWiseApi/venv/lib/python3.11/site-packages/django/core/handlers/base.py", line 197, in _get_response
    response = wrapped_callback(request, *callback_args, **callback_kwargs)
               ^^^^^^^^^^^^^^^^^^^^^^^^^^^^^^^^^^^^^^^^^^^^^^^^^^^^^^^^^^^^
  File "/media/zahid/Ads Power/Enterprise Infosec Consultants/ComplyWiseApi/venv/lib/python3.11/site-packages/django/views/decorators/csrf.py", line 65, in _view_wrapper
    return view_func(request, *args, **kwargs)
           ^^^^^^^^^^^^^^^^^^^^^^^^^^^^^^^^^^^
  File "/media/zahid/Ads Power/Enterprise Infosec Consultants/ComplyWiseApi/venv/lib/python3.11/site-packages/rest_framework/viewsets.py", line 124, in view
    return self.dispatch(request, *args, **kwargs)
           ^^^^^^^^^^^^^^^^^^^^^^^^^^^^^^^^^^^^^^^
  File "/media/zahid/Ads Power/Enterprise Infosec Consultants/ComplyWiseApi/venv/lib/python3.11/site-packages/rest_framework/views.py", line 509, in dispatch
    response = self.handle_exception(exc)
               ^^^^^^^^^^^^^^^^^^^^^^^^^^
  File "/media/zahid/Ads Power/Enterprise Infosec Consultants/ComplyWiseApi/venv/lib/python3.11/site-packages/rest_framework/views.py", line 469, in handle_exception
    self.raise_uncaught_exception(exc)
  File "/media/zahid/Ads Power/Enterprise Infosec Consultants/ComplyWiseApi/venv/lib/python3.11/site-packages/rest_framework/views.py", line 480, in raise_uncaught_exception
    raise exc
  File "/media/zahid/Ads Power/Enterprise Infosec Consultants/ComplyWiseApi/venv/lib/python3.11/site-packages/rest_framework/views.py", line 506, in dispatch
    response = handler(request, *args, **kwargs)
               ^^^^^^^^^^^^^^^^^^^^^^^^^^^^^^^^^
  File "/media/zahid/Ads Power/Enterprise Infosec Consultants/ComplyWiseApi/app/modules/access_control/views/employee.py", line 26, in create
    document_serializer = DocumentsSerializer(data={
                          ^^^^^^^^^^^^^^^^^^^
NameError: name 'DocumentsSerializer' is not defined
ERROR 2025-03-05 06:17:50,569 basehttp "POST /api/employees/ HTTP/1.1" 500 109094
ERROR 2025-03-06 06:55:00,359 log Internal Server Error: /api/register/
Traceback (most recent call last):
  File "/media/zahid/Ads Power/Enterprise Infosec Consultants/ComplyWiseApi/venv/lib/python3.11/site-packages/django/core/handlers/exception.py", line 55, in inner
    response = get_response(request)
               ^^^^^^^^^^^^^^^^^^^^^
  File "/media/zahid/Ads Power/Enterprise Infosec Consultants/ComplyWiseApi/venv/lib/python3.11/site-packages/django/core/handlers/base.py", line 220, in _get_response
    response = response.render()
               ^^^^^^^^^^^^^^^^^
  File "/media/zahid/Ads Power/Enterprise Infosec Consultants/ComplyWiseApi/venv/lib/python3.11/site-packages/django/template/response.py", line 114, in render
    self.content = self.rendered_content
                   ^^^^^^^^^^^^^^^^^^^^^
  File "/media/zahid/Ads Power/Enterprise Infosec Consultants/ComplyWiseApi/venv/lib/python3.11/site-packages/rest_framework/response.py", line 74, in rendered_content
    ret = renderer.render(self.data, accepted_media_type, context)
          ^^^^^^^^^^^^^^^^^^^^^^^^^^^^^^^^^^^^^^^^^^^^^^^^^^^^^^^^
  File "/media/zahid/Ads Power/Enterprise Infosec Consultants/ComplyWiseApi/venv/lib/python3.11/site-packages/rest_framework/renderers.py", line 727, in render
    context = self.get_context(data, accepted_media_type, renderer_context)
              ^^^^^^^^^^^^^^^^^^^^^^^^^^^^^^^^^^^^^^^^^^^^^^^^^^^^^^^^^^^^^
  File "/media/zahid/Ads Power/Enterprise Infosec Consultants/ComplyWiseApi/venv/lib/python3.11/site-packages/rest_framework/renderers.py", line 658, in get_context
    raw_data_post_form = self.get_raw_data_form(data, view, 'POST', request)
                         ^^^^^^^^^^^^^^^^^^^^^^^^^^^^^^^^^^^^^^^^^^^^^^^^^^^
  File "/media/zahid/Ads Power/Enterprise Infosec Consultants/ComplyWiseApi/venv/lib/python3.11/site-packages/rest_framework/renderers.py", line 554, in get_raw_data_form
    serializer = view.get_serializer()
                 ^^^^^^^^^^^^^^^^^^^^^
  File "/media/zahid/Ads Power/Enterprise Infosec Consultants/ComplyWiseApi/venv/lib/python3.11/site-packages/rest_framework/generics.py", line 112, in get_serializer
    serializer_class = self.get_serializer_class()
                       ^^^^^^^^^^^^^^^^^^^^^^^^^^^
  File "/media/zahid/Ads Power/Enterprise Infosec Consultants/ComplyWiseApi/venv/lib/python3.11/site-packages/rest_framework/generics.py", line 126, in get_serializer_class
    assert self.serializer_class is not None, (
           ^^^^^^^^^^^^^^^^^^^^^^^^^^^^^^^^^
AssertionError: 'UserViewSet' should either include a `serializer_class` attribute, or override the `get_serializer_class()` method.
ERROR 2025-03-06 06:55:00,363 basehttp "GET /api/register/ HTTP/1.1" 500 108260
ERROR 2025-03-06 06:57:23,232 log Internal Server Error: /api/register/
Traceback (most recent call last):
  File "/media/zahid/Ads Power/Enterprise Infosec Consultants/ComplyWiseApi/venv/lib/python3.11/site-packages/django/core/handlers/exception.py", line 55, in inner
    response = get_response(request)
               ^^^^^^^^^^^^^^^^^^^^^
  File "/media/zahid/Ads Power/Enterprise Infosec Consultants/ComplyWiseApi/venv/lib/python3.11/site-packages/django/core/handlers/base.py", line 220, in _get_response
    response = response.render()
               ^^^^^^^^^^^^^^^^^
  File "/media/zahid/Ads Power/Enterprise Infosec Consultants/ComplyWiseApi/venv/lib/python3.11/site-packages/django/template/response.py", line 114, in render
    self.content = self.rendered_content
                   ^^^^^^^^^^^^^^^^^^^^^
  File "/media/zahid/Ads Power/Enterprise Infosec Consultants/ComplyWiseApi/venv/lib/python3.11/site-packages/rest_framework/response.py", line 74, in rendered_content
    ret = renderer.render(self.data, accepted_media_type, context)
          ^^^^^^^^^^^^^^^^^^^^^^^^^^^^^^^^^^^^^^^^^^^^^^^^^^^^^^^^
  File "/media/zahid/Ads Power/Enterprise Infosec Consultants/ComplyWiseApi/venv/lib/python3.11/site-packages/rest_framework/renderers.py", line 727, in render
    context = self.get_context(data, accepted_media_type, renderer_context)
              ^^^^^^^^^^^^^^^^^^^^^^^^^^^^^^^^^^^^^^^^^^^^^^^^^^^^^^^^^^^^^
  File "/media/zahid/Ads Power/Enterprise Infosec Consultants/ComplyWiseApi/venv/lib/python3.11/site-packages/rest_framework/renderers.py", line 658, in get_context
    raw_data_post_form = self.get_raw_data_form(data, view, 'POST', request)
                         ^^^^^^^^^^^^^^^^^^^^^^^^^^^^^^^^^^^^^^^^^^^^^^^^^^^
  File "/media/zahid/Ads Power/Enterprise Infosec Consultants/ComplyWiseApi/venv/lib/python3.11/site-packages/rest_framework/renderers.py", line 554, in get_raw_data_form
    serializer = view.get_serializer()
                 ^^^^^^^^^^^^^^^^^^^^^
  File "/media/zahid/Ads Power/Enterprise Infosec Consultants/ComplyWiseApi/venv/lib/python3.11/site-packages/rest_framework/generics.py", line 112, in get_serializer
    serializer_class = self.get_serializer_class()
                       ^^^^^^^^^^^^^^^^^^^^^^^^^^^
  File "/media/zahid/Ads Power/Enterprise Infosec Consultants/ComplyWiseApi/venv/lib/python3.11/site-packages/rest_framework/generics.py", line 126, in get_serializer_class
    assert self.serializer_class is not None, (
           ^^^^^^^^^^^^^^^^^^^^^^^^^^^^^^^^^
AssertionError: 'UserViewSet' should either include a `serializer_class` attribute, or override the `get_serializer_class()` method.
ERROR 2025-03-06 06:57:23,235 basehttp "GET /api/register/ HTTP/1.1" 500 108397
ERROR 2025-03-06 06:57:25,968 log Internal Server Error: /api/register/
Traceback (most recent call last):
  File "/media/zahid/Ads Power/Enterprise Infosec Consultants/ComplyWiseApi/venv/lib/python3.11/site-packages/django/core/handlers/exception.py", line 55, in inner
    response = get_response(request)
               ^^^^^^^^^^^^^^^^^^^^^
  File "/media/zahid/Ads Power/Enterprise Infosec Consultants/ComplyWiseApi/venv/lib/python3.11/site-packages/django/core/handlers/base.py", line 220, in _get_response
    response = response.render()
               ^^^^^^^^^^^^^^^^^
  File "/media/zahid/Ads Power/Enterprise Infosec Consultants/ComplyWiseApi/venv/lib/python3.11/site-packages/django/template/response.py", line 114, in render
    self.content = self.rendered_content
                   ^^^^^^^^^^^^^^^^^^^^^
  File "/media/zahid/Ads Power/Enterprise Infosec Consultants/ComplyWiseApi/venv/lib/python3.11/site-packages/rest_framework/response.py", line 74, in rendered_content
    ret = renderer.render(self.data, accepted_media_type, context)
          ^^^^^^^^^^^^^^^^^^^^^^^^^^^^^^^^^^^^^^^^^^^^^^^^^^^^^^^^
  File "/media/zahid/Ads Power/Enterprise Infosec Consultants/ComplyWiseApi/venv/lib/python3.11/site-packages/rest_framework/renderers.py", line 727, in render
    context = self.get_context(data, accepted_media_type, renderer_context)
              ^^^^^^^^^^^^^^^^^^^^^^^^^^^^^^^^^^^^^^^^^^^^^^^^^^^^^^^^^^^^^
  File "/media/zahid/Ads Power/Enterprise Infosec Consultants/ComplyWiseApi/venv/lib/python3.11/site-packages/rest_framework/renderers.py", line 658, in get_context
    raw_data_post_form = self.get_raw_data_form(data, view, 'POST', request)
                         ^^^^^^^^^^^^^^^^^^^^^^^^^^^^^^^^^^^^^^^^^^^^^^^^^^^
  File "/media/zahid/Ads Power/Enterprise Infosec Consultants/ComplyWiseApi/venv/lib/python3.11/site-packages/rest_framework/renderers.py", line 554, in get_raw_data_form
    serializer = view.get_serializer()
                 ^^^^^^^^^^^^^^^^^^^^^
  File "/media/zahid/Ads Power/Enterprise Infosec Consultants/ComplyWiseApi/venv/lib/python3.11/site-packages/rest_framework/generics.py", line 112, in get_serializer
    serializer_class = self.get_serializer_class()
                       ^^^^^^^^^^^^^^^^^^^^^^^^^^^
  File "/media/zahid/Ads Power/Enterprise Infosec Consultants/ComplyWiseApi/venv/lib/python3.11/site-packages/rest_framework/generics.py", line 126, in get_serializer_class
    assert self.serializer_class is not None, (
           ^^^^^^^^^^^^^^^^^^^^^^^^^^^^^^^^^
AssertionError: 'UserViewSet' should either include a `serializer_class` attribute, or override the `get_serializer_class()` method.
ERROR 2025-03-06 06:57:25,975 basehttp "GET /api/register/ HTTP/1.1" 500 108397
ERROR 2025-03-06 06:58:20,636 log Internal Server Error: /api/register/
Traceback (most recent call last):
  File "/media/zahid/Ads Power/Enterprise Infosec Consultants/ComplyWiseApi/venv/lib/python3.11/site-packages/django/core/handlers/exception.py", line 55, in inner
    response = get_response(request)
               ^^^^^^^^^^^^^^^^^^^^^
  File "/media/zahid/Ads Power/Enterprise Infosec Consultants/ComplyWiseApi/venv/lib/python3.11/site-packages/django/core/handlers/base.py", line 220, in _get_response
    response = response.render()
               ^^^^^^^^^^^^^^^^^
  File "/media/zahid/Ads Power/Enterprise Infosec Consultants/ComplyWiseApi/venv/lib/python3.11/site-packages/django/template/response.py", line 114, in render
    self.content = self.rendered_content
                   ^^^^^^^^^^^^^^^^^^^^^
  File "/media/zahid/Ads Power/Enterprise Infosec Consultants/ComplyWiseApi/venv/lib/python3.11/site-packages/rest_framework/response.py", line 74, in rendered_content
    ret = renderer.render(self.data, accepted_media_type, context)
          ^^^^^^^^^^^^^^^^^^^^^^^^^^^^^^^^^^^^^^^^^^^^^^^^^^^^^^^^
  File "/media/zahid/Ads Power/Enterprise Infosec Consultants/ComplyWiseApi/venv/lib/python3.11/site-packages/rest_framework/renderers.py", line 727, in render
    context = self.get_context(data, accepted_media_type, renderer_context)
              ^^^^^^^^^^^^^^^^^^^^^^^^^^^^^^^^^^^^^^^^^^^^^^^^^^^^^^^^^^^^^
  File "/media/zahid/Ads Power/Enterprise Infosec Consultants/ComplyWiseApi/venv/lib/python3.11/site-packages/rest_framework/renderers.py", line 658, in get_context
    raw_data_post_form = self.get_raw_data_form(data, view, 'POST', request)
                         ^^^^^^^^^^^^^^^^^^^^^^^^^^^^^^^^^^^^^^^^^^^^^^^^^^^
  File "/media/zahid/Ads Power/Enterprise Infosec Consultants/ComplyWiseApi/venv/lib/python3.11/site-packages/rest_framework/renderers.py", line 554, in get_raw_data_form
    serializer = view.get_serializer()
                 ^^^^^^^^^^^^^^^^^^^^^
  File "/media/zahid/Ads Power/Enterprise Infosec Consultants/ComplyWiseApi/venv/lib/python3.11/site-packages/rest_framework/generics.py", line 112, in get_serializer
    serializer_class = self.get_serializer_class()
                       ^^^^^^^^^^^^^^^^^^^^^^^^^^^
  File "/media/zahid/Ads Power/Enterprise Infosec Consultants/ComplyWiseApi/venv/lib/python3.11/site-packages/rest_framework/generics.py", line 126, in get_serializer_class
    assert self.serializer_class is not None, (
           ^^^^^^^^^^^^^^^^^^^^^^^^^^^^^^^^^
AssertionError: 'UserViewSet' should either include a `serializer_class` attribute, or override the `get_serializer_class()` method.
ERROR 2025-03-06 06:58:20,641 basehttp "GET /api/register/ HTTP/1.1" 500 108397
ERROR 2025-03-06 07:00:50,441 log Internal Server Error: /api/register/
Traceback (most recent call last):
  File "/media/zahid/Ads Power/Enterprise Infosec Consultants/ComplyWiseApi/venv/lib/python3.11/site-packages/django/core/handlers/exception.py", line 55, in inner
    response = get_response(request)
               ^^^^^^^^^^^^^^^^^^^^^
  File "/media/zahid/Ads Power/Enterprise Infosec Consultants/ComplyWiseApi/venv/lib/python3.11/site-packages/django/core/handlers/base.py", line 197, in _get_response
    response = wrapped_callback(request, *callback_args, **callback_kwargs)
               ^^^^^^^^^^^^^^^^^^^^^^^^^^^^^^^^^^^^^^^^^^^^^^^^^^^^^^^^^^^^
  File "/media/zahid/Ads Power/Enterprise Infosec Consultants/ComplyWiseApi/venv/lib/python3.11/site-packages/django/views/decorators/csrf.py", line 65, in _view_wrapper
    return view_func(request, *args, **kwargs)
           ^^^^^^^^^^^^^^^^^^^^^^^^^^^^^^^^^^^
  File "/media/zahid/Ads Power/Enterprise Infosec Consultants/ComplyWiseApi/venv/lib/python3.11/site-packages/rest_framework/viewsets.py", line 124, in view
    return self.dispatch(request, *args, **kwargs)
           ^^^^^^^^^^^^^^^^^^^^^^^^^^^^^^^^^^^^^^^
  File "/media/zahid/Ads Power/Enterprise Infosec Consultants/ComplyWiseApi/venv/lib/python3.11/site-packages/rest_framework/views.py", line 509, in dispatch
    response = self.handle_exception(exc)
               ^^^^^^^^^^^^^^^^^^^^^^^^^^
  File "/media/zahid/Ads Power/Enterprise Infosec Consultants/ComplyWiseApi/venv/lib/python3.11/site-packages/rest_framework/views.py", line 469, in handle_exception
    self.raise_uncaught_exception(exc)
  File "/media/zahid/Ads Power/Enterprise Infosec Consultants/ComplyWiseApi/venv/lib/python3.11/site-packages/rest_framework/views.py", line 480, in raise_uncaught_exception
    raise exc
  File "/media/zahid/Ads Power/Enterprise Infosec Consultants/ComplyWiseApi/venv/lib/python3.11/site-packages/rest_framework/views.py", line 506, in dispatch
    response = handler(request, *args, **kwargs)
               ^^^^^^^^^^^^^^^^^^^^^^^^^^^^^^^^^
  File "/media/zahid/Ads Power/Enterprise Infosec Consultants/ComplyWiseApi/app/modules/access_control/views/user.py", line 59, in register
    user = serializer.save()
           ^^^^^^^^^^^^^^^^^
  File "/media/zahid/Ads Power/Enterprise Infosec Consultants/ComplyWiseApi/venv/lib/python3.11/site-packages/rest_framework/serializers.py", line 208, in save
    self.instance = self.create(validated_data)
                    ^^^^^^^^^^^^^^^^^^^^^^^^^^^
  File "/media/zahid/Ads Power/Enterprise Infosec Consultants/ComplyWiseApi/app/modules/access_control/serializers/user.py", line 14, in create
    return User.objects.create_user(**validated_data)
           ^^^^^^^^^^^^^^^^^^^^^^^^^^^^^^^^^^^^^^^^^^
  File "/media/zahid/Ads Power/Enterprise Infosec Consultants/ComplyWiseApi/app/modules/access_control/models/user.py", line 12, in create_user
    user.set_password(password)
    ^^^^^^^^^^^^^^^^^
AttributeError: 'User' object has no attribute 'set_password'
ERROR 2025-03-06 07:00:50,445 basehttp "POST /api/register/ HTTP/1.1" 500 121441
ERROR 2025-03-06 08:11:44,373 log Internal Server Error: /api/register/
Traceback (most recent call last):
  File "/media/zahid/Ads Power/Enterprise Infosec Consultants/ComplyWiseApi/venv/lib/python3.11/site-packages/django/core/handlers/exception.py", line 55, in inner
    response = get_response(request)
               ^^^^^^^^^^^^^^^^^^^^^
  File "/media/zahid/Ads Power/Enterprise Infosec Consultants/ComplyWiseApi/venv/lib/python3.11/site-packages/django/core/handlers/base.py", line 197, in _get_response
    response = wrapped_callback(request, *callback_args, **callback_kwargs)
               ^^^^^^^^^^^^^^^^^^^^^^^^^^^^^^^^^^^^^^^^^^^^^^^^^^^^^^^^^^^^
  File "/media/zahid/Ads Power/Enterprise Infosec Consultants/ComplyWiseApi/venv/lib/python3.11/site-packages/django/views/decorators/csrf.py", line 65, in _view_wrapper
    return view_func(request, *args, **kwargs)
           ^^^^^^^^^^^^^^^^^^^^^^^^^^^^^^^^^^^
  File "/media/zahid/Ads Power/Enterprise Infosec Consultants/ComplyWiseApi/venv/lib/python3.11/site-packages/django/views/generic/base.py", line 104, in view
    return self.dispatch(request, *args, **kwargs)
           ^^^^^^^^^^^^^^^^^^^^^^^^^^^^^^^^^^^^^^^
  File "/media/zahid/Ads Power/Enterprise Infosec Consultants/ComplyWiseApi/venv/lib/python3.11/site-packages/rest_framework/views.py", line 509, in dispatch
    response = self.handle_exception(exc)
               ^^^^^^^^^^^^^^^^^^^^^^^^^^
  File "/media/zahid/Ads Power/Enterprise Infosec Consultants/ComplyWiseApi/venv/lib/python3.11/site-packages/rest_framework/views.py", line 469, in handle_exception
    self.raise_uncaught_exception(exc)
  File "/media/zahid/Ads Power/Enterprise Infosec Consultants/ComplyWiseApi/venv/lib/python3.11/site-packages/rest_framework/views.py", line 480, in raise_uncaught_exception
    raise exc
  File "/media/zahid/Ads Power/Enterprise Infosec Consultants/ComplyWiseApi/venv/lib/python3.11/site-packages/rest_framework/views.py", line 506, in dispatch
    response = handler(request, *args, **kwargs)
               ^^^^^^^^^^^^^^^^^^^^^^^^^^^^^^^^^
  File "/media/zahid/Ads Power/Enterprise Infosec Consultants/ComplyWiseApi/venv/lib/python3.11/site-packages/rest_framework/generics.py", line 194, in post
    return self.create(request, *args, **kwargs)
           ^^^^^^^^^^^^^^^^^^^^^^^^^^^^^^^^^^^^^
  File "/media/zahid/Ads Power/Enterprise Infosec Consultants/ComplyWiseApi/app/modules/access_control/views/user.py", line 20, in create
    user = serializer.save()
           ^^^^^^^^^^^^^^^^^
  File "/media/zahid/Ads Power/Enterprise Infosec Consultants/ComplyWiseApi/venv/lib/python3.11/site-packages/rest_framework/serializers.py", line 208, in save
    self.instance = self.create(validated_data)
                    ^^^^^^^^^^^^^^^^^^^^^^^^^^^
  File "/media/zahid/Ads Power/Enterprise Infosec Consultants/ComplyWiseApi/app/modules/access_control/serializers/user.py", line 14, in create
    return User.objects.create_user(**validated_data)
           ^^^^^^^^^^^^^^^^^^^^^^^^^^^^^^^^^^^^^^^^^^
  File "/media/zahid/Ads Power/Enterprise Infosec Consultants/ComplyWiseApi/app/modules/access_control/models/user.py", line 12, in create_user
    user.set_password(password)
    ^^^^^^^^^^^^^^^^^
AttributeError: 'User' object has no attribute 'set_password'
ERROR 2025-03-06 08:11:44,381 basehttp "POST /api/register/ HTTP/1.1" 500 125696
ERROR 2025-03-06 08:17:18,480 log Internal Server Error: /api/register/
Traceback (most recent call last):
  File "/media/zahid/Ads Power/Enterprise Infosec Consultants/ComplyWiseApi/venv/lib/python3.11/site-packages/django/core/handlers/exception.py", line 55, in inner
    response = get_response(request)
               ^^^^^^^^^^^^^^^^^^^^^
  File "/media/zahid/Ads Power/Enterprise Infosec Consultants/ComplyWiseApi/venv/lib/python3.11/site-packages/django/core/handlers/base.py", line 197, in _get_response
    response = wrapped_callback(request, *callback_args, **callback_kwargs)
               ^^^^^^^^^^^^^^^^^^^^^^^^^^^^^^^^^^^^^^^^^^^^^^^^^^^^^^^^^^^^
  File "/media/zahid/Ads Power/Enterprise Infosec Consultants/ComplyWiseApi/venv/lib/python3.11/site-packages/django/views/decorators/csrf.py", line 65, in _view_wrapper
    return view_func(request, *args, **kwargs)
           ^^^^^^^^^^^^^^^^^^^^^^^^^^^^^^^^^^^
  File "/media/zahid/Ads Power/Enterprise Infosec Consultants/ComplyWiseApi/venv/lib/python3.11/site-packages/django/views/generic/base.py", line 104, in view
    return self.dispatch(request, *args, **kwargs)
           ^^^^^^^^^^^^^^^^^^^^^^^^^^^^^^^^^^^^^^^
  File "/media/zahid/Ads Power/Enterprise Infosec Consultants/ComplyWiseApi/venv/lib/python3.11/site-packages/rest_framework/views.py", line 509, in dispatch
    response = self.handle_exception(exc)
               ^^^^^^^^^^^^^^^^^^^^^^^^^^
  File "/media/zahid/Ads Power/Enterprise Infosec Consultants/ComplyWiseApi/venv/lib/python3.11/site-packages/rest_framework/views.py", line 469, in handle_exception
    self.raise_uncaught_exception(exc)
  File "/media/zahid/Ads Power/Enterprise Infosec Consultants/ComplyWiseApi/venv/lib/python3.11/site-packages/rest_framework/views.py", line 480, in raise_uncaught_exception
    raise exc
  File "/media/zahid/Ads Power/Enterprise Infosec Consultants/ComplyWiseApi/venv/lib/python3.11/site-packages/rest_framework/views.py", line 506, in dispatch
    response = handler(request, *args, **kwargs)
               ^^^^^^^^^^^^^^^^^^^^^^^^^^^^^^^^^
  File "/media/zahid/Ads Power/Enterprise Infosec Consultants/ComplyWiseApi/venv/lib/python3.11/site-packages/rest_framework/generics.py", line 194, in post
    return self.create(request, *args, **kwargs)
           ^^^^^^^^^^^^^^^^^^^^^^^^^^^^^^^^^^^^^
  File "/media/zahid/Ads Power/Enterprise Infosec Consultants/ComplyWiseApi/app/modules/access_control/views/user.py", line 20, in create
    user = serializer.save()
           ^^^^^^^^^^^^^^^^^
  File "/media/zahid/Ads Power/Enterprise Infosec Consultants/ComplyWiseApi/venv/lib/python3.11/site-packages/rest_framework/serializers.py", line 208, in save
    self.instance = self.create(validated_data)
                    ^^^^^^^^^^^^^^^^^^^^^^^^^^^
  File "/media/zahid/Ads Power/Enterprise Infosec Consultants/ComplyWiseApi/app/modules/access_control/serializers/user.py", line 14, in create
    return User.objects.create_user(**validated_data)
           ^^^^^^^^^^^^^^^^^^^^^^^^^^^^^^^^^^^^^^^^^^
  File "/media/zahid/Ads Power/Enterprise Infosec Consultants/ComplyWiseApi/app/modules/access_control/models/user.py", line 12, in create_user
    user.set_password(password)
    ^^^^^^^^^^^^^^^^^
AttributeError: 'User' object has no attribute 'set_password'
ERROR 2025-03-06 08:17:18,484 basehttp "POST /api/register/ HTTP/1.1" 500 125696
ERROR 2025-03-06 08:30:50,527 log Internal Server Error: /api/register/
Traceback (most recent call last):
  File "/media/zahid/Ads Power/Enterprise Infosec Consultants/ComplyWiseApi/venv/lib/python3.11/site-packages/django/core/handlers/exception.py", line 55, in inner
    response = get_response(request)
               ^^^^^^^^^^^^^^^^^^^^^
  File "/media/zahid/Ads Power/Enterprise Infosec Consultants/ComplyWiseApi/venv/lib/python3.11/site-packages/django/core/handlers/base.py", line 197, in _get_response
    response = wrapped_callback(request, *callback_args, **callback_kwargs)
               ^^^^^^^^^^^^^^^^^^^^^^^^^^^^^^^^^^^^^^^^^^^^^^^^^^^^^^^^^^^^
  File "/media/zahid/Ads Power/Enterprise Infosec Consultants/ComplyWiseApi/venv/lib/python3.11/site-packages/django/views/decorators/csrf.py", line 65, in _view_wrapper
    return view_func(request, *args, **kwargs)
           ^^^^^^^^^^^^^^^^^^^^^^^^^^^^^^^^^^^
  File "/media/zahid/Ads Power/Enterprise Infosec Consultants/ComplyWiseApi/venv/lib/python3.11/site-packages/django/views/generic/base.py", line 104, in view
    return self.dispatch(request, *args, **kwargs)
           ^^^^^^^^^^^^^^^^^^^^^^^^^^^^^^^^^^^^^^^
  File "/media/zahid/Ads Power/Enterprise Infosec Consultants/ComplyWiseApi/venv/lib/python3.11/site-packages/rest_framework/views.py", line 509, in dispatch
    response = self.handle_exception(exc)
               ^^^^^^^^^^^^^^^^^^^^^^^^^^
  File "/media/zahid/Ads Power/Enterprise Infosec Consultants/ComplyWiseApi/venv/lib/python3.11/site-packages/rest_framework/views.py", line 469, in handle_exception
    self.raise_uncaught_exception(exc)
  File "/media/zahid/Ads Power/Enterprise Infosec Consultants/ComplyWiseApi/venv/lib/python3.11/site-packages/rest_framework/views.py", line 480, in raise_uncaught_exception
    raise exc
  File "/media/zahid/Ads Power/Enterprise Infosec Consultants/ComplyWiseApi/venv/lib/python3.11/site-packages/rest_framework/views.py", line 506, in dispatch
    response = handler(request, *args, **kwargs)
               ^^^^^^^^^^^^^^^^^^^^^^^^^^^^^^^^^
  File "/media/zahid/Ads Power/Enterprise Infosec Consultants/ComplyWiseApi/venv/lib/python3.11/site-packages/rest_framework/generics.py", line 194, in post
    return self.create(request, *args, **kwargs)
           ^^^^^^^^^^^^^^^^^^^^^^^^^^^^^^^^^^^^^
  File "/media/zahid/Ads Power/Enterprise Infosec Consultants/ComplyWiseApi/app/modules/access_control/views/user.py", line 20, in create
    serializer.is_valid(raise_exception=True)
  File "/media/zahid/Ads Power/Enterprise Infosec Consultants/ComplyWiseApi/venv/lib/python3.11/site-packages/rest_framework/serializers.py", line 223, in is_valid
    self._validated_data = self.run_validation(self.initial_data)
                           ^^^^^^^^^^^^^^^^^^^^^^^^^^^^^^^^^^^^^^
  File "/media/zahid/Ads Power/Enterprise Infosec Consultants/ComplyWiseApi/venv/lib/python3.11/site-packages/rest_framework/serializers.py", line 442, in run_validation
    value = self.to_internal_value(data)
            ^^^^^^^^^^^^^^^^^^^^^^^^^^^^
  File "/media/zahid/Ads Power/Enterprise Infosec Consultants/ComplyWiseApi/venv/lib/python3.11/site-packages/rest_framework/serializers.py", line 495, in to_internal_value
    for field in fields:
  File "/media/zahid/Ads Power/Enterprise Infosec Consultants/ComplyWiseApi/venv/lib/python3.11/site-packages/rest_framework/serializers.py", line 378, in _writable_fields
    for field in self.fields.values():
                 ^^^^^^^^^^^
  File "/media/zahid/Ads Power/Enterprise Infosec Consultants/ComplyWiseApi/venv/lib/python3.11/site-packages/django/utils/functional.py", line 47, in __get__
    res = instance.__dict__[self.name] = self.func(instance)
                                         ^^^^^^^^^^^^^^^^^^^
  File "/media/zahid/Ads Power/Enterprise Infosec Consultants/ComplyWiseApi/venv/lib/python3.11/site-packages/rest_framework/serializers.py", line 372, in fields
    for key, value in self.get_fields().items():
                      ^^^^^^^^^^^^^^^^^
  File "/media/zahid/Ads Power/Enterprise Infosec Consultants/ComplyWiseApi/venv/lib/python3.11/site-packages/rest_framework/serializers.py", line 1103, in get_fields
    field_class, field_kwargs = self.build_field(
                                ^^^^^^^^^^^^^^^^^
  File "/media/zahid/Ads Power/Enterprise Infosec Consultants/ComplyWiseApi/venv/lib/python3.11/site-packages/rest_framework/serializers.py", line 1249, in build_field
    return self.build_unknown_field(field_name, model_class)
           ^^^^^^^^^^^^^^^^^^^^^^^^^^^^^^^^^^^^^^^^^^^^^^^^^
  File "/media/zahid/Ads Power/Enterprise Infosec Consultants/ComplyWiseApi/venv/lib/python3.11/site-packages/rest_framework/serializers.py", line 1367, in build_unknown_field
    raise ImproperlyConfigured(
django.core.exceptions.ImproperlyConfigured: Field name `password` is not valid for model `User` in `app.modules.access_control.serializers.user.UserRegistrationSerializer`.
ERROR 2025-03-06 08:30:50,535 basehttp "POST /api/register/ HTTP/1.1" 500 156837
ERROR 2025-03-06 08:31:39,230 log Internal Server Error: /api/register/
Traceback (most recent call last):
  File "/media/zahid/Ads Power/Enterprise Infosec Consultants/ComplyWiseApi/venv/lib/python3.11/site-packages/django/core/handlers/exception.py", line 55, in inner
    response = get_response(request)
               ^^^^^^^^^^^^^^^^^^^^^
  File "/media/zahid/Ads Power/Enterprise Infosec Consultants/ComplyWiseApi/venv/lib/python3.11/site-packages/django/core/handlers/base.py", line 197, in _get_response
    response = wrapped_callback(request, *callback_args, **callback_kwargs)
               ^^^^^^^^^^^^^^^^^^^^^^^^^^^^^^^^^^^^^^^^^^^^^^^^^^^^^^^^^^^^
  File "/media/zahid/Ads Power/Enterprise Infosec Consultants/ComplyWiseApi/venv/lib/python3.11/site-packages/django/views/decorators/csrf.py", line 65, in _view_wrapper
    return view_func(request, *args, **kwargs)
           ^^^^^^^^^^^^^^^^^^^^^^^^^^^^^^^^^^^
  File "/media/zahid/Ads Power/Enterprise Infosec Consultants/ComplyWiseApi/venv/lib/python3.11/site-packages/django/views/generic/base.py", line 104, in view
    return self.dispatch(request, *args, **kwargs)
           ^^^^^^^^^^^^^^^^^^^^^^^^^^^^^^^^^^^^^^^
  File "/media/zahid/Ads Power/Enterprise Infosec Consultants/ComplyWiseApi/venv/lib/python3.11/site-packages/rest_framework/views.py", line 509, in dispatch
    response = self.handle_exception(exc)
               ^^^^^^^^^^^^^^^^^^^^^^^^^^
  File "/media/zahid/Ads Power/Enterprise Infosec Consultants/ComplyWiseApi/venv/lib/python3.11/site-packages/rest_framework/views.py", line 469, in handle_exception
    self.raise_uncaught_exception(exc)
  File "/media/zahid/Ads Power/Enterprise Infosec Consultants/ComplyWiseApi/venv/lib/python3.11/site-packages/rest_framework/views.py", line 480, in raise_uncaught_exception
    raise exc
  File "/media/zahid/Ads Power/Enterprise Infosec Consultants/ComplyWiseApi/venv/lib/python3.11/site-packages/rest_framework/views.py", line 506, in dispatch
    response = handler(request, *args, **kwargs)
               ^^^^^^^^^^^^^^^^^^^^^^^^^^^^^^^^^
  File "/media/zahid/Ads Power/Enterprise Infosec Consultants/ComplyWiseApi/venv/lib/python3.11/site-packages/rest_framework/generics.py", line 194, in post
    return self.create(request, *args, **kwargs)
           ^^^^^^^^^^^^^^^^^^^^^^^^^^^^^^^^^^^^^
  File "/media/zahid/Ads Power/Enterprise Infosec Consultants/ComplyWiseApi/app/modules/access_control/views/user.py", line 21, in create
    serializer.save()
  File "/media/zahid/Ads Power/Enterprise Infosec Consultants/ComplyWiseApi/venv/lib/python3.11/site-packages/rest_framework/serializers.py", line 208, in save
    self.instance = self.create(validated_data)
                    ^^^^^^^^^^^^^^^^^^^^^^^^^^^
  File "/media/zahid/Ads Power/Enterprise Infosec Consultants/ComplyWiseApi/app/modules/access_control/serializers/user.py", line 13, in create
    user = User.objects.create_user(**validated_data)
           ^^^^^^^^^^^^^^^^^^^^^^^^^^^^^^^^^^^^^^^^^^
  File "/media/zahid/Ads Power/Enterprise Infosec Consultants/ComplyWiseApi/app/modules/access_control/models/user.py", line 12, in create_user
    user.set_password(password)
    ^^^^^^^^^^^^^^^^^
AttributeError: 'User' object has no attribute 'set_password'
ERROR 2025-03-06 08:31:39,237 basehttp "POST /api/register/ HTTP/1.1" 500 126104
ERROR 2025-03-06 09:32:49,622 log Internal Server Error: /api/register/
Traceback (most recent call last):
  File "/media/zahid/Ads Power/Enterprise Infosec Consultants/ComplyWiseApi/venv/lib/python3.11/site-packages/django/db/backends/utils.py", line 105, in _execute
    return self.cursor.execute(sql, params)
           ^^^^^^^^^^^^^^^^^^^^^^^^^^^^^^^^
psycopg2.errors.UniqueViolation: duplicate key value violates unique constraint "app_user_username_key"
DETAIL:  Key (username)=() already exists.


The above exception was the direct cause of the following exception:

Traceback (most recent call last):
  File "/media/zahid/Ads Power/Enterprise Infosec Consultants/ComplyWiseApi/venv/lib/python3.11/site-packages/django/core/handlers/exception.py", line 55, in inner
    response = get_response(request)
               ^^^^^^^^^^^^^^^^^^^^^
  File "/media/zahid/Ads Power/Enterprise Infosec Consultants/ComplyWiseApi/venv/lib/python3.11/site-packages/django/core/handlers/base.py", line 197, in _get_response
    response = wrapped_callback(request, *callback_args, **callback_kwargs)
               ^^^^^^^^^^^^^^^^^^^^^^^^^^^^^^^^^^^^^^^^^^^^^^^^^^^^^^^^^^^^
  File "/media/zahid/Ads Power/Enterprise Infosec Consultants/ComplyWiseApi/venv/lib/python3.11/site-packages/django/views/decorators/csrf.py", line 65, in _view_wrapper
    return view_func(request, *args, **kwargs)
           ^^^^^^^^^^^^^^^^^^^^^^^^^^^^^^^^^^^
  File "/media/zahid/Ads Power/Enterprise Infosec Consultants/ComplyWiseApi/venv/lib/python3.11/site-packages/django/views/generic/base.py", line 104, in view
    return self.dispatch(request, *args, **kwargs)
           ^^^^^^^^^^^^^^^^^^^^^^^^^^^^^^^^^^^^^^^
  File "/media/zahid/Ads Power/Enterprise Infosec Consultants/ComplyWiseApi/venv/lib/python3.11/site-packages/rest_framework/views.py", line 509, in dispatch
    response = self.handle_exception(exc)
               ^^^^^^^^^^^^^^^^^^^^^^^^^^
  File "/media/zahid/Ads Power/Enterprise Infosec Consultants/ComplyWiseApi/venv/lib/python3.11/site-packages/rest_framework/views.py", line 469, in handle_exception
    self.raise_uncaught_exception(exc)
  File "/media/zahid/Ads Power/Enterprise Infosec Consultants/ComplyWiseApi/venv/lib/python3.11/site-packages/rest_framework/views.py", line 480, in raise_uncaught_exception
    raise exc
  File "/media/zahid/Ads Power/Enterprise Infosec Consultants/ComplyWiseApi/venv/lib/python3.11/site-packages/rest_framework/views.py", line 506, in dispatch
    response = handler(request, *args, **kwargs)
               ^^^^^^^^^^^^^^^^^^^^^^^^^^^^^^^^^
  File "/media/zahid/Ads Power/Enterprise Infosec Consultants/ComplyWiseApi/venv/lib/python3.11/site-packages/rest_framework/generics.py", line 194, in post
    return self.create(request, *args, **kwargs)
           ^^^^^^^^^^^^^^^^^^^^^^^^^^^^^^^^^^^^^
  File "/media/zahid/Ads Power/Enterprise Infosec Consultants/ComplyWiseApi/app/modules/access_control/views/user.py", line 25, in create
    serializer.save()
  File "/media/zahid/Ads Power/Enterprise Infosec Consultants/ComplyWiseApi/venv/lib/python3.11/site-packages/rest_framework/serializers.py", line 208, in save
    self.instance = self.create(validated_data)
                    ^^^^^^^^^^^^^^^^^^^^^^^^^^^
  File "/media/zahid/Ads Power/Enterprise Infosec Consultants/ComplyWiseApi/app/modules/access_control/serializers/user.py", line 13, in create
    user = User.objects.create_user(**validated_data)
           ^^^^^^^^^^^^^^^^^^^^^^^^^^^^^^^^^^^^^^^^^^
  File "/media/zahid/Ads Power/Enterprise Infosec Consultants/ComplyWiseApi/app/modules/access_control/models/user.py", line 13, in create_user
    user.save(using=self._db)
  File "/media/zahid/Ads Power/Enterprise Infosec Consultants/ComplyWiseApi/venv/lib/python3.11/site-packages/django/contrib/auth/base_user.py", line 62, in save
    super().save(*args, **kwargs)
  File "/media/zahid/Ads Power/Enterprise Infosec Consultants/ComplyWiseApi/venv/lib/python3.11/site-packages/django/db/models/base.py", line 892, in save
    self.save_base(
  File "/media/zahid/Ads Power/Enterprise Infosec Consultants/ComplyWiseApi/venv/lib/python3.11/site-packages/django/db/models/base.py", line 998, in save_base
    updated = self._save_table(
              ^^^^^^^^^^^^^^^^^
  File "/media/zahid/Ads Power/Enterprise Infosec Consultants/ComplyWiseApi/venv/lib/python3.11/site-packages/django/db/models/base.py", line 1161, in _save_table
    results = self._do_insert(
              ^^^^^^^^^^^^^^^^
  File "/media/zahid/Ads Power/Enterprise Infosec Consultants/ComplyWiseApi/venv/lib/python3.11/site-packages/django/db/models/base.py", line 1202, in _do_insert
    return manager._insert(
           ^^^^^^^^^^^^^^^^
  File "/media/zahid/Ads Power/Enterprise Infosec Consultants/ComplyWiseApi/venv/lib/python3.11/site-packages/django/db/models/manager.py", line 87, in manager_method
    return getattr(self.get_queryset(), name)(*args, **kwargs)
           ^^^^^^^^^^^^^^^^^^^^^^^^^^^^^^^^^^^^^^^^^^^^^^^^^^^
  File "/media/zahid/Ads Power/Enterprise Infosec Consultants/ComplyWiseApi/venv/lib/python3.11/site-packages/django/db/models/query.py", line 1847, in _insert
    return query.get_compiler(using=using).execute_sql(returning_fields)
           ^^^^^^^^^^^^^^^^^^^^^^^^^^^^^^^^^^^^^^^^^^^^^^^^^^^^^^^^^^^^^
  File "/media/zahid/Ads Power/Enterprise Infosec Consultants/ComplyWiseApi/venv/lib/python3.11/site-packages/django/db/models/sql/compiler.py", line 1836, in execute_sql
    cursor.execute(sql, params)
  File "/media/zahid/Ads Power/Enterprise Infosec Consultants/ComplyWiseApi/venv/lib/python3.11/site-packages/django/db/backends/utils.py", line 122, in execute
    return super().execute(sql, params)
           ^^^^^^^^^^^^^^^^^^^^^^^^^^^^
  File "/media/zahid/Ads Power/Enterprise Infosec Consultants/ComplyWiseApi/venv/lib/python3.11/site-packages/django/db/backends/utils.py", line 79, in execute
    return self._execute_with_wrappers(
           ^^^^^^^^^^^^^^^^^^^^^^^^^^^^
  File "/media/zahid/Ads Power/Enterprise Infosec Consultants/ComplyWiseApi/venv/lib/python3.11/site-packages/django/db/backends/utils.py", line 92, in _execute_with_wrappers
    return executor(sql, params, many, context)
           ^^^^^^^^^^^^^^^^^^^^^^^^^^^^^^^^^^^^
  File "/media/zahid/Ads Power/Enterprise Infosec Consultants/ComplyWiseApi/venv/lib/python3.11/site-packages/django/db/backends/utils.py", line 100, in _execute
    with self.db.wrap_database_errors:
  File "/media/zahid/Ads Power/Enterprise Infosec Consultants/ComplyWiseApi/venv/lib/python3.11/site-packages/django/db/utils.py", line 91, in __exit__
    raise dj_exc_value.with_traceback(traceback) from exc_value
  File "/media/zahid/Ads Power/Enterprise Infosec Consultants/ComplyWiseApi/venv/lib/python3.11/site-packages/django/db/backends/utils.py", line 105, in _execute
    return self.cursor.execute(sql, params)
           ^^^^^^^^^^^^^^^^^^^^^^^^^^^^^^^^
django.db.utils.IntegrityError: duplicate key value violates unique constraint "app_user_username_key"
DETAIL:  Key (username)=() already exists.

ERROR 2025-03-06 09:32:49,632 basehttp "POST /api/register/ HTTP/1.1" 500 212043
ERROR 2025-03-09 04:31:49,253 log Internal Server Error: /api/employees/1/
Traceback (most recent call last):
  File "/media/zahid/Ads Power/Enterprise Infosec Consultants/ComplyWiseApi/venv/lib/python3.11/site-packages/django/db/models/fields/__init__.py", line 2123, in get_prep_value
    return int(value)
           ^^^^^^^^^^
ValueError: invalid literal for int() with base 10: ','

The above exception was the direct cause of the following exception:

Traceback (most recent call last):
  File "/media/zahid/Ads Power/Enterprise Infosec Consultants/ComplyWiseApi/venv/lib/python3.11/site-packages/django/core/handlers/exception.py", line 55, in inner
    response = get_response(request)
               ^^^^^^^^^^^^^^^^^^^^^
  File "/media/zahid/Ads Power/Enterprise Infosec Consultants/ComplyWiseApi/venv/lib/python3.11/site-packages/django/core/handlers/base.py", line 197, in _get_response
    response = wrapped_callback(request, *callback_args, **callback_kwargs)
               ^^^^^^^^^^^^^^^^^^^^^^^^^^^^^^^^^^^^^^^^^^^^^^^^^^^^^^^^^^^^
  File "/media/zahid/Ads Power/Enterprise Infosec Consultants/ComplyWiseApi/venv/lib/python3.11/site-packages/django/views/decorators/csrf.py", line 65, in _view_wrapper
    return view_func(request, *args, **kwargs)
           ^^^^^^^^^^^^^^^^^^^^^^^^^^^^^^^^^^^
  File "/media/zahid/Ads Power/Enterprise Infosec Consultants/ComplyWiseApi/venv/lib/python3.11/site-packages/rest_framework/viewsets.py", line 124, in view
    return self.dispatch(request, *args, **kwargs)
           ^^^^^^^^^^^^^^^^^^^^^^^^^^^^^^^^^^^^^^^
  File "/media/zahid/Ads Power/Enterprise Infosec Consultants/ComplyWiseApi/venv/lib/python3.11/site-packages/rest_framework/views.py", line 509, in dispatch
    response = self.handle_exception(exc)
               ^^^^^^^^^^^^^^^^^^^^^^^^^^
  File "/media/zahid/Ads Power/Enterprise Infosec Consultants/ComplyWiseApi/venv/lib/python3.11/site-packages/rest_framework/views.py", line 469, in handle_exception
    self.raise_uncaught_exception(exc)
  File "/media/zahid/Ads Power/Enterprise Infosec Consultants/ComplyWiseApi/venv/lib/python3.11/site-packages/rest_framework/views.py", line 480, in raise_uncaught_exception
    raise exc
  File "/media/zahid/Ads Power/Enterprise Infosec Consultants/ComplyWiseApi/venv/lib/python3.11/site-packages/rest_framework/views.py", line 506, in dispatch
    response = handler(request, *args, **kwargs)
               ^^^^^^^^^^^^^^^^^^^^^^^^^^^^^^^^^
  File "/media/zahid/Ads Power/Enterprise Infosec Consultants/ComplyWiseApi/app/modules/access_control/views/employee.py", line 48, in partial_update
    Documents.objects.filter(id__in=deleted_documents_ids).delete()
    ^^^^^^^^^^^^^^^^^^^^^^^^^^^^^^^^^^^^^^^^^^^^^^^^^^^^^^
  File "/media/zahid/Ads Power/Enterprise Infosec Consultants/ComplyWiseApi/venv/lib/python3.11/site-packages/django/db/models/manager.py", line 87, in manager_method
    return getattr(self.get_queryset(), name)(*args, **kwargs)
           ^^^^^^^^^^^^^^^^^^^^^^^^^^^^^^^^^^^^^^^^^^^^^^^^^^^
  File "/media/zahid/Ads Power/Enterprise Infosec Consultants/ComplyWiseApi/venv/lib/python3.11/site-packages/django/db/models/query.py", line 1476, in filter
    return self._filter_or_exclude(False, args, kwargs)
           ^^^^^^^^^^^^^^^^^^^^^^^^^^^^^^^^^^^^^^^^^^^^
  File "/media/zahid/Ads Power/Enterprise Infosec Consultants/ComplyWiseApi/venv/lib/python3.11/site-packages/django/db/models/query.py", line 1494, in _filter_or_exclude
    clone._filter_or_exclude_inplace(negate, args, kwargs)
  File "/media/zahid/Ads Power/Enterprise Infosec Consultants/ComplyWiseApi/venv/lib/python3.11/site-packages/django/db/models/query.py", line 1501, in _filter_or_exclude_inplace
    self._query.add_q(Q(*args, **kwargs))
  File "/media/zahid/Ads Power/Enterprise Infosec Consultants/ComplyWiseApi/venv/lib/python3.11/site-packages/django/db/models/sql/query.py", line 1609, in add_q
    clause, _ = self._add_q(q_object, self.used_aliases)
                ^^^^^^^^^^^^^^^^^^^^^^^^^^^^^^^^^^^^^^^^
  File "/media/zahid/Ads Power/Enterprise Infosec Consultants/ComplyWiseApi/venv/lib/python3.11/site-packages/django/db/models/sql/query.py", line 1641, in _add_q
    child_clause, needed_inner = self.build_filter(
                                 ^^^^^^^^^^^^^^^^^^
  File "/media/zahid/Ads Power/Enterprise Infosec Consultants/ComplyWiseApi/venv/lib/python3.11/site-packages/django/db/models/sql/query.py", line 1555, in build_filter
    condition = self.build_lookup(lookups, col, value)
                ^^^^^^^^^^^^^^^^^^^^^^^^^^^^^^^^^^^^^^
  File "/media/zahid/Ads Power/Enterprise Infosec Consultants/ComplyWiseApi/venv/lib/python3.11/site-packages/django/db/models/sql/query.py", line 1385, in build_lookup
    lookup = lookup_class(lhs, rhs)
             ^^^^^^^^^^^^^^^^^^^^^^
  File "/media/zahid/Ads Power/Enterprise Infosec Consultants/ComplyWiseApi/venv/lib/python3.11/site-packages/django/db/models/lookups.py", line 30, in __init__
    self.rhs = self.get_prep_lookup()
               ^^^^^^^^^^^^^^^^^^^^^^
  File "/media/zahid/Ads Power/Enterprise Infosec Consultants/ComplyWiseApi/venv/lib/python3.11/site-packages/django/db/models/lookups.py", line 497, in get_prep_lookup
    return super().get_prep_lookup()
           ^^^^^^^^^^^^^^^^^^^^^^^^^
  File "/media/zahid/Ads Power/Enterprise Infosec Consultants/ComplyWiseApi/venv/lib/python3.11/site-packages/django/db/models/lookups.py", line 304, in get_prep_lookup
    rhs_value = self.lhs.output_field.get_prep_value(rhs_value)
                ^^^^^^^^^^^^^^^^^^^^^^^^^^^^^^^^^^^^^^^^^^^^^^^
  File "/media/zahid/Ads Power/Enterprise Infosec Consultants/ComplyWiseApi/venv/lib/python3.11/site-packages/django/db/models/fields/__init__.py", line 2125, in get_prep_value
    raise e.__class__(
ValueError: Field 'id' expected a number but got ','.
ERROR 2025-03-09 04:31:49,263 basehttp "PATCH /api/employees/1/ HTTP/1.1" 500 175345
ERROR 2025-03-09 04:31:59,867 log Internal Server Error: /api/employees/1/
Traceback (most recent call last):
  File "/media/zahid/Ads Power/Enterprise Infosec Consultants/ComplyWiseApi/venv/lib/python3.11/site-packages/django/db/models/fields/__init__.py", line 2123, in get_prep_value
    return int(value)
           ^^^^^^^^^^
ValueError: invalid literal for int() with base 10: ','

The above exception was the direct cause of the following exception:

Traceback (most recent call last):
  File "/media/zahid/Ads Power/Enterprise Infosec Consultants/ComplyWiseApi/venv/lib/python3.11/site-packages/django/core/handlers/exception.py", line 55, in inner
    response = get_response(request)
               ^^^^^^^^^^^^^^^^^^^^^
  File "/media/zahid/Ads Power/Enterprise Infosec Consultants/ComplyWiseApi/venv/lib/python3.11/site-packages/django/core/handlers/base.py", line 197, in _get_response
    response = wrapped_callback(request, *callback_args, **callback_kwargs)
               ^^^^^^^^^^^^^^^^^^^^^^^^^^^^^^^^^^^^^^^^^^^^^^^^^^^^^^^^^^^^
  File "/media/zahid/Ads Power/Enterprise Infosec Consultants/ComplyWiseApi/venv/lib/python3.11/site-packages/django/views/decorators/csrf.py", line 65, in _view_wrapper
    return view_func(request, *args, **kwargs)
           ^^^^^^^^^^^^^^^^^^^^^^^^^^^^^^^^^^^
  File "/media/zahid/Ads Power/Enterprise Infosec Consultants/ComplyWiseApi/venv/lib/python3.11/site-packages/rest_framework/viewsets.py", line 124, in view
    return self.dispatch(request, *args, **kwargs)
           ^^^^^^^^^^^^^^^^^^^^^^^^^^^^^^^^^^^^^^^
  File "/media/zahid/Ads Power/Enterprise Infosec Consultants/ComplyWiseApi/venv/lib/python3.11/site-packages/rest_framework/views.py", line 509, in dispatch
    response = self.handle_exception(exc)
               ^^^^^^^^^^^^^^^^^^^^^^^^^^
  File "/media/zahid/Ads Power/Enterprise Infosec Consultants/ComplyWiseApi/venv/lib/python3.11/site-packages/rest_framework/views.py", line 469, in handle_exception
    self.raise_uncaught_exception(exc)
  File "/media/zahid/Ads Power/Enterprise Infosec Consultants/ComplyWiseApi/venv/lib/python3.11/site-packages/rest_framework/views.py", line 480, in raise_uncaught_exception
    raise exc
  File "/media/zahid/Ads Power/Enterprise Infosec Consultants/ComplyWiseApi/venv/lib/python3.11/site-packages/rest_framework/views.py", line 506, in dispatch
    response = handler(request, *args, **kwargs)
               ^^^^^^^^^^^^^^^^^^^^^^^^^^^^^^^^^
  File "/media/zahid/Ads Power/Enterprise Infosec Consultants/ComplyWiseApi/app/modules/access_control/views/employee.py", line 48, in partial_update
    Documents.objects.filter(id__in=deleted_documents_ids).delete()
    ^^^^^^^^^^^^^^^^^^^^^^^^^^^^^^^^^^^^^^^^^^^^^^^^^^^^^^
  File "/media/zahid/Ads Power/Enterprise Infosec Consultants/ComplyWiseApi/venv/lib/python3.11/site-packages/django/db/models/manager.py", line 87, in manager_method
    return getattr(self.get_queryset(), name)(*args, **kwargs)
           ^^^^^^^^^^^^^^^^^^^^^^^^^^^^^^^^^^^^^^^^^^^^^^^^^^^
  File "/media/zahid/Ads Power/Enterprise Infosec Consultants/ComplyWiseApi/venv/lib/python3.11/site-packages/django/db/models/query.py", line 1476, in filter
    return self._filter_or_exclude(False, args, kwargs)
           ^^^^^^^^^^^^^^^^^^^^^^^^^^^^^^^^^^^^^^^^^^^^
  File "/media/zahid/Ads Power/Enterprise Infosec Consultants/ComplyWiseApi/venv/lib/python3.11/site-packages/django/db/models/query.py", line 1494, in _filter_or_exclude
    clone._filter_or_exclude_inplace(negate, args, kwargs)
  File "/media/zahid/Ads Power/Enterprise Infosec Consultants/ComplyWiseApi/venv/lib/python3.11/site-packages/django/db/models/query.py", line 1501, in _filter_or_exclude_inplace
    self._query.add_q(Q(*args, **kwargs))
  File "/media/zahid/Ads Power/Enterprise Infosec Consultants/ComplyWiseApi/venv/lib/python3.11/site-packages/django/db/models/sql/query.py", line 1609, in add_q
    clause, _ = self._add_q(q_object, self.used_aliases)
                ^^^^^^^^^^^^^^^^^^^^^^^^^^^^^^^^^^^^^^^^
  File "/media/zahid/Ads Power/Enterprise Infosec Consultants/ComplyWiseApi/venv/lib/python3.11/site-packages/django/db/models/sql/query.py", line 1641, in _add_q
    child_clause, needed_inner = self.build_filter(
                                 ^^^^^^^^^^^^^^^^^^
  File "/media/zahid/Ads Power/Enterprise Infosec Consultants/ComplyWiseApi/venv/lib/python3.11/site-packages/django/db/models/sql/query.py", line 1555, in build_filter
    condition = self.build_lookup(lookups, col, value)
                ^^^^^^^^^^^^^^^^^^^^^^^^^^^^^^^^^^^^^^
  File "/media/zahid/Ads Power/Enterprise Infosec Consultants/ComplyWiseApi/venv/lib/python3.11/site-packages/django/db/models/sql/query.py", line 1385, in build_lookup
    lookup = lookup_class(lhs, rhs)
             ^^^^^^^^^^^^^^^^^^^^^^
  File "/media/zahid/Ads Power/Enterprise Infosec Consultants/ComplyWiseApi/venv/lib/python3.11/site-packages/django/db/models/lookups.py", line 30, in __init__
    self.rhs = self.get_prep_lookup()
               ^^^^^^^^^^^^^^^^^^^^^^
  File "/media/zahid/Ads Power/Enterprise Infosec Consultants/ComplyWiseApi/venv/lib/python3.11/site-packages/django/db/models/lookups.py", line 497, in get_prep_lookup
    return super().get_prep_lookup()
           ^^^^^^^^^^^^^^^^^^^^^^^^^
  File "/media/zahid/Ads Power/Enterprise Infosec Consultants/ComplyWiseApi/venv/lib/python3.11/site-packages/django/db/models/lookups.py", line 304, in get_prep_lookup
    rhs_value = self.lhs.output_field.get_prep_value(rhs_value)
                ^^^^^^^^^^^^^^^^^^^^^^^^^^^^^^^^^^^^^^^^^^^^^^^
  File "/media/zahid/Ads Power/Enterprise Infosec Consultants/ComplyWiseApi/venv/lib/python3.11/site-packages/django/db/models/fields/__init__.py", line 2125, in get_prep_value
    raise e.__class__(
ValueError: Field 'id' expected a number but got ','.
ERROR 2025-03-09 04:31:59,869 basehttp "PATCH /api/employees/1/ HTTP/1.1" 500 175138
ERROR 2025-03-09 04:32:22,749 log Internal Server Error: /api/employees/1/
Traceback (most recent call last):
  File "/media/zahid/Ads Power/Enterprise Infosec Consultants/ComplyWiseApi/venv/lib/python3.11/site-packages/django/db/models/fields/__init__.py", line 2123, in get_prep_value
    return int(value)
           ^^^^^^^^^^
ValueError: invalid literal for int() with base 10: ' '

The above exception was the direct cause of the following exception:

Traceback (most recent call last):
  File "/media/zahid/Ads Power/Enterprise Infosec Consultants/ComplyWiseApi/venv/lib/python3.11/site-packages/django/core/handlers/exception.py", line 55, in inner
    response = get_response(request)
               ^^^^^^^^^^^^^^^^^^^^^
  File "/media/zahid/Ads Power/Enterprise Infosec Consultants/ComplyWiseApi/venv/lib/python3.11/site-packages/django/core/handlers/base.py", line 197, in _get_response
    response = wrapped_callback(request, *callback_args, **callback_kwargs)
               ^^^^^^^^^^^^^^^^^^^^^^^^^^^^^^^^^^^^^^^^^^^^^^^^^^^^^^^^^^^^
  File "/media/zahid/Ads Power/Enterprise Infosec Consultants/ComplyWiseApi/venv/lib/python3.11/site-packages/django/views/decorators/csrf.py", line 65, in _view_wrapper
    return view_func(request, *args, **kwargs)
           ^^^^^^^^^^^^^^^^^^^^^^^^^^^^^^^^^^^
  File "/media/zahid/Ads Power/Enterprise Infosec Consultants/ComplyWiseApi/venv/lib/python3.11/site-packages/rest_framework/viewsets.py", line 124, in view
    return self.dispatch(request, *args, **kwargs)
           ^^^^^^^^^^^^^^^^^^^^^^^^^^^^^^^^^^^^^^^
  File "/media/zahid/Ads Power/Enterprise Infosec Consultants/ComplyWiseApi/venv/lib/python3.11/site-packages/rest_framework/views.py", line 509, in dispatch
    response = self.handle_exception(exc)
               ^^^^^^^^^^^^^^^^^^^^^^^^^^
  File "/media/zahid/Ads Power/Enterprise Infosec Consultants/ComplyWiseApi/venv/lib/python3.11/site-packages/rest_framework/views.py", line 469, in handle_exception
    self.raise_uncaught_exception(exc)
  File "/media/zahid/Ads Power/Enterprise Infosec Consultants/ComplyWiseApi/venv/lib/python3.11/site-packages/rest_framework/views.py", line 480, in raise_uncaught_exception
    raise exc
  File "/media/zahid/Ads Power/Enterprise Infosec Consultants/ComplyWiseApi/venv/lib/python3.11/site-packages/rest_framework/views.py", line 506, in dispatch
    response = handler(request, *args, **kwargs)
               ^^^^^^^^^^^^^^^^^^^^^^^^^^^^^^^^^
  File "/media/zahid/Ads Power/Enterprise Infosec Consultants/ComplyWiseApi/app/modules/access_control/views/employee.py", line 48, in partial_update
    Documents.objects.filter(id__in=deleted_documents_ids).delete()
    ^^^^^^^^^^^^^^^^^^^^^^^^^^^^^^^^^^^^^^^^^^^^^^^^^^^^^^
  File "/media/zahid/Ads Power/Enterprise Infosec Consultants/ComplyWiseApi/venv/lib/python3.11/site-packages/django/db/models/manager.py", line 87, in manager_method
    return getattr(self.get_queryset(), name)(*args, **kwargs)
           ^^^^^^^^^^^^^^^^^^^^^^^^^^^^^^^^^^^^^^^^^^^^^^^^^^^
  File "/media/zahid/Ads Power/Enterprise Infosec Consultants/ComplyWiseApi/venv/lib/python3.11/site-packages/django/db/models/query.py", line 1476, in filter
    return self._filter_or_exclude(False, args, kwargs)
           ^^^^^^^^^^^^^^^^^^^^^^^^^^^^^^^^^^^^^^^^^^^^
  File "/media/zahid/Ads Power/Enterprise Infosec Consultants/ComplyWiseApi/venv/lib/python3.11/site-packages/django/db/models/query.py", line 1494, in _filter_or_exclude
    clone._filter_or_exclude_inplace(negate, args, kwargs)
  File "/media/zahid/Ads Power/Enterprise Infosec Consultants/ComplyWiseApi/venv/lib/python3.11/site-packages/django/db/models/query.py", line 1501, in _filter_or_exclude_inplace
    self._query.add_q(Q(*args, **kwargs))
  File "/media/zahid/Ads Power/Enterprise Infosec Consultants/ComplyWiseApi/venv/lib/python3.11/site-packages/django/db/models/sql/query.py", line 1609, in add_q
    clause, _ = self._add_q(q_object, self.used_aliases)
                ^^^^^^^^^^^^^^^^^^^^^^^^^^^^^^^^^^^^^^^^
  File "/media/zahid/Ads Power/Enterprise Infosec Consultants/ComplyWiseApi/venv/lib/python3.11/site-packages/django/db/models/sql/query.py", line 1641, in _add_q
    child_clause, needed_inner = self.build_filter(
                                 ^^^^^^^^^^^^^^^^^^
  File "/media/zahid/Ads Power/Enterprise Infosec Consultants/ComplyWiseApi/venv/lib/python3.11/site-packages/django/db/models/sql/query.py", line 1555, in build_filter
    condition = self.build_lookup(lookups, col, value)
                ^^^^^^^^^^^^^^^^^^^^^^^^^^^^^^^^^^^^^^
  File "/media/zahid/Ads Power/Enterprise Infosec Consultants/ComplyWiseApi/venv/lib/python3.11/site-packages/django/db/models/sql/query.py", line 1385, in build_lookup
    lookup = lookup_class(lhs, rhs)
             ^^^^^^^^^^^^^^^^^^^^^^
  File "/media/zahid/Ads Power/Enterprise Infosec Consultants/ComplyWiseApi/venv/lib/python3.11/site-packages/django/db/models/lookups.py", line 30, in __init__
    self.rhs = self.get_prep_lookup()
               ^^^^^^^^^^^^^^^^^^^^^^
  File "/media/zahid/Ads Power/Enterprise Infosec Consultants/ComplyWiseApi/venv/lib/python3.11/site-packages/django/db/models/lookups.py", line 497, in get_prep_lookup
    return super().get_prep_lookup()
           ^^^^^^^^^^^^^^^^^^^^^^^^^
  File "/media/zahid/Ads Power/Enterprise Infosec Consultants/ComplyWiseApi/venv/lib/python3.11/site-packages/django/db/models/lookups.py", line 304, in get_prep_lookup
    rhs_value = self.lhs.output_field.get_prep_value(rhs_value)
                ^^^^^^^^^^^^^^^^^^^^^^^^^^^^^^^^^^^^^^^^^^^^^^^
  File "/media/zahid/Ads Power/Enterprise Infosec Consultants/ComplyWiseApi/venv/lib/python3.11/site-packages/django/db/models/fields/__init__.py", line 2125, in get_prep_value
    raise e.__class__(
ValueError: Field 'id' expected a number but got ' '.
ERROR 2025-03-09 04:32:22,753 basehttp "PATCH /api/employees/1/ HTTP/1.1" 500 175156
ERROR 2025-03-09 04:32:37,110 log Internal Server Error: /api/employees/1/
Traceback (most recent call last):
  File "/media/zahid/Ads Power/Enterprise Infosec Consultants/ComplyWiseApi/venv/lib/python3.11/site-packages/django/db/models/fields/__init__.py", line 2123, in get_prep_value
    return int(value)
           ^^^^^^^^^^
ValueError: invalid literal for int() with base 10: '['

The above exception was the direct cause of the following exception:

Traceback (most recent call last):
  File "/media/zahid/Ads Power/Enterprise Infosec Consultants/ComplyWiseApi/venv/lib/python3.11/site-packages/django/core/handlers/exception.py", line 55, in inner
    response = get_response(request)
               ^^^^^^^^^^^^^^^^^^^^^
  File "/media/zahid/Ads Power/Enterprise Infosec Consultants/ComplyWiseApi/venv/lib/python3.11/site-packages/django/core/handlers/base.py", line 197, in _get_response
    response = wrapped_callback(request, *callback_args, **callback_kwargs)
               ^^^^^^^^^^^^^^^^^^^^^^^^^^^^^^^^^^^^^^^^^^^^^^^^^^^^^^^^^^^^
  File "/media/zahid/Ads Power/Enterprise Infosec Consultants/ComplyWiseApi/venv/lib/python3.11/site-packages/django/views/decorators/csrf.py", line 65, in _view_wrapper
    return view_func(request, *args, **kwargs)
           ^^^^^^^^^^^^^^^^^^^^^^^^^^^^^^^^^^^
  File "/media/zahid/Ads Power/Enterprise Infosec Consultants/ComplyWiseApi/venv/lib/python3.11/site-packages/rest_framework/viewsets.py", line 124, in view
    return self.dispatch(request, *args, **kwargs)
           ^^^^^^^^^^^^^^^^^^^^^^^^^^^^^^^^^^^^^^^
  File "/media/zahid/Ads Power/Enterprise Infosec Consultants/ComplyWiseApi/venv/lib/python3.11/site-packages/rest_framework/views.py", line 509, in dispatch
    response = self.handle_exception(exc)
               ^^^^^^^^^^^^^^^^^^^^^^^^^^
  File "/media/zahid/Ads Power/Enterprise Infosec Consultants/ComplyWiseApi/venv/lib/python3.11/site-packages/rest_framework/views.py", line 469, in handle_exception
    self.raise_uncaught_exception(exc)
  File "/media/zahid/Ads Power/Enterprise Infosec Consultants/ComplyWiseApi/venv/lib/python3.11/site-packages/rest_framework/views.py", line 480, in raise_uncaught_exception
    raise exc
  File "/media/zahid/Ads Power/Enterprise Infosec Consultants/ComplyWiseApi/venv/lib/python3.11/site-packages/rest_framework/views.py", line 506, in dispatch
    response = handler(request, *args, **kwargs)
               ^^^^^^^^^^^^^^^^^^^^^^^^^^^^^^^^^
  File "/media/zahid/Ads Power/Enterprise Infosec Consultants/ComplyWiseApi/app/modules/access_control/views/employee.py", line 48, in partial_update
    Documents.objects.filter(id__in=deleted_documents_ids).delete()
    ^^^^^^^^^^^^^^^^^^^^^^^^^^^^^^^^^^^^^^^^^^^^^^^^^^^^^^
  File "/media/zahid/Ads Power/Enterprise Infosec Consultants/ComplyWiseApi/venv/lib/python3.11/site-packages/django/db/models/manager.py", line 87, in manager_method
    return getattr(self.get_queryset(), name)(*args, **kwargs)
           ^^^^^^^^^^^^^^^^^^^^^^^^^^^^^^^^^^^^^^^^^^^^^^^^^^^
  File "/media/zahid/Ads Power/Enterprise Infosec Consultants/ComplyWiseApi/venv/lib/python3.11/site-packages/django/db/models/query.py", line 1476, in filter
    return self._filter_or_exclude(False, args, kwargs)
           ^^^^^^^^^^^^^^^^^^^^^^^^^^^^^^^^^^^^^^^^^^^^
  File "/media/zahid/Ads Power/Enterprise Infosec Consultants/ComplyWiseApi/venv/lib/python3.11/site-packages/django/db/models/query.py", line 1494, in _filter_or_exclude
    clone._filter_or_exclude_inplace(negate, args, kwargs)
  File "/media/zahid/Ads Power/Enterprise Infosec Consultants/ComplyWiseApi/venv/lib/python3.11/site-packages/django/db/models/query.py", line 1501, in _filter_or_exclude_inplace
    self._query.add_q(Q(*args, **kwargs))
  File "/media/zahid/Ads Power/Enterprise Infosec Consultants/ComplyWiseApi/venv/lib/python3.11/site-packages/django/db/models/sql/query.py", line 1609, in add_q
    clause, _ = self._add_q(q_object, self.used_aliases)
                ^^^^^^^^^^^^^^^^^^^^^^^^^^^^^^^^^^^^^^^^
  File "/media/zahid/Ads Power/Enterprise Infosec Consultants/ComplyWiseApi/venv/lib/python3.11/site-packages/django/db/models/sql/query.py", line 1641, in _add_q
    child_clause, needed_inner = self.build_filter(
                                 ^^^^^^^^^^^^^^^^^^
  File "/media/zahid/Ads Power/Enterprise Infosec Consultants/ComplyWiseApi/venv/lib/python3.11/site-packages/django/db/models/sql/query.py", line 1555, in build_filter
    condition = self.build_lookup(lookups, col, value)
                ^^^^^^^^^^^^^^^^^^^^^^^^^^^^^^^^^^^^^^
  File "/media/zahid/Ads Power/Enterprise Infosec Consultants/ComplyWiseApi/venv/lib/python3.11/site-packages/django/db/models/sql/query.py", line 1385, in build_lookup
    lookup = lookup_class(lhs, rhs)
             ^^^^^^^^^^^^^^^^^^^^^^
  File "/media/zahid/Ads Power/Enterprise Infosec Consultants/ComplyWiseApi/venv/lib/python3.11/site-packages/django/db/models/lookups.py", line 30, in __init__
    self.rhs = self.get_prep_lookup()
               ^^^^^^^^^^^^^^^^^^^^^^
  File "/media/zahid/Ads Power/Enterprise Infosec Consultants/ComplyWiseApi/venv/lib/python3.11/site-packages/django/db/models/lookups.py", line 497, in get_prep_lookup
    return super().get_prep_lookup()
           ^^^^^^^^^^^^^^^^^^^^^^^^^
  File "/media/zahid/Ads Power/Enterprise Infosec Consultants/ComplyWiseApi/venv/lib/python3.11/site-packages/django/db/models/lookups.py", line 304, in get_prep_lookup
    rhs_value = self.lhs.output_field.get_prep_value(rhs_value)
                ^^^^^^^^^^^^^^^^^^^^^^^^^^^^^^^^^^^^^^^^^^^^^^^
  File "/media/zahid/Ads Power/Enterprise Infosec Consultants/ComplyWiseApi/venv/lib/python3.11/site-packages/django/db/models/fields/__init__.py", line 2125, in get_prep_value
    raise e.__class__(
ValueError: Field 'id' expected a number but got '['.
ERROR 2025-03-09 04:32:37,116 basehttp "PATCH /api/employees/1/ HTTP/1.1" 500 175173
ERROR 2025-03-09 04:36:44,064 log Internal Server Error: /api/employees/1/
Traceback (most recent call last):
  File "/media/zahid/Ads Power/Enterprise Infosec Consultants/ComplyWiseApi/venv/lib/python3.11/site-packages/django/db/models/fields/__init__.py", line 2123, in get_prep_value
    return int(value)
           ^^^^^^^^^^
ValueError: invalid literal for int() with base 10: '['

The above exception was the direct cause of the following exception:

Traceback (most recent call last):
  File "/media/zahid/Ads Power/Enterprise Infosec Consultants/ComplyWiseApi/venv/lib/python3.11/site-packages/django/core/handlers/exception.py", line 55, in inner
    response = get_response(request)
               ^^^^^^^^^^^^^^^^^^^^^
  File "/media/zahid/Ads Power/Enterprise Infosec Consultants/ComplyWiseApi/venv/lib/python3.11/site-packages/django/core/handlers/base.py", line 197, in _get_response
    response = wrapped_callback(request, *callback_args, **callback_kwargs)
               ^^^^^^^^^^^^^^^^^^^^^^^^^^^^^^^^^^^^^^^^^^^^^^^^^^^^^^^^^^^^
  File "/media/zahid/Ads Power/Enterprise Infosec Consultants/ComplyWiseApi/venv/lib/python3.11/site-packages/django/views/decorators/csrf.py", line 65, in _view_wrapper
    return view_func(request, *args, **kwargs)
           ^^^^^^^^^^^^^^^^^^^^^^^^^^^^^^^^^^^
  File "/media/zahid/Ads Power/Enterprise Infosec Consultants/ComplyWiseApi/venv/lib/python3.11/site-packages/rest_framework/viewsets.py", line 124, in view
    return self.dispatch(request, *args, **kwargs)
           ^^^^^^^^^^^^^^^^^^^^^^^^^^^^^^^^^^^^^^^
  File "/media/zahid/Ads Power/Enterprise Infosec Consultants/ComplyWiseApi/venv/lib/python3.11/site-packages/rest_framework/views.py", line 509, in dispatch
    response = self.handle_exception(exc)
               ^^^^^^^^^^^^^^^^^^^^^^^^^^
  File "/media/zahid/Ads Power/Enterprise Infosec Consultants/ComplyWiseApi/venv/lib/python3.11/site-packages/rest_framework/views.py", line 469, in handle_exception
    self.raise_uncaught_exception(exc)
  File "/media/zahid/Ads Power/Enterprise Infosec Consultants/ComplyWiseApi/venv/lib/python3.11/site-packages/rest_framework/views.py", line 480, in raise_uncaught_exception
    raise exc
  File "/media/zahid/Ads Power/Enterprise Infosec Consultants/ComplyWiseApi/venv/lib/python3.11/site-packages/rest_framework/views.py", line 506, in dispatch
    response = handler(request, *args, **kwargs)
               ^^^^^^^^^^^^^^^^^^^^^^^^^^^^^^^^^
  File "/media/zahid/Ads Power/Enterprise Infosec Consultants/ComplyWiseApi/app/modules/access_control/views/employee.py", line 48, in partial_update
    Documents.objects.filter(id__in=deleted_documents_ids).delete()
    ^^^^^^^^^^^^^^^^^^^^^^^^^^^^^^^^^^^^^^^^^^^^^^^^^^^^^^
  File "/media/zahid/Ads Power/Enterprise Infosec Consultants/ComplyWiseApi/venv/lib/python3.11/site-packages/django/db/models/manager.py", line 87, in manager_method
    return getattr(self.get_queryset(), name)(*args, **kwargs)
           ^^^^^^^^^^^^^^^^^^^^^^^^^^^^^^^^^^^^^^^^^^^^^^^^^^^
  File "/media/zahid/Ads Power/Enterprise Infosec Consultants/ComplyWiseApi/venv/lib/python3.11/site-packages/django/db/models/query.py", line 1476, in filter
    return self._filter_or_exclude(False, args, kwargs)
           ^^^^^^^^^^^^^^^^^^^^^^^^^^^^^^^^^^^^^^^^^^^^
  File "/media/zahid/Ads Power/Enterprise Infosec Consultants/ComplyWiseApi/venv/lib/python3.11/site-packages/django/db/models/query.py", line 1494, in _filter_or_exclude
    clone._filter_or_exclude_inplace(negate, args, kwargs)
  File "/media/zahid/Ads Power/Enterprise Infosec Consultants/ComplyWiseApi/venv/lib/python3.11/site-packages/django/db/models/query.py", line 1501, in _filter_or_exclude_inplace
    self._query.add_q(Q(*args, **kwargs))
  File "/media/zahid/Ads Power/Enterprise Infosec Consultants/ComplyWiseApi/venv/lib/python3.11/site-packages/django/db/models/sql/query.py", line 1609, in add_q
    clause, _ = self._add_q(q_object, self.used_aliases)
                ^^^^^^^^^^^^^^^^^^^^^^^^^^^^^^^^^^^^^^^^
  File "/media/zahid/Ads Power/Enterprise Infosec Consultants/ComplyWiseApi/venv/lib/python3.11/site-packages/django/db/models/sql/query.py", line 1641, in _add_q
    child_clause, needed_inner = self.build_filter(
                                 ^^^^^^^^^^^^^^^^^^
  File "/media/zahid/Ads Power/Enterprise Infosec Consultants/ComplyWiseApi/venv/lib/python3.11/site-packages/django/db/models/sql/query.py", line 1555, in build_filter
    condition = self.build_lookup(lookups, col, value)
                ^^^^^^^^^^^^^^^^^^^^^^^^^^^^^^^^^^^^^^
  File "/media/zahid/Ads Power/Enterprise Infosec Consultants/ComplyWiseApi/venv/lib/python3.11/site-packages/django/db/models/sql/query.py", line 1385, in build_lookup
    lookup = lookup_class(lhs, rhs)
             ^^^^^^^^^^^^^^^^^^^^^^
  File "/media/zahid/Ads Power/Enterprise Infosec Consultants/ComplyWiseApi/venv/lib/python3.11/site-packages/django/db/models/lookups.py", line 30, in __init__
    self.rhs = self.get_prep_lookup()
               ^^^^^^^^^^^^^^^^^^^^^^
  File "/media/zahid/Ads Power/Enterprise Infosec Consultants/ComplyWiseApi/venv/lib/python3.11/site-packages/django/db/models/lookups.py", line 497, in get_prep_lookup
    return super().get_prep_lookup()
           ^^^^^^^^^^^^^^^^^^^^^^^^^
  File "/media/zahid/Ads Power/Enterprise Infosec Consultants/ComplyWiseApi/venv/lib/python3.11/site-packages/django/db/models/lookups.py", line 304, in get_prep_lookup
    rhs_value = self.lhs.output_field.get_prep_value(rhs_value)
                ^^^^^^^^^^^^^^^^^^^^^^^^^^^^^^^^^^^^^^^^^^^^^^^
  File "/media/zahid/Ads Power/Enterprise Infosec Consultants/ComplyWiseApi/venv/lib/python3.11/site-packages/django/db/models/fields/__init__.py", line 2125, in get_prep_value
    raise e.__class__(
ValueError: Field 'id' expected a number but got '['.
ERROR 2025-03-09 04:36:44,066 basehttp "PATCH /api/employees/1/ HTTP/1.1" 500 176408
ERROR 2025-03-09 04:41:14,070 log Internal Server Error: /api/employees/1/
Traceback (most recent call last):
  File "/media/zahid/Ads Power/Enterprise Infosec Consultants/ComplyWiseApi/venv/lib/python3.11/site-packages/django/db/models/fields/__init__.py", line 2123, in get_prep_value
    return int(value)
           ^^^^^^^^^^
ValueError: invalid literal for int() with base 10: '['

The above exception was the direct cause of the following exception:

Traceback (most recent call last):
  File "/media/zahid/Ads Power/Enterprise Infosec Consultants/ComplyWiseApi/venv/lib/python3.11/site-packages/django/core/handlers/exception.py", line 55, in inner
    response = get_response(request)
               ^^^^^^^^^^^^^^^^^^^^^
  File "/media/zahid/Ads Power/Enterprise Infosec Consultants/ComplyWiseApi/venv/lib/python3.11/site-packages/django/core/handlers/base.py", line 197, in _get_response
    response = wrapped_callback(request, *callback_args, **callback_kwargs)
               ^^^^^^^^^^^^^^^^^^^^^^^^^^^^^^^^^^^^^^^^^^^^^^^^^^^^^^^^^^^^
  File "/media/zahid/Ads Power/Enterprise Infosec Consultants/ComplyWiseApi/venv/lib/python3.11/site-packages/django/views/decorators/csrf.py", line 65, in _view_wrapper
    return view_func(request, *args, **kwargs)
           ^^^^^^^^^^^^^^^^^^^^^^^^^^^^^^^^^^^
  File "/media/zahid/Ads Power/Enterprise Infosec Consultants/ComplyWiseApi/venv/lib/python3.11/site-packages/rest_framework/viewsets.py", line 124, in view
    return self.dispatch(request, *args, **kwargs)
           ^^^^^^^^^^^^^^^^^^^^^^^^^^^^^^^^^^^^^^^
  File "/media/zahid/Ads Power/Enterprise Infosec Consultants/ComplyWiseApi/venv/lib/python3.11/site-packages/rest_framework/views.py", line 509, in dispatch
    response = self.handle_exception(exc)
               ^^^^^^^^^^^^^^^^^^^^^^^^^^
  File "/media/zahid/Ads Power/Enterprise Infosec Consultants/ComplyWiseApi/venv/lib/python3.11/site-packages/rest_framework/views.py", line 469, in handle_exception
    self.raise_uncaught_exception(exc)
  File "/media/zahid/Ads Power/Enterprise Infosec Consultants/ComplyWiseApi/venv/lib/python3.11/site-packages/rest_framework/views.py", line 480, in raise_uncaught_exception
    raise exc
  File "/media/zahid/Ads Power/Enterprise Infosec Consultants/ComplyWiseApi/venv/lib/python3.11/site-packages/rest_framework/views.py", line 506, in dispatch
    response = handler(request, *args, **kwargs)
               ^^^^^^^^^^^^^^^^^^^^^^^^^^^^^^^^^
  File "/media/zahid/Ads Power/Enterprise Infosec Consultants/ComplyWiseApi/app/modules/access_control/views/employee.py", line 48, in partial_update
    Documents.objects.filter(id__in=deleted_documents_ids).delete()
    ^^^^^^^^^^^^^^^^^^^^^^^^^^^^^^^^^^^^^^^^^^^^^^^^^^^^^^
  File "/media/zahid/Ads Power/Enterprise Infosec Consultants/ComplyWiseApi/venv/lib/python3.11/site-packages/django/db/models/manager.py", line 87, in manager_method
    return getattr(self.get_queryset(), name)(*args, **kwargs)
           ^^^^^^^^^^^^^^^^^^^^^^^^^^^^^^^^^^^^^^^^^^^^^^^^^^^
  File "/media/zahid/Ads Power/Enterprise Infosec Consultants/ComplyWiseApi/venv/lib/python3.11/site-packages/django/db/models/query.py", line 1476, in filter
    return self._filter_or_exclude(False, args, kwargs)
           ^^^^^^^^^^^^^^^^^^^^^^^^^^^^^^^^^^^^^^^^^^^^
  File "/media/zahid/Ads Power/Enterprise Infosec Consultants/ComplyWiseApi/venv/lib/python3.11/site-packages/django/db/models/query.py", line 1494, in _filter_or_exclude
    clone._filter_or_exclude_inplace(negate, args, kwargs)
  File "/media/zahid/Ads Power/Enterprise Infosec Consultants/ComplyWiseApi/venv/lib/python3.11/site-packages/django/db/models/query.py", line 1501, in _filter_or_exclude_inplace
    self._query.add_q(Q(*args, **kwargs))
  File "/media/zahid/Ads Power/Enterprise Infosec Consultants/ComplyWiseApi/venv/lib/python3.11/site-packages/django/db/models/sql/query.py", line 1609, in add_q
    clause, _ = self._add_q(q_object, self.used_aliases)
                ^^^^^^^^^^^^^^^^^^^^^^^^^^^^^^^^^^^^^^^^
  File "/media/zahid/Ads Power/Enterprise Infosec Consultants/ComplyWiseApi/venv/lib/python3.11/site-packages/django/db/models/sql/query.py", line 1641, in _add_q
    child_clause, needed_inner = self.build_filter(
                                 ^^^^^^^^^^^^^^^^^^
  File "/media/zahid/Ads Power/Enterprise Infosec Consultants/ComplyWiseApi/venv/lib/python3.11/site-packages/django/db/models/sql/query.py", line 1555, in build_filter
    condition = self.build_lookup(lookups, col, value)
                ^^^^^^^^^^^^^^^^^^^^^^^^^^^^^^^^^^^^^^
  File "/media/zahid/Ads Power/Enterprise Infosec Consultants/ComplyWiseApi/venv/lib/python3.11/site-packages/django/db/models/sql/query.py", line 1385, in build_lookup
    lookup = lookup_class(lhs, rhs)
             ^^^^^^^^^^^^^^^^^^^^^^
  File "/media/zahid/Ads Power/Enterprise Infosec Consultants/ComplyWiseApi/venv/lib/python3.11/site-packages/django/db/models/lookups.py", line 30, in __init__
    self.rhs = self.get_prep_lookup()
               ^^^^^^^^^^^^^^^^^^^^^^
  File "/media/zahid/Ads Power/Enterprise Infosec Consultants/ComplyWiseApi/venv/lib/python3.11/site-packages/django/db/models/lookups.py", line 497, in get_prep_lookup
    return super().get_prep_lookup()
           ^^^^^^^^^^^^^^^^^^^^^^^^^
  File "/media/zahid/Ads Power/Enterprise Infosec Consultants/ComplyWiseApi/venv/lib/python3.11/site-packages/django/db/models/lookups.py", line 304, in get_prep_lookup
    rhs_value = self.lhs.output_field.get_prep_value(rhs_value)
                ^^^^^^^^^^^^^^^^^^^^^^^^^^^^^^^^^^^^^^^^^^^^^^^
  File "/media/zahid/Ads Power/Enterprise Infosec Consultants/ComplyWiseApi/venv/lib/python3.11/site-packages/django/db/models/fields/__init__.py", line 2125, in get_prep_value
    raise e.__class__(
ValueError: Field 'id' expected a number but got '['.
ERROR 2025-03-09 04:41:14,073 basehttp "PATCH /api/employees/1/ HTTP/1.1" 500 175905
ERROR 2025-03-09 04:50:04,783 log Internal Server Error: /api/employees/1/
Traceback (most recent call last):
  File "/media/zahid/Ads Power/Enterprise Infosec Consultants/ComplyWiseApi/venv/lib/python3.11/site-packages/django/db/models/fields/__init__.py", line 2123, in get_prep_value
    return int(value)
           ^^^^^^^^^^
ValueError: invalid literal for int() with base 10: '[10, 11]'

The above exception was the direct cause of the following exception:

Traceback (most recent call last):
  File "/media/zahid/Ads Power/Enterprise Infosec Consultants/ComplyWiseApi/venv/lib/python3.11/site-packages/django/core/handlers/exception.py", line 55, in inner
    response = get_response(request)
               ^^^^^^^^^^^^^^^^^^^^^
  File "/media/zahid/Ads Power/Enterprise Infosec Consultants/ComplyWiseApi/venv/lib/python3.11/site-packages/django/core/handlers/base.py", line 197, in _get_response
    response = wrapped_callback(request, *callback_args, **callback_kwargs)
               ^^^^^^^^^^^^^^^^^^^^^^^^^^^^^^^^^^^^^^^^^^^^^^^^^^^^^^^^^^^^
  File "/media/zahid/Ads Power/Enterprise Infosec Consultants/ComplyWiseApi/venv/lib/python3.11/site-packages/django/views/decorators/csrf.py", line 65, in _view_wrapper
    return view_func(request, *args, **kwargs)
           ^^^^^^^^^^^^^^^^^^^^^^^^^^^^^^^^^^^
  File "/media/zahid/Ads Power/Enterprise Infosec Consultants/ComplyWiseApi/venv/lib/python3.11/site-packages/rest_framework/viewsets.py", line 124, in view
    return self.dispatch(request, *args, **kwargs)
           ^^^^^^^^^^^^^^^^^^^^^^^^^^^^^^^^^^^^^^^
  File "/media/zahid/Ads Power/Enterprise Infosec Consultants/ComplyWiseApi/venv/lib/python3.11/site-packages/rest_framework/views.py", line 509, in dispatch
    response = self.handle_exception(exc)
               ^^^^^^^^^^^^^^^^^^^^^^^^^^
  File "/media/zahid/Ads Power/Enterprise Infosec Consultants/ComplyWiseApi/venv/lib/python3.11/site-packages/rest_framework/views.py", line 469, in handle_exception
    self.raise_uncaught_exception(exc)
  File "/media/zahid/Ads Power/Enterprise Infosec Consultants/ComplyWiseApi/venv/lib/python3.11/site-packages/rest_framework/views.py", line 480, in raise_uncaught_exception
    raise exc
  File "/media/zahid/Ads Power/Enterprise Infosec Consultants/ComplyWiseApi/venv/lib/python3.11/site-packages/rest_framework/views.py", line 506, in dispatch
    response = handler(request, *args, **kwargs)
               ^^^^^^^^^^^^^^^^^^^^^^^^^^^^^^^^^
  File "/media/zahid/Ads Power/Enterprise Infosec Consultants/ComplyWiseApi/app/modules/access_control/views/employee.py", line 45, in partial_update
    document = Documents.objects.filter(id=doc_id, parent_id=instance.id, parent_type="Employee").first()
               ^^^^^^^^^^^^^^^^^^^^^^^^^^^^^^^^^^^^^^^^^^^^^^^^^^^^^^^^^^^^^^^^^^^^^^^^^^^^^^^^^^
  File "/media/zahid/Ads Power/Enterprise Infosec Consultants/ComplyWiseApi/venv/lib/python3.11/site-packages/django/db/models/manager.py", line 87, in manager_method
    return getattr(self.get_queryset(), name)(*args, **kwargs)
           ^^^^^^^^^^^^^^^^^^^^^^^^^^^^^^^^^^^^^^^^^^^^^^^^^^^
  File "/media/zahid/Ads Power/Enterprise Infosec Consultants/ComplyWiseApi/venv/lib/python3.11/site-packages/django/db/models/query.py", line 1476, in filter
    return self._filter_or_exclude(False, args, kwargs)
           ^^^^^^^^^^^^^^^^^^^^^^^^^^^^^^^^^^^^^^^^^^^^
  File "/media/zahid/Ads Power/Enterprise Infosec Consultants/ComplyWiseApi/venv/lib/python3.11/site-packages/django/db/models/query.py", line 1494, in _filter_or_exclude
    clone._filter_or_exclude_inplace(negate, args, kwargs)
  File "/media/zahid/Ads Power/Enterprise Infosec Consultants/ComplyWiseApi/venv/lib/python3.11/site-packages/django/db/models/query.py", line 1501, in _filter_or_exclude_inplace
    self._query.add_q(Q(*args, **kwargs))
  File "/media/zahid/Ads Power/Enterprise Infosec Consultants/ComplyWiseApi/venv/lib/python3.11/site-packages/django/db/models/sql/query.py", line 1609, in add_q
    clause, _ = self._add_q(q_object, self.used_aliases)
                ^^^^^^^^^^^^^^^^^^^^^^^^^^^^^^^^^^^^^^^^
  File "/media/zahid/Ads Power/Enterprise Infosec Consultants/ComplyWiseApi/venv/lib/python3.11/site-packages/django/db/models/sql/query.py", line 1641, in _add_q
    child_clause, needed_inner = self.build_filter(
                                 ^^^^^^^^^^^^^^^^^^
  File "/media/zahid/Ads Power/Enterprise Infosec Consultants/ComplyWiseApi/venv/lib/python3.11/site-packages/django/db/models/sql/query.py", line 1555, in build_filter
    condition = self.build_lookup(lookups, col, value)
                ^^^^^^^^^^^^^^^^^^^^^^^^^^^^^^^^^^^^^^
  File "/media/zahid/Ads Power/Enterprise Infosec Consultants/ComplyWiseApi/venv/lib/python3.11/site-packages/django/db/models/sql/query.py", line 1385, in build_lookup
    lookup = lookup_class(lhs, rhs)
             ^^^^^^^^^^^^^^^^^^^^^^
  File "/media/zahid/Ads Power/Enterprise Infosec Consultants/ComplyWiseApi/venv/lib/python3.11/site-packages/django/db/models/lookups.py", line 30, in __init__
    self.rhs = self.get_prep_lookup()
               ^^^^^^^^^^^^^^^^^^^^^^
  File "/media/zahid/Ads Power/Enterprise Infosec Consultants/ComplyWiseApi/venv/lib/python3.11/site-packages/django/db/models/lookups.py", line 369, in get_prep_lookup
    return super().get_prep_lookup()
           ^^^^^^^^^^^^^^^^^^^^^^^^^
  File "/media/zahid/Ads Power/Enterprise Infosec Consultants/ComplyWiseApi/venv/lib/python3.11/site-packages/django/db/models/lookups.py", line 88, in get_prep_lookup
    return self.lhs.output_field.get_prep_value(self.rhs)
           ^^^^^^^^^^^^^^^^^^^^^^^^^^^^^^^^^^^^^^^^^^^^^^
  File "/media/zahid/Ads Power/Enterprise Infosec Consultants/ComplyWiseApi/venv/lib/python3.11/site-packages/django/db/models/fields/__init__.py", line 2125, in get_prep_value
    raise e.__class__(
ValueError: Field 'id' expected a number but got '[10, 11]'.
ERROR 2025-03-09 04:50:04,788 basehttp "PATCH /api/employees/1/ HTTP/1.1" 500 175664
ERROR 2025-03-09 04:50:54,386 log Internal Server Error: /api/employees/1/
Traceback (most recent call last):
  File "/media/zahid/Ads Power/Enterprise Infosec Consultants/ComplyWiseApi/venv/lib/python3.11/site-packages/django/db/models/fields/__init__.py", line 2123, in get_prep_value
    return int(value)
           ^^^^^^^^^^
ValueError: invalid literal for int() with base 10: '12, 13'

The above exception was the direct cause of the following exception:

Traceback (most recent call last):
  File "/media/zahid/Ads Power/Enterprise Infosec Consultants/ComplyWiseApi/venv/lib/python3.11/site-packages/django/core/handlers/exception.py", line 55, in inner
    response = get_response(request)
               ^^^^^^^^^^^^^^^^^^^^^
  File "/media/zahid/Ads Power/Enterprise Infosec Consultants/ComplyWiseApi/venv/lib/python3.11/site-packages/django/core/handlers/base.py", line 197, in _get_response
    response = wrapped_callback(request, *callback_args, **callback_kwargs)
               ^^^^^^^^^^^^^^^^^^^^^^^^^^^^^^^^^^^^^^^^^^^^^^^^^^^^^^^^^^^^
  File "/media/zahid/Ads Power/Enterprise Infosec Consultants/ComplyWiseApi/venv/lib/python3.11/site-packages/django/views/decorators/csrf.py", line 65, in _view_wrapper
    return view_func(request, *args, **kwargs)
           ^^^^^^^^^^^^^^^^^^^^^^^^^^^^^^^^^^^
  File "/media/zahid/Ads Power/Enterprise Infosec Consultants/ComplyWiseApi/venv/lib/python3.11/site-packages/rest_framework/viewsets.py", line 124, in view
    return self.dispatch(request, *args, **kwargs)
           ^^^^^^^^^^^^^^^^^^^^^^^^^^^^^^^^^^^^^^^
  File "/media/zahid/Ads Power/Enterprise Infosec Consultants/ComplyWiseApi/venv/lib/python3.11/site-packages/rest_framework/views.py", line 509, in dispatch
    response = self.handle_exception(exc)
               ^^^^^^^^^^^^^^^^^^^^^^^^^^
  File "/media/zahid/Ads Power/Enterprise Infosec Consultants/ComplyWiseApi/venv/lib/python3.11/site-packages/rest_framework/views.py", line 469, in handle_exception
    self.raise_uncaught_exception(exc)
  File "/media/zahid/Ads Power/Enterprise Infosec Consultants/ComplyWiseApi/venv/lib/python3.11/site-packages/rest_framework/views.py", line 480, in raise_uncaught_exception
    raise exc
  File "/media/zahid/Ads Power/Enterprise Infosec Consultants/ComplyWiseApi/venv/lib/python3.11/site-packages/rest_framework/views.py", line 506, in dispatch
    response = handler(request, *args, **kwargs)
               ^^^^^^^^^^^^^^^^^^^^^^^^^^^^^^^^^
  File "/media/zahid/Ads Power/Enterprise Infosec Consultants/ComplyWiseApi/app/modules/access_control/views/employee.py", line 45, in partial_update
    document = Documents.objects.filter(id=doc_id, parent_id=instance.id, parent_type="Employee").first()
               ^^^^^^^^^^^^^^^^^^^^^^^^^^^^^^^^^^^^^^^^^^^^^^^^^^^^^^^^^^^^^^^^^^^^^^^^^^^^^^^^^^
  File "/media/zahid/Ads Power/Enterprise Infosec Consultants/ComplyWiseApi/venv/lib/python3.11/site-packages/django/db/models/manager.py", line 87, in manager_method
    return getattr(self.get_queryset(), name)(*args, **kwargs)
           ^^^^^^^^^^^^^^^^^^^^^^^^^^^^^^^^^^^^^^^^^^^^^^^^^^^
  File "/media/zahid/Ads Power/Enterprise Infosec Consultants/ComplyWiseApi/venv/lib/python3.11/site-packages/django/db/models/query.py", line 1476, in filter
    return self._filter_or_exclude(False, args, kwargs)
           ^^^^^^^^^^^^^^^^^^^^^^^^^^^^^^^^^^^^^^^^^^^^
  File "/media/zahid/Ads Power/Enterprise Infosec Consultants/ComplyWiseApi/venv/lib/python3.11/site-packages/django/db/models/query.py", line 1494, in _filter_or_exclude
    clone._filter_or_exclude_inplace(negate, args, kwargs)
  File "/media/zahid/Ads Power/Enterprise Infosec Consultants/ComplyWiseApi/venv/lib/python3.11/site-packages/django/db/models/query.py", line 1501, in _filter_or_exclude_inplace
    self._query.add_q(Q(*args, **kwargs))
  File "/media/zahid/Ads Power/Enterprise Infosec Consultants/ComplyWiseApi/venv/lib/python3.11/site-packages/django/db/models/sql/query.py", line 1609, in add_q
    clause, _ = self._add_q(q_object, self.used_aliases)
                ^^^^^^^^^^^^^^^^^^^^^^^^^^^^^^^^^^^^^^^^
  File "/media/zahid/Ads Power/Enterprise Infosec Consultants/ComplyWiseApi/venv/lib/python3.11/site-packages/django/db/models/sql/query.py", line 1641, in _add_q
    child_clause, needed_inner = self.build_filter(
                                 ^^^^^^^^^^^^^^^^^^
  File "/media/zahid/Ads Power/Enterprise Infosec Consultants/ComplyWiseApi/venv/lib/python3.11/site-packages/django/db/models/sql/query.py", line 1555, in build_filter
    condition = self.build_lookup(lookups, col, value)
                ^^^^^^^^^^^^^^^^^^^^^^^^^^^^^^^^^^^^^^
  File "/media/zahid/Ads Power/Enterprise Infosec Consultants/ComplyWiseApi/venv/lib/python3.11/site-packages/django/db/models/sql/query.py", line 1385, in build_lookup
    lookup = lookup_class(lhs, rhs)
             ^^^^^^^^^^^^^^^^^^^^^^
  File "/media/zahid/Ads Power/Enterprise Infosec Consultants/ComplyWiseApi/venv/lib/python3.11/site-packages/django/db/models/lookups.py", line 30, in __init__
    self.rhs = self.get_prep_lookup()
               ^^^^^^^^^^^^^^^^^^^^^^
  File "/media/zahid/Ads Power/Enterprise Infosec Consultants/ComplyWiseApi/venv/lib/python3.11/site-packages/django/db/models/lookups.py", line 369, in get_prep_lookup
    return super().get_prep_lookup()
           ^^^^^^^^^^^^^^^^^^^^^^^^^
  File "/media/zahid/Ads Power/Enterprise Infosec Consultants/ComplyWiseApi/venv/lib/python3.11/site-packages/django/db/models/lookups.py", line 88, in get_prep_lookup
    return self.lhs.output_field.get_prep_value(self.rhs)
           ^^^^^^^^^^^^^^^^^^^^^^^^^^^^^^^^^^^^^^^^^^^^^^
  File "/media/zahid/Ads Power/Enterprise Infosec Consultants/ComplyWiseApi/venv/lib/python3.11/site-packages/django/db/models/fields/__init__.py", line 2125, in get_prep_value
    raise e.__class__(
ValueError: Field 'id' expected a number but got '12, 13'.
ERROR 2025-03-09 04:50:54,389 basehttp "PATCH /api/employees/1/ HTTP/1.1" 500 174864
ERROR 2025-03-09 04:53:57,838 log Internal Server Error: /api/employees/1/
Traceback (most recent call last):
  File "/media/zahid/Ads Power/Enterprise Infosec Consultants/ComplyWiseApi/venv/lib/python3.11/site-packages/django/db/models/fields/__init__.py", line 2123, in get_prep_value
    return int(value)
           ^^^^^^^^^^
ValueError: invalid literal for int() with base 10: '[7, 8]'

The above exception was the direct cause of the following exception:

Traceback (most recent call last):
  File "/media/zahid/Ads Power/Enterprise Infosec Consultants/ComplyWiseApi/venv/lib/python3.11/site-packages/django/core/handlers/exception.py", line 55, in inner
    response = get_response(request)
               ^^^^^^^^^^^^^^^^^^^^^
  File "/media/zahid/Ads Power/Enterprise Infosec Consultants/ComplyWiseApi/venv/lib/python3.11/site-packages/django/core/handlers/base.py", line 197, in _get_response
    response = wrapped_callback(request, *callback_args, **callback_kwargs)
               ^^^^^^^^^^^^^^^^^^^^^^^^^^^^^^^^^^^^^^^^^^^^^^^^^^^^^^^^^^^^
  File "/media/zahid/Ads Power/Enterprise Infosec Consultants/ComplyWiseApi/venv/lib/python3.11/site-packages/django/views/decorators/csrf.py", line 65, in _view_wrapper
    return view_func(request, *args, **kwargs)
           ^^^^^^^^^^^^^^^^^^^^^^^^^^^^^^^^^^^
  File "/media/zahid/Ads Power/Enterprise Infosec Consultants/ComplyWiseApi/venv/lib/python3.11/site-packages/rest_framework/viewsets.py", line 124, in view
    return self.dispatch(request, *args, **kwargs)
           ^^^^^^^^^^^^^^^^^^^^^^^^^^^^^^^^^^^^^^^
  File "/media/zahid/Ads Power/Enterprise Infosec Consultants/ComplyWiseApi/venv/lib/python3.11/site-packages/rest_framework/views.py", line 509, in dispatch
    response = self.handle_exception(exc)
               ^^^^^^^^^^^^^^^^^^^^^^^^^^
  File "/media/zahid/Ads Power/Enterprise Infosec Consultants/ComplyWiseApi/venv/lib/python3.11/site-packages/rest_framework/views.py", line 469, in handle_exception
    self.raise_uncaught_exception(exc)
  File "/media/zahid/Ads Power/Enterprise Infosec Consultants/ComplyWiseApi/venv/lib/python3.11/site-packages/rest_framework/views.py", line 480, in raise_uncaught_exception
    raise exc
  File "/media/zahid/Ads Power/Enterprise Infosec Consultants/ComplyWiseApi/venv/lib/python3.11/site-packages/rest_framework/views.py", line 506, in dispatch
    response = handler(request, *args, **kwargs)
               ^^^^^^^^^^^^^^^^^^^^^^^^^^^^^^^^^
  File "/media/zahid/Ads Power/Enterprise Infosec Consultants/ComplyWiseApi/app/modules/access_control/views/employee.py", line 45, in partial_update
    document = Documents.objects.filter(id=doc_id, parent_id=instance.id, parent_type="Employee").first()
               ^^^^^^^^^^^^^^^^^^^^^^^^^^^^^^^^^^^^^^^^^^^^^^^^^^^^^^^^^^^^^^^^^^^^^^^^^^^^^^^^^^
  File "/media/zahid/Ads Power/Enterprise Infosec Consultants/ComplyWiseApi/venv/lib/python3.11/site-packages/django/db/models/manager.py", line 87, in manager_method
    return getattr(self.get_queryset(), name)(*args, **kwargs)
           ^^^^^^^^^^^^^^^^^^^^^^^^^^^^^^^^^^^^^^^^^^^^^^^^^^^
  File "/media/zahid/Ads Power/Enterprise Infosec Consultants/ComplyWiseApi/venv/lib/python3.11/site-packages/django/db/models/query.py", line 1476, in filter
    return self._filter_or_exclude(False, args, kwargs)
           ^^^^^^^^^^^^^^^^^^^^^^^^^^^^^^^^^^^^^^^^^^^^
  File "/media/zahid/Ads Power/Enterprise Infosec Consultants/ComplyWiseApi/venv/lib/python3.11/site-packages/django/db/models/query.py", line 1494, in _filter_or_exclude
    clone._filter_or_exclude_inplace(negate, args, kwargs)
  File "/media/zahid/Ads Power/Enterprise Infosec Consultants/ComplyWiseApi/venv/lib/python3.11/site-packages/django/db/models/query.py", line 1501, in _filter_or_exclude_inplace
    self._query.add_q(Q(*args, **kwargs))
  File "/media/zahid/Ads Power/Enterprise Infosec Consultants/ComplyWiseApi/venv/lib/python3.11/site-packages/django/db/models/sql/query.py", line 1609, in add_q
    clause, _ = self._add_q(q_object, self.used_aliases)
                ^^^^^^^^^^^^^^^^^^^^^^^^^^^^^^^^^^^^^^^^
  File "/media/zahid/Ads Power/Enterprise Infosec Consultants/ComplyWiseApi/venv/lib/python3.11/site-packages/django/db/models/sql/query.py", line 1641, in _add_q
    child_clause, needed_inner = self.build_filter(
                                 ^^^^^^^^^^^^^^^^^^
  File "/media/zahid/Ads Power/Enterprise Infosec Consultants/ComplyWiseApi/venv/lib/python3.11/site-packages/django/db/models/sql/query.py", line 1555, in build_filter
    condition = self.build_lookup(lookups, col, value)
                ^^^^^^^^^^^^^^^^^^^^^^^^^^^^^^^^^^^^^^
  File "/media/zahid/Ads Power/Enterprise Infosec Consultants/ComplyWiseApi/venv/lib/python3.11/site-packages/django/db/models/sql/query.py", line 1385, in build_lookup
    lookup = lookup_class(lhs, rhs)
             ^^^^^^^^^^^^^^^^^^^^^^
  File "/media/zahid/Ads Power/Enterprise Infosec Consultants/ComplyWiseApi/venv/lib/python3.11/site-packages/django/db/models/lookups.py", line 30, in __init__
    self.rhs = self.get_prep_lookup()
               ^^^^^^^^^^^^^^^^^^^^^^
  File "/media/zahid/Ads Power/Enterprise Infosec Consultants/ComplyWiseApi/venv/lib/python3.11/site-packages/django/db/models/lookups.py", line 369, in get_prep_lookup
    return super().get_prep_lookup()
           ^^^^^^^^^^^^^^^^^^^^^^^^^
  File "/media/zahid/Ads Power/Enterprise Infosec Consultants/ComplyWiseApi/venv/lib/python3.11/site-packages/django/db/models/lookups.py", line 88, in get_prep_lookup
    return self.lhs.output_field.get_prep_value(self.rhs)
           ^^^^^^^^^^^^^^^^^^^^^^^^^^^^^^^^^^^^^^^^^^^^^^
  File "/media/zahid/Ads Power/Enterprise Infosec Consultants/ComplyWiseApi/venv/lib/python3.11/site-packages/django/db/models/fields/__init__.py", line 2125, in get_prep_value
    raise e.__class__(
ValueError: Field 'id' expected a number but got '[7, 8]'.
ERROR 2025-03-09 04:53:57,843 basehttp "PATCH /api/employees/1/ HTTP/1.1" 500 175108
